Workbook

Sheet Revenue Exposure - Overall
A1: Company Name | B1: Revenue Exposure - Intermediate Component | C1: HHI Index - Value | D1: HHI Index - Submultiplier | E1: Revenue Exposure - Final Component
A2: Allianz | B2: ='Country of Revenues - Allianz'!$J$9 -> 3.7720216 | C2: =SUMPRODUCT('Country of Revenues - Allianz'!$D$4:$D$150,'Country of Revenues - Allianz'!$D$4:$D$150) -> 0.09271898 | D2: ='HHI Index Submultiplier'!C2 -> 0.9 | E2: =Tabella2[[#This Row],[Revenue Exposure - Intermediate Component]]*Tabella2[[#This Row],[HHI Index - Submultiplier]] -> 3.3948195
A3: Amazon | B3: ='Country of Revenues - Amazon'!$J$9 -> 4.0292105 | C3: =SUMPRODUCT('Country of Revenues - Amazon'!$D$4:$D$150,'Country of Revenues - Amazon'!$D$4:$D$150) -> 0.65874178 | D3: ='HHI Index Submultiplier'!C3 -> 1.5 | E3: =Tabella2[[#This Row],[Revenue Exposure - Intermediate Component]]*Tabella2[[#This Row],[HHI Index - Submultiplier]] -> 6.0438158
A4: Apple | B4: ='Country of Revenues - Apple'!$J$9 -> 4.1049432 | C4: =SUMPRODUCT('Country of Revenues - Apple'!$D$4:$D$150,'Country of Revenues - Apple'!$D$4:$D$150) -> 0.23058349 | D4: ='HHI Index Submultiplier'!C4 -> 1 | E4: =Tabella2[[#This Row],[Revenue Exposure - Intermediate Component]]*Tabella2[[#This Row],[HHI Index - Submultiplier]] -> 4.1049432
A5: ASML | B5: ='Country of Revenues - ASML'!$J$9 -> 4.0105683 | C5: =SUMPRODUCT('Country of Revenues - ASML'!$D$4:$D$150,'Country of Revenues - ASML'!$D$4:$D$150) -> 0.39167225 | D5: ='HHI Index Submultiplier'!C5 -> 1.1 | E5: =Tabella2[[#This Row],[Revenue Exposure - Intermediate Component]]*Tabella2[[#This Row],[HHI Index - Submultiplier]] -> 4.4116251
A6: BNP Paribas | B6: ='Country of Revenues - BNP'!$J$9 -> 3.7290288 | C6: =SUMPRODUCT('Country of Revenues - BNP'!$D$4:$D$150,'Country of Revenues - BNP'!$D$4:$D$150) -> 0.12116874 | D6: ='HHI Index Submultiplier'!C6 -> 0.9 | E6: =Tabella2[[#This Row],[Revenue Exposure - Intermediate Component]]*Tabella2[[#This Row],[HHI Index - Submultiplier]] -> 3.3561259
A7: Eli Lilly | B7: ='Country of Revenues - Eli LIlly'!$J$9 -> 4.1002007 | C7: =SUMPRODUCT('Country of Revenues - Eli LIlly'!$D$4:$D$150,'Country of Revenues - Eli LIlly'!$D$4:$D$150) -> 0.16582394 | D7: ='HHI Index Submultiplier'!C7 -> 1 | E7: =Tabella2[[#This Row],[Revenue Exposure - Intermediate Component]]*Tabella2[[#This Row],[HHI Index - Submultiplier]] -> 4.1002007
A8: ENI | B8: ='Country of Revenues - ENI'!$J$9 -> 3.9368104 | C8: =SUMPRODUCT('Country of Revenues - ENI'!$D$4:$D$150,'Country of Revenues - ENI'!$D$4:$D$150) -> 0.18768843 | D8: ='HHI Index Submultiplier'!C8 -> 1 | E8: =Tabella2[[#This Row],[Revenue Exposure - Intermediate Component]]*Tabella2[[#This Row],[HHI Index - Submultiplier]] -> 3.9368104
A9: Ford | B9: ='Country of Revenues - Ford'!$J$9 -> 4.0784836 | C9: =SUMPRODUCT('Country of Revenues - Ford'!$D$4:$D$150,'Country of Revenues - Ford'!$D$4:$D$150) -> 0.59893054 | D9: ='HHI Index Submultiplier'!C9 -> 1.25 | E9: =Tabella2[[#This Row],[Revenue Exposure - Intermediate Component]]*Tabella2[[#This Row],[HHI Index - Submultiplier]] -> 5.0981045
A10: JP Morgan | B10: ='Country of Revenues - JP Morgan'!$J$9 -> 4.0328985 | C10: =SUMPRODUCT('Country of Revenues - JP Morgan'!$D$4:$D$150,'Country of Revenues - JP Morgan'!$D$4:$D$150) -> 0.52924521 | D10: ='HHI Index Submultiplier'!C10 -> 1.25 | E10: =Tabella2[[#This Row],[Revenue Exposure - Intermediate Component]]*Tabella2[[#This Row],[HHI Index - Submultiplier]] -> 5.0411231
A11: L'Oreal | B11: ='Country of Revenues - Oreal'!J9 -> 4.0242964 | C11: =SUMPRODUCT('Country of Revenues - Oreal'!$D$4:$D$150,'Country of Revenues - Oreal'!$D$4:$D$150) -> 0.15308301 | D11: ='HHI Index Submultiplier'!C11 -> 1 | E11: =Tabella2[[#This Row],[Revenue Exposure - Intermediate Component]]*Tabella2[[#This Row],[HHI Index - Submultiplier]] -> 4.0242964
A12: LVMH | B12: ='Country of Revenues - LVMH'!$J$9 -> 4.0610137 | C12: =SUMPRODUCT('Country of Revenues - LVMH'!$D$4:$D$150,'Country of Revenues - LVMH'!$D$4:$D$150) -> 0.16976331 | D12: ='HHI Index Submultiplier'!C12 -> 1 | E12: =Tabella2[[#This Row],[Revenue Exposure - Intermediate Component]]*Tabella2[[#This Row],[HHI Index - Submultiplier]] -> 4.0610137
A13: Meta | B13: ='Country of Revenues - Meta'!$J$9 -> 4.0756275 | C13: =SUMPRODUCT('Country of Revenues - Meta'!$D$4:$D$150,'Country of Revenues - Meta'!$D$4:$D$150) -> 0.2230063 | D13: ='HHI Index Submultiplier'!C13 -> 1 | E13: =Tabella2[[#This Row],[Revenue Exposure - Intermediate Component]]*Tabella2[[#This Row],[HHI Index - Submultiplier]] -> 4.0756275
A14: Microsoft | B14: ='Country of Revenues - Microsoft'!$J$9 -> 4.1699698 | C14: =SUMPRODUCT('Country of Revenues - Microsoft'!$D$4:$D$150,'Country of Revenues - Microsoft'!$D$4:$D$150) -> 0.40182632 | D14: ='HHI Index Submultiplier'!C14 -> 1.25 | E14: =Tabella2[[#This Row],[Revenue Exposure - Intermediate Component]]*Tabella2[[#This Row],[HHI Index - Submultiplier]] -> 5.2124623
A15: Novo Nordisk | B15: ='Country of Revenues - Nordisk'!$J$9 -> 4.1369089 | C15: =SUMPRODUCT('Country of Revenues - Nordisk'!$D$4:$D$150,'Country of Revenues - Nordisk'!$D$4:$D$150) -> 0.43061929 | D15: ='HHI Index Submultiplier'!C15 -> 1.25 | E15: =Tabella2[[#This Row],[Revenue Exposure - Intermediate Component]]*Tabella2[[#This Row],[HHI Index - Submultiplier]] -> 5.1711361
A16: NVIDIA | B16: ='Country of Revenues - NVIDIA'!$J$9 -> 4.2089876 | C16: =SUMPRODUCT('Country of Revenues - NVIDIA'!$D$4:$D$150,'Country of Revenues - NVIDIA'!$D$4:$D$150) -> 0.59301668 | D16: ='HHI Index Submultiplier'!C16 -> 1.25 | E16: =Tabella2[[#This Row],[Revenue Exposure - Intermediate Component]]*Tabella2[[#This Row],[HHI Index - Submultiplier]] -> 5.2612345
A17: Procter & Gamble | B17: ='Country of Revenues - P&G'!$J$9 -> 4.1662735 | C17: =SUMPRODUCT('Country of Revenues - P&G'!$D$4:$D$150,'Country of Revenues - P&G'!$D$4:$D$150) -> 0.36840581 | D17: ='HHI Index Submultiplier'!C17 -> 1.1 | E17: =Tabella2[[#This Row],[Revenue Exposure - Intermediate Component]]*Tabella2[[#This Row],[HHI Index - Submultiplier]] -> 4.5829008
A18: Reliance Industries | B18: ='Country of Revenues - Reliance'!$J$9 -> 4.9082045 | C18: =SUMPRODUCT('Country of Revenues - Reliance'!$D$4:$D$150,'Country of Revenues - Reliance'!$D$4:$D$150) -> 0.69171596 | D18: ='HHI Index Submultiplier'!C18 -> 1.5 | E18: =Tabella2[[#This Row],[Revenue Exposure - Intermediate Component]]*Tabella2[[#This Row],[HHI Index - Submultiplier]] -> 7.3623067
A19: Samsung | B19: ='Country of Revenues - Samsung'!$J$9 -> 4.0305108 | C19: =SUMPRODUCT('Country of Revenues - Samsung'!$D$4:$D$150,'Country of Revenues - Samsung'!$D$4:$D$150) -> 0.17706431 | D19: ='HHI Index Submultiplier'!C19 -> 1 | E19: =Tabella2[[#This Row],[Revenue Exposure - Intermediate Component]]*Tabella2[[#This Row],[HHI Index - Submultiplier]] -> 4.0305108
A20: SAP | B20: ='Country of Revenues - SAP'!$J$9 -> 3.9690703 | C20: =SUMPRODUCT('Country of Revenues - SAP'!$D$4:$D$150,'Country of Revenues - SAP'!$D$4:$D$150) -> 0.28029191 | D20: ='HHI Index Submultiplier'!C20 -> 1.1 | E20: =Tabella2[[#This Row],[Revenue Exposure - Intermediate Component]]*Tabella2[[#This Row],[HHI Index - Submultiplier]] -> 4.3659773
A21: Sony | B21: ='Country of Revenues - Sony'!$J$9 -> 3.931858 | C21: =SUMPRODUCT('Country of Revenues - Sony'!$D$4:$D$150,'Country of Revenues - Sony'!$D$4:$D$150) -> 0.16957249 | D21: ='HHI Index Submultiplier'!C21 -> 1 | E21: =Tabella2[[#This Row],[Revenue Exposure - Intermediate Component]]*Tabella2[[#This Row],[HHI Index - Submultiplier]] -> 3.931858
A22: Tencent | B22: ='Country of Revenues - Tencent'!$J$9 -> 4.2558828 | C22: =SUMPRODUCT('Country of Revenues - Tencent'!$D$4:$D$150,'Country of Revenues - Tencent'!$D$4:$D$150) -> 1 | D22: ='HHI Index Submultiplier'!C22 -> 1.5 | E22: =Tabella2[[#This Row],[Revenue Exposure - Intermediate Component]]*Tabella2[[#This Row],[HHI Index - Submultiplier]] -> 6.3838242
A23: TotaleEnergies | B23: ='Country of Revenues - Total En'!$J$9 -> 3.8600721 | C23: =SUMPRODUCT('Country of Revenues - Total En'!$D$4:$D$150,'Country of Revenues - Total En'!$D$4:$D$150) -> 0.13243431 | D23: ='HHI Index Submultiplier'!C23 -> 0.9 | E23: =Tabella2[[#This Row],[Revenue Exposure - Intermediate Component]]*Tabella2[[#This Row],[HHI Index - Submultiplier]] -> 3.4740649
A24: Toyota | B24: ='Country of Revenues - Toyota'!$J$9 -> 4.0129565 | C24: =SUMPRODUCT('Country of Revenues - Toyota'!$D$4:$D$150,'Country of Revenues - Toyota'!$D$4:$D$150) -> 0.24135179 | D24: ='HHI Index Submultiplier'!C24 -> 1 | E24: =Tabella2[[#This Row],[Revenue Exposure - Intermediate Component]]*Tabella2[[#This Row],[HHI Index - Submultiplier]] -> 4.0129565
A25: TSMC | B25: ='Country of Revenues - TSMC'!$J$9 -> 4.1677913 | C25: =SUMPRODUCT('Country of Revenues - TSMC'!$D$4:$D$150,'Country of Revenues - TSMC'!$D$4:$D$150) -> 0.64773114 | D25: ='HHI Index Submultiplier'!C25 -> 1.5 | E25: =Tabella2[[#This Row],[Revenue Exposure - Intermediate Component]]*Tabella2[[#This Row],[HHI Index - Submultiplier]] -> 6.2516869
A26: Volkswagen | B26: ='Country of Revenues - VW'!$J$9 -> 3.8082592 | C26: =SUMPRODUCT('Country of Revenues - VW'!$D$4:$D$150,'Country of Revenues - VW'!$D$4:$D$150) -> 0.11745964 | D26: ='HHI Index Submultiplier'!C26 -> 0.9 | E26: =Tabella2[[#This Row],[Revenue Exposure - Intermediate Component]]*Tabella2[[#This Row],[HHI Index - Submultiplier]] -> 3.4274333

Sheet HHI Index Submultiplier
A1: Company Name | B1: HHI Index - Revenue Distribution | C1: HHI Index - Submultiplier
A2: Allianz | B2: =SUMPRODUCT('Country of Revenues - Allianz'!$D$4:$D$150,'Country of Revenues - Allianz'!$D$4:$D$150) -> 0.09271898 | C2: =IF(B2<0.15,0.9, IF(B2<0.25,1, IF(B2<0.4,1.1, IF(B2<0.6,1.25, 1.5)))) -> 0.9
A3: Amazon | B3: =SUMPRODUCT('Country of Revenues - Amazon'!$D$4:$D$150,'Country of Revenues - Amazon'!$D$4:$D$150) -> 0.65874178 | C3: =IF(B3<0.15,0.9, IF(B3<0.25,1, IF(B3<0.4,1.1, IF(B3<0.6,1.25, 1.5)))) -> 1.5
A4: Apple | B4: =SUMPRODUCT('Country of Revenues - Apple'!$D$4:$D$150,'Country of Revenues - Apple'!$D$4:$D$150) -> 0.23058349 | C4: =IF(B4<0.15,0.9, IF(B4<0.25,1, IF(B4<0.4,1.1, IF(B4<0.6,1.25, 1.5)))) -> 1
A5: ASML | B5: =SUMPRODUCT('Country of Revenues - ASML'!$D$4:$D$150,'Country of Revenues - ASML'!$D$4:$D$150) -> 0.39167225 | C5: =IF(B5<0.15,0.9, IF(B5<0.25,1, IF(B5<0.4,1.1, IF(B5<0.6,1.25, 1.5)))) -> 1.1
A6: BNP Paribas | B6: =SUMPRODUCT('Country of Revenues - BNP'!$D$4:$D$150,'Country of Revenues - BNP'!$D$4:$D$150) -> 0.12116874 | C6: =IF(B6<0.15,0.9, IF(B6<0.25,1, IF(B6<0.4,1.1, IF(B6<0.6,1.25, 1.5)))) -> 0.9
A7: Eli Lilly | B7: =SUMPRODUCT('Country of Revenues - Eli LIlly'!$D$4:$D$150,'Country of Revenues - Eli LIlly'!$D$4:$D$150) -> 0.16582394 | C7: =IF(B7<0.15,0.9, IF(B7<0.25,1, IF(B7<0.4,1.1, IF(B7<0.6,1.25, 1.5)))) -> 1
A8: ENI | B8: =SUMPRODUCT('Country of Revenues - ENI'!$D$4:$D$150,'Country of Revenues - ENI'!$D$4:$D$150) -> 0.18768843 | C8: =IF(B8<0.15,0.9, IF(B8<0.25,1, IF(B8<0.4,1.1, IF(B8<0.6,1.25, 1.5)))) -> 1
A9: Ford | B9: =SUMPRODUCT('Country of Revenues - Ford'!$D$4:$D$150,'Country of Revenues - Ford'!$D$4:$D$150) -> 0.59893054 | C9: =IF(B9<0.15,0.9, IF(B9<0.25,1, IF(B9<0.4,1.1, IF(B9<0.6,1.25, 1.5)))) -> 1.25
A10: JP Morgan | B10: =SUMPRODUCT('Country of Revenues - JP Morgan'!$D$4:$D$150,'Country of Revenues - JP Morgan'!$D$4:$D$150) -> 0.52924521 | C10: =IF(B10<0.15,0.9, IF(B10<0.25,1, IF(B10<0.4,1.1, IF(B10<0.6,1.25, 1.5)))) -> 1.25
A11: L'Oreal | B11: =SUMPRODUCT('Country of Revenues - Oreal'!$D$4:$D$150,'Country of Revenues - Oreal'!$D$4:$D$150) -> 0.15308301 | C11: =IF(B11<0.15,0.9, IF(B11<0.25,1, IF(B11<0.4,1.1, IF(B11<0.6,1.25, 1.5)))) -> 1
A12: LVMH | B12: =SUMPRODUCT('Country of Revenues - LVMH'!$D$4:$D$150,'Country of Revenues - LVMH'!$D$4:$D$150) -> 0.16976331 | C12: =IF(B12<0.15,0.9, IF(B12<0.25,1, IF(B12<0.4,1.1, IF(B12<0.6,1.25, 1.5)))) -> 1
A13: Meta | B13: =SUMPRODUCT('Country of Revenues - Meta'!$D$4:$D$150,'Country of Revenues - Meta'!$D$4:$D$150) -> 0.2230063 | C13: =IF(B13<0.15,0.9, IF(B13<0.25,1, IF(B13<0.4,1.1, IF(B13<0.6,1.25, 1.5)))) -> 1
A14: Microsoft | B14: =SUMPRODUCT('Country of Revenues - Microsoft'!$D$4:$D$150,'Country of Revenues - Microsoft'!$D$4:$D$150) -> 0.40182632 | C14: =IF(B14<0.15,0.9, IF(B14<0.25,1, IF(B14<0.4,1.1, IF(B14<0.6,1.25, 1.5)))) -> 1.25
A15: Novo Nordisk | B15: =SUMPRODUCT('Country of Revenues - Nordisk'!$D$4:$D$150,'Country of Revenues - Nordisk'!$D$4:$D$150) -> 0.43061929 | C15: =IF(B15<0.15,0.9, IF(B15<0.25,1, IF(B15<0.4,1.1, IF(B15<0.6,1.25, 1.5)))) -> 1.25
A16: NVIDIA | B16: =SUMPRODUCT('Country of Revenues - NVIDIA'!$D$4:$D$150,'Country of Revenues - NVIDIA'!$D$4:$D$150) -> 0.59301668 | C16: =IF(B16<0.15,0.9, IF(B16<0.25,1, IF(B16<0.4,1.1, IF(B16<0.6,1.25, 1.5)))) -> 1.25
A17: Procter & Gamble | B17: =SUMPRODUCT('Country of Revenues - P&G'!$D$4:$D$150,'Country of Revenues - P&G'!$D$4:$D$150) -> 0.36840581 | C17: =IF(B17<0.15,0.9, IF(B17<0.25,1, IF(B17<0.4,1.1, IF(B17<0.6,1.25, 1.5)))) -> 1.1
A18: Reliance Industries | B18: =SUMPRODUCT('Country of Revenues - Reliance'!$D$4:$D$150,'Country of Revenues - Reliance'!$D$4:$D$150) -> 0.69171596 | C18: =IF(B18<0.15,0.9, IF(B18<0.25,1, IF(B18<0.4,1.1, IF(B18<0.6,1.25, 1.5)))) -> 1.5
A19: Samsung | B19: =SUMPRODUCT('Country of Revenues - Samsung'!$D$4:$D$150,'Country of Revenues - Samsung'!$D$4:$D$150) -> 0.17706431 | C19: =IF(B19<0.15,0.9, IF(B19<0.25,1, IF(B19<0.4,1.1, IF(B19<0.6,1.25, 1.5)))) -> 1
A20: SAP | B20: =SUMPRODUCT('Country of Revenues - SAP'!$D$4:$D$150,'Country of Revenues - SAP'!$D$4:$D$150) -> 0.28029191 | C20: =IF(B20<0.15,0.9, IF(B20<0.25,1, IF(B20<0.4,1.1, IF(B20<0.6,1.25, 1.5)))) -> 1.1
A21: Sony | B21: =SUMPRODUCT('Country of Revenues - Sony'!$D$4:$D$150,'Country of Revenues - Sony'!$D$4:$D$150) -> 0.16957249 | C21: =IF(B21<0.15,0.9, IF(B21<0.25,1, IF(B21<0.4,1.1, IF(B21<0.6,1.25, 1.5)))) -> 1
A22: Tencent | B22: =SUMPRODUCT('Country of Revenues - Tencent'!$D$4:$D$150,'Country of Revenues - Tencent'!$D$4:$D$150) -> 1 | C22: =IF(B22<0.15,0.9, IF(B22<0.25,1, IF(B22<0.4,1.1, IF(B22<0.6,1.25, 1.5)))) -> 1.5
A23: Total Energies | B23: =SUMPRODUCT('Country of Revenues - Total En'!$D$4:$D$150,'Country of Revenues - Total En'!$D$4:$D$150) -> 0.13243431 | C23: =IF(B23<0.15,0.9, IF(B23<0.25,1, IF(B23<0.4,1.1, IF(B23<0.6,1.25, 1.5)))) -> 0.9
A24: Toyota | B24: =SUMPRODUCT('Country of Revenues - Toyota'!$D$4:$D$150,'Country of Revenues - Toyota'!$D$4:$D$150) -> 0.24135179 | C24: =IF(B24<0.15,0.9, IF(B24<0.25,1, IF(B24<0.4,1.1, IF(B24<0.6,1.25, 1.5)))) -> 1
A25: TSMC | B25: =SUMPRODUCT('Country of Revenues - TSMC'!$D$4:$D$150,'Country of Revenues - TSMC'!$D$4:$D$150) -> 0.64773114 | C25: =IF(B25<0.15,0.9, IF(B25<0.25,1, IF(B25<0.4,1.1, IF(B25<0.6,1.25, 1.5)))) -> 1.5
A26: Volkswagen | B26: =SUMPRODUCT('Country of Revenues - VW'!$D$4:$D$150,'Country of Revenues - VW'!$D$4:$D$150) -> 0.11745964 | C26: =IF(B26<0.15,0.9, IF(B26<0.25,1, IF(B26<0.4,1.1, IF(B26<0.6,1.25, 1.5)))) -> 0.9

Sheet Country of Revenues - Apple
A1: Apple Inc.
A3: Country of Revenue | B3: Country Geopolitical Risk Index | C3: Percentage of Revenues | D3: Percentage of Revenues Standardized
A4: Albania | B4: 4.3705708 | C4: 0 | D4: =C4/$C$151 -> 0
A5: Algeria | B5: 5.2136193 | C5: 0 | D5: =C5/$C$151 -> 0 | G5: Main Data
A6: Angola | B6: 5.6305966 | C6: 0 | D6: =C6/$C$151 -> 0 | H6: Country | I6: Geopolitical Risk Index | J6: Value
A7: Argentina | B7: 4.3620978 | C7: 0.0056 | D7: =C7/$C$151 -> 0.0066571564 | G7: Minimum | H7: =INDEX(A4:A150,MATCH(MIN(D4:D150),D4:D150,0)) -> Albania | I7: =INDEX(B4:B150,MATCH(MIN(D4:D150),D4:D150,0)) -> 4.3705708 | J7: =INDEX(D4:D150,MATCH(MIN(D4:D150),D4:D150,0)) -> 0
A8: Armenia | B8: 4.7882033 | C8: 0 | D8: =C8/$C$151 -> 0 | G8: Maximum | H8: =INDEX(A4:A150,MATCH(MAX(D4:D150),D4:D150,0)) -> United States | I8: =INDEX(B4:B150,MATCH(MAX(D4:D150),D4:D150,0)) -> 4.1903554 | J8: =INDEX(D4:D150,MATCH(MAX(D4:D150),D4:D150,0)) -> 0.43354731
A9: Australia | B9: 3.2228923 | C9: 0.0165 | D9: =C9/$C$151 -> 0.019614836 | G9: Component - Revenues | J9: =SUMPRODUCT(B4:B150,D4:D150) -> 4.1049432
A10: Austria | B10: 3.4101851 | C10: 0 | D10: =C10/$C$151 -> 0
A11: Azerbaijan | B11: 5.2109259 | C11: 0 | D11: =C11/$C$151 -> 0
A12: Bahrain | B12: 4.2572307 | C12: 0 | D12: =C12/$C$151 -> 0
A13: Bangladesh | B13: 6.2938646 | C13: 0 | D13: =C13/$C$151 -> 0
A14: Belarus | B14: 5.4470392 | C14: 0 | D14: =C14/$C$151 -> 0
A15: Belgium | B15: 3.3272157 | C15: 0 | D15: =C15/$C$151 -> 0
A16: Benin | B16: 5.9976204 | C16: 0 | D16: =C16/$C$151 -> 0
A17: Bhutan | B17: 5.0248646 | C17: 0 | D17: =C17/$C$151 -> 0
A18: Bolivia | B18: 5.4119735 | C18: 0 | D18: =C18/$C$151 -> 0
A19: Bosnia and Herzegovina | B19: 5.3424605 | C19: 0 | D19: =C19/$C$151 -> 0
A20: Botswana | B20: 4.3392269 | C20: 0 | D20: =C20/$C$151 -> 0
A21: Brazil | B21: 5.352888 | C21: 0.0189 | D21: =C21/$C$151 -> 0.022467903
... A30: Chile | B30: 4.3579263 | C30: 0 | D30: =C30/$C$151 -> 0
A31: China | B31: 4.2558828 | C31: 0.143 | D31: =C31/$C$151 -> 0.16999524 | E31: Includes Taiwan
A32: Colombia | B32: 5.724794 | C32: 0 | D32: =C32/$C$151 -> 0
A33: Congo, Rep. | B33: 5.6489161 | C33: 0 | D33: =C33/$C$151 -> 0
A34: Costa Rica | B34: 4.2297468 | C34: 0 | D34: =C34/$C$151 -> 0
A35: Cote d'Ivoire | B35: 5.5958392 | C35: 0 | D35: =C35/$C$151 -> 0
A36: Croatia | B36: 4.2818307 | C36: 0 | D36: =C36/$C$151 -> 0
A37: Cyprus | B37: 4.6657023 | C37: 0 | D37: =C37/$C$151 -> 0
A38: Czech Republic | B38: 3.748497 | C38: 0 | D38: =C38/$C$151 -> 0
A39: Denmark | B39: 3.1990776 | C39: 0 | D39: =C39/$C$151 -> 0
A40: Djibouti | B40: 5.9780559 | C40: 0 | D40: =C40/$C$151 -> 0
A41: Dominican Republic | B41: 4.6951386 | C41: 0 | D41: =C41/$C$151 -> 0
A42: Ecuador | B42: 5.7086244 | C42: 0 | D42: =C42/$C$151 -> 0
A43: Egypt | B43: 5.6039767 | C43: 0 | D43: =C43/$C$151 -> 0
... A150: Zimbabwe | B150: 6.1447845 | C150: 0 | D150: =C150/$C$151 -> 0
A151: TOTAL | C151: =SUM(C4:C150) -> 0.8412 | D151: =SUM(D4:D150) -> 1

Sheet Country of Revenues - Meta
A1: Meta
A3: Country of Revenue | B3: Country Geopolitical Risk Index | C3: Percentage of Revenues | D3: Percentage of Revenues Standardized
A4: Albania | B4: 4.3705708 | C4: 0 | D4: =C4/$C$151 -> 0
A5: Algeria | B5: 5.2136193 | C5: 0 | D5: =C5/$C$151 -> 0 | G5: Main Data
A6: Angola | B6: 5.6305966 | C6: 0 | D6: =C6/$C$151 -> 0 | H6: Country | I6: Geopolitical Risk Index | J6: Value
A7: Argentina | B7: 4.3620978 | C7: 0 | D7: =C7/$C$151 -> 0 | G7: Minimum | H7: =INDEX(A4:A150,MATCH(MIN(D4:D150),D4:D150,0)) -> Albania | I7: =INDEX(B4:B150,MATCH(MIN(D4:D150),D4:D150,0)) -> 4.3705708 | J7: =INDEX(D4:D150,MATCH(MIN(D4:D150),D4:D150,0)) -> 0
A8: Armenia | B8: 4.7882033 | C8: 0 | D8: =C8/$C$151 -> 0 | G8: Maximum | H8: =INDEX(A4:A150,MATCH(MAX(D4:D150),D4:D150,0)) -> United States | I8: =INDEX(B4:B150,MATCH(MAX(D4:D150),D4:D150,0)) -> 4.1903554 | J8: =INDEX(D4:D150,MATCH(MAX(D4:D150),D4:D150,0)) -> 0.43093111
A9: Australia | B9: 3.2228923 | C9: 0 | D9: =C9/$C$151 -> 0 | G9: Component - Revenues | J9: =SUMPRODUCT(B4:B150,D4:D150) -> 4.0756275
A10: Austria | B10: 3.4101851 | C10: 0 | D10: =C10/$C$151 -> 0
A11: Azerbaijan | B11: 5.2109259 | C11: 0 | D11: =C11/$C$151 -> 0
A12: Bahrain | B12: 4.2572307 | C12: 0 | D12: =C12/$C$151 -> 0
A13: Bangladesh | B13: 6.2938646 | C13: 0 | D13: =C13/$C$151 -> 0
A14: Belarus | B14: 5.4470392 | C14: 0 | D14: =C14/$C$151 -> 0
A15: Belgium | B15: 3.3272157 | C15: 0 | D15: =C15/$C$151 -> 0
A16: Benin | B16: 5.9976204 | C16: 0 | D16: =C16/$C$151 -> 0
A17: Bhutan | B17: 5.0248646 | C17: 0 | D17: =C17/$C$151 -> 0
A18: Bolivia | B18: 5.4119735 | C18: 0 | D18: =C18/$C$151 -> 0
A19: Bosnia and Herzegovina | B19: 5.3424605 | C19: 0 | D19: =C19/$C$151 -> 0
A20: Botswana | B20: 4.3392269 | C20: 0 | D20: =C20/$C$151 -> 0
A21: Brazil | B21: 5.352888 | C21: 0.0125 | D21: =C21/$C$151 -> 0.015294262
... A30: Chile | B30: 4.3579263 | C30: 0 | D30: =C30/$C$151 -> 0
A31: China | B31: 4.2558828 | C31: 0.0912 | D31: =C31/$C$151 -> 0.11158693 | E31: Includes Taiwan
A32: Colombia | B32: 5.724794 | C32: 0 | D32: =C32/$C$151 -> 0
A33: Congo, Rep. | B33: 5.6489161 | C33: 0 | D33: =C33/$C$151 -> 0
A34: Costa Rica | B34: 4.2297468 | C34: 0 | D34: =C34/$C$151 -> 0
A35: Cote d'Ivoire | B35: 5.5958392 | C35: 0 | D35: =C35/$C$151 -> 0
A36: Croatia | B36: 4.2818307 | C36: 0 | D36: =C36/$C$151 -> 0
A37: Cyprus | B37: 4.6657023 | C37: 0 | D37: =C37/$C$151 -> 0
A38: Czech Republic | B38: 3.748497 | C38: 0 | D38: =C38/$C$151 -> 0
A39: Denmark | B39: 3.1990776 | C39: 0 | D39: =C39/$C$151 -> 0
A40: Djibouti | B40: 5.9780559 | C40: 0 | D40: =C40/$C$151 -> 0
A41: Dominican Republic | B41: 4.6951386 | C41: 0 | D41: =C41/$C$151 -> 0
A42: Ecuador | B42: 5.7086244 | C42: 0 | D42: =C42/$C$151 -> 0
A43: Egypt | B43: 5.6039767 | C43: 0 | D43: =C43/$C$151 -> 0
... A150: Zimbabwe | B150: 6.1447845 | C150: 0 | D150: =C150/$C$151 -> 0
A151: TOTAL | C151: =SUM(C4:C150) -> 0.8173 | D151: =SUM(D4:D150) -> 1

Sheet Country of Revenues - Microsoft
A1: Microsoft
A3: Country of Revenue | B3: Country Geopolitical Risk Index | C3: Percentage of Revenues | D3: Percentage of Revenues Standardized
A4: Albania | B4: 4.3705708 | C4: 0 | D4: =C4/$C$151 -> 0
A5: Algeria | B5: 5.2136193 | C5: 0 | D5: =C5/$C$151 -> 0 | G5: Main Data
A6: Angola | B6: 5.6305966 | C6: 0 | D6: =C6/$C$151 -> 0 | H6: Country | I6: Geopolitical Risk Index | J6: Value
A7: Argentina | B7: 4.3620978 | C7: 0 | D7: =C7/$C$151 -> 0 | G7: Minimum | H7: =INDEX(A4:A150,MATCH(MIN(D4:D150),D4:D150,0)) -> Albania | I7: =INDEX(B4:B150,MATCH(MIN(D4:D150),D4:D150,0)) -> 4.3705708 | J7: =INDEX(D4:D150,MATCH(MIN(D4:D150),D4:D150,0)) -> 0
A8: Armenia | B8: 4.7882033 | C8: 0 | D8: =C8/$C$151 -> 0 | G8: Maximum | H8: =INDEX(A4:A150,MATCH(MAX(D4:D150),D4:D150,0)) -> United States | I8: =INDEX(B4:B150,MATCH(MAX(D4:D150),D4:D150,0)) -> 4.1903554 | J8: =INDEX(D4:D150,MATCH(MAX(D4:D150),D4:D150,0)) -> 0.6148592
A9: Australia | B9: 3.2228923 | C9: 0.01 | D9: =C9/$C$151 -> 0.011983223 | G9: Component - Revenues | J9: =SUMPRODUCT(B4:B150,D4:D150) -> 4.1699698
A10: Austria | B10: 3.4101851 | C10: 0 | D10: =C10/$C$151 -> 0
A11: Azerbaijan | B11: 5.2109259 | C11: 0 | D11: =C11/$C$151 -> 0
A12: Bahrain | B12: 4.2572307 | C12: 0 | D12: =C12/$C$151 -> 0
A13: Bangladesh | B13: 6.2938646 | C13: 0 | D13: =C13/$C$151 -> 0
A14: Belarus | B14: 5.4470392 | C14: 0 | D14: =C14/$C$151 -> 0
A15: Belgium | B15: 3.3272157 | C15: 0 | D15: =C15/$C$151 -> 0
A16: Benin | B16: 5.9976204 | C16: 0 | D16: =C16/$C$151 -> 0
A17: Bhutan | B17: 5.0248646 | C17: 0 | D17: =C17/$C$151 -> 0
A18: Bolivia | B18: 5.4119735 | C18: 0 | D18: =C18/$C$151 -> 0
A19: Bosnia and Herzegovina | B19: 5.3424605 | C19: 0 | D19: =C19/$C$151 -> 0
A20: Botswana | B20: 4.3392269 | C20: 0 | D20: =C20/$C$151 -> 0
A21: Brazil | B21: 5.352888 | C21: 0.0151 | D21: =C21/$C$151 -> 0.018094667
... A30: Chile | B30: 4.3579263 | C30: 0 | D30: =C30/$C$151 -> 0
A31: China | B31: 4.2558828 | C31: 0.1124 | D31: =C31/$C$151 -> 0.13469143 | E31: Includes Taiwan
A32: Colombia | B32: 5.724794 | C32: 0 | D32: =C32/$C$151 -> 0
A33: Congo, Rep. | B33: 5.6489161 | C33: 0 | D33: =C33/$C$151 -> 0
A34: Costa Rica | B34: 4.2297468 | C34: 0 | D34: =C34/$C$151 -> 0
A35: Cote d'Ivoire | B35: 5.5958392 | C35: 0 | D35: =C35/$C$151 -> 0
A36: Croatia | B36: 4.2818307 | C36: 0 | D36: =C36/$C$151 -> 0
A37: Cyprus | B37: 4.6657023 | C37: 0 | D37: =C37/$C$151 -> 0
A38: Czech Republic | B38: 3.748497 | C38: 0 | D38: =C38/$C$151 -> 0
A39: Denmark | B39: 3.1990776 | C39: 0 | D39: =C39/$C$151 -> 0
A40: Djibouti | B40: 5.9780559 | C40: 0 | D40: =C40/$C$151 -> 0
A41: Dominican Republic | B41: 4.6951386 | C41: 0 | D41: =C41/$C$151 -> 0
A42: Ecuador | B42: 5.7086244 | C42: 0 | D42: =C42/$C$151 -> 0
A43: Egypt | B43: 5.6039767 | C43: 0 | D43: =C43/$C$151 -> 0
... A150: Zimbabwe | B150: 6.1447845 | C150: 0 | D150: =C150/$C$151 -> 0
A151: TOTAL | C151: =SUM(C4:C150) -> 0.8345 | D151: =SUM(D4:D150) -> 1

Sheet Country of Revenues - Ford
A1: Ford
A3: Country of Revenue | B3: Country Geopolitical Risk Index | C3: Percentage of Revenues | D3: Percentage of Revenues Standardized
A4: Albania | B4: 4.3705708 | C4: 0 | D4: =C4/$C$151 -> 0
A5: Algeria | B5: 5.2136193 | C5: 0 | D5: =C5/$C$151 -> 0 | G5: Main Data
A6: Angola | B6: 5.6305966 | C6: 0 | D6: =C6/$C$151 -> 0 | H6: Country | I6: Geopolitical Risk Index | J6: Value
A7: Argentina | B7: 4.3620978 | C7: 0 | D7: =C7/$C$151 -> 0 | G7: Minimum | H7: =INDEX(A4:A150,MATCH(MIN(D4:D150),D4:D150,0)) -> Albania | I7: =INDEX(B4:B150,MATCH(MIN(D4:D150),D4:D150,0)) -> 4.3705708 | J7: =INDEX(D4:D150,MATCH(MIN(D4:D150),D4:D150,0)) -> 0
A8: Armenia | B8: 4.7882033 | C8: 0 | D8: =C8/$C$151 -> 0 | G8: Maximum | H8: =INDEX(A4:A150,MATCH(MAX(D4:D150),D4:D150,0)) -> United States | I8: =INDEX(B4:B150,MATCH(MAX(D4:D150),D4:D150,0)) -> 4.1903554 | J8: =INDEX(D4:D150,MATCH(MAX(D4:D150),D4:D150,0)) -> 0.76264274
A9: Australia | B9: 3.2228923 | C9: 0 | D9: =C9/$C$151 -> 0 | G9: Component - Revenues | J9: =SUMPRODUCT(B4:B150,D4:D150) -> 4.0784836
A10: Austria | B10: 3.4101851 | C10: 0 | D10: =C10/$C$151 -> 0
A11: Azerbaijan | B11: 5.2109259 | C11: 0 | D11: =C11/$C$151 -> 0
A12: Bahrain | B12: 4.2572307 | C12: 0 | D12: =C12/$C$151 -> 0
A13: Bangladesh | B13: 6.2938646 | C13: 0 | D13: =C13/$C$151 -> 0
A14: Belarus | B14: 5.4470392 | C14: 0 | D14: =C14/$C$151 -> 0
A15: Belgium | B15: 3.3272157 | C15: 0 | D15: =C15/$C$151 -> 0
A16: Benin | B16: 5.9976204 | C16: 0 | D16: =C16/$C$151 -> 0
A17: Bhutan | B17: 5.0248646 | C17: 0 | D17: =C17/$C$151 -> 0
A18: Bolivia | B18: 5.4119735 | C18: 0 | D18: =C18/$C$151 -> 0
A19: Bosnia and Herzegovina | B19: 5.3424605 | C19: 0 | D19: =C19/$C$151 -> 0
A20: Botswana | B20: 4.3392269 | C20: 0 | D20: =C20/$C$151 -> 0
A21: Brazil | B21: 5.352888 | C21: 0 | D21: =C21/$C$151 -> 0
... A30: Chile | B30: 4.3579263 | C30: 0 | D30: =C30/$C$151 -> 0
A31: China | B31: 4.2558828 | C31: 0.0471 | D31: =C31/$C$151 -> 0.054882312 | E31: Includes Taiwan
A32: Colombia | B32: 5.724794 | C32: 0 | D32: =C32/$C$151 -> 0
A33: Congo, Rep. | B33: 5.6489161 | C33: 0 | D33: =C33/$C$151 -> 0
A34: Costa Rica | B34: 4.2297468 | C34: 0 | D34: =C34/$C$151 -> 0
A35: Cote d'Ivoire | B35: 5.5958392 | C35: 0 | D35: =C35/$C$151 -> 0
A36: Croatia | B36: 4.2818307 | C36: 0 | D36: =C36/$C$151 -> 0
A37: Cyprus | B37: 4.6657023 | C37: 0 | D37: =C37/$C$151 -> 0
A38: Czech Republic | B38: 3.748497 | C38: 0 | D38: =C38/$C$151 -> 0
A39: Denmark | B39: 3.1990776 | C39: 0 | D39: =C39/$C$151 -> 0
A40: Djibouti | B40: 5.9780559 | C40: 0 | D40: =C40/$C$151 -> 0
A41: Dominican Republic | B41: 4.6951386 | C41: 0 | D41: =C41/$C$151 -> 0
A42: Ecuador | B42: 5.7086244 | C42: 0 | D42: =C42/$C$151 -> 0
A43: Egypt | B43: 5.6039767 | C43: 0 | D43: =C43/$C$151 -> 0
... A150: Zimbabwe | B150: 6.1447845 | C150: 0 | D150: =C150/$C$151 -> 0
A151: TOTAL | C151: =SUM(C4:C150) -> 0.8582 | D151: =SUM(D4:D150) -> 1

Sheet Country of Revenues - P&G
A1: Procter & Gamble
A3: Country of Revenue | B3: Country Geopolitical Risk Index | C3: Percentage of Revenues | D3: Percentage of Revenues Standardized
A4: Albania | B4: 4.3705708 | C4: 0 | D4: =C4/$C$151 -> 0
A5: Algeria | B5: 5.2136193 | C5: 0 | D5: =C5/$C$151 -> 0 | G5: Main Data
A6: Angola | B6: 5.6305966 | C6: 0 | D6: =C6/$C$151 -> 0 | H6: Country | I6: Geopolitical Risk Index | J6: Value
A7: Argentina | B7: 4.3620978 | C7: 0 | D7: =C7/$C$151 -> 0 | G7: Minimum | H7: =INDEX(A4:A150,MATCH(MIN(D4:D150),D4:D150,0)) -> Albania | I7: =INDEX(B4:B150,MATCH(MIN(D4:D150),D4:D150,0)) -> 4.3705708 | J7: =INDEX(D4:D150,MATCH(MIN(D4:D150),D4:D150,0)) -> 0
A8: Armenia | B8: 4.7882033 | C8: 0 | D8: =C8/$C$151 -> 0 | G8: Maximum | H8: =INDEX(A4:A150,MATCH(MAX(D4:D150),D4:D150,0)) -> United States | I8: =INDEX(B4:B150,MATCH(MAX(D4:D150),D4:D150,0)) -> 4.1903554 | J8: =INDEX(D4:D150,MATCH(MAX(D4:D150),D4:D150,0)) -> 0.58563798
A9: Australia | B9: 3.2228923 | C9: 0.0103 | D9: =C9/$C$151 -> 0.012225519 | G9: Component - Revenues | J9: =SUMPRODUCT(B4:B150,D4:D150) -> 4.1662735
A10: Austria | B10: 3.4101851 | C10: 0 | D10: =C10/$C$151 -> 0
A11: Azerbaijan | B11: 5.2109259 | C11: 0 | D11: =C11/$C$151 -> 0
A12: Bahrain | B12: 4.2572307 | C12: 0 | D12: =C12/$C$151 -> 0
A13: Bangladesh | B13: 6.2938646 | C13: 0 | D13: =C13/$C$151 -> 0
A14: Belarus | B14: 5.4470392 | C14: 0 | D14: =C14/$C$151 -> 0
A15: Belgium | B15: 3.3272157 | C15: 0 | D15: =C15/$C$151 -> 0
A16: Benin | B16: 5.9976204 | C16: 0 | D16: =C16/$C$151 -> 0
A17: Bhutan | B17: 5.0248646 | C17: 0 | D17: =C17/$C$151 -> 0
A18: Bolivia | B18: 5.4119735 | C18: 0 | D18: =C18/$C$151 -> 0
A19: Bosnia and Herzegovina | B19: 5.3424605 | C19: 0 | D19: =C19/$C$151 -> 0
A20: Botswana | B20: 4.3392269 | C20: 0 | D20: =C20/$C$151 -> 0
A21: Brazil | B21: 5.352888 | C21: 0.0158 | D21: =C21/$C$151 -> 0.018753709
... A30: Chile | B30: 4.3579263 | C30: 0 | D30: =C30/$C$151 -> 0
A31: China | B31: 4.2558828 | C31: 0.117 | D31: =C31/$C$151 -> 0.1388724 | E31: Includes Taiwan
A32: Colombia | B32: 5.724794 | C32: 0 | D32: =C32/$C$151 -> 0
A33: Congo, Rep. | B33: 5.6489161 | C33: 0 | D33: =C33/$C$151 -> 0
A34: Costa Rica | B34: 4.2297468 | C34: 0 | D34: =C34/$C$151 -> 0
A35: Cote d'Ivoire | B35: 5.5958392 | C35: 0 | D35: =C35/$C$151 -> 0
A36: Croatia | B36: 4.2818307 | C36: 0 | D36: =C36/$C$151 -> 0
A37: Cyprus | B37: 4.6657023 | C37: 0 | D37: =C37/$C$151 -> 0
A38: Czech Republic | B38: 3.748497 | C38: 0 | D38: =C38/$C$151 -> 0
A39: Denmark | B39: 3.1990776 | C39: 0 | D39: =C39/$C$151 -> 0
A40: Djibouti | B40: 5.9780559 | C40: 0 | D40: =C40/$C$151 -> 0
A41: Dominican Republic | B41: 4.6951386 | C41: 0 | D41: =C41/$C$151 -> 0
A42: Ecuador | B42: 5.7086244 | C42: 0 | D42: =C42/$C$151 -> 0
A43: Egypt | B43: 5.6039767 | C43: 0 | D43: =C43/$C$151 -> 0
... A150: Zimbabwe | B150: 6.1447845 | C150: 0 | D150: =C150/$C$151 -> 0
A151: TOTAL | C151: =SUM(C4:C150) -> 0.8425 | D151: =SUM(D4:D150) -> 1

Sheet Country of Revenues - Samsung
A1: Samsung
A3: Country of Revenue | B3: Country Geopolitical Risk Index | C3: Percentage of Revenues | D3: Percentage of Revenues Standardized
A4: Albania | B4: 4.3705708 | C4: 0 | D4: =C4/$C$151 -> 0
A5: Algeria | B5: 5.2136193 | C5: 0 | D5: =C5/$C$151 -> 0 | G5: Main Data
A6: Angola | B6: 5.6305966 | C6: 0 | D6: =C6/$C$151 -> 0 | H6: Country | I6: Geopolitical Risk Index | J6: Value
A7: Argentina | B7: 4.3620978 | C7: 0 | D7: =C7/$C$151 -> 0 | G7: Minimum | H7: =INDEX(A4:A150,MATCH(MIN(D4:D150),D4:D150,0)) -> Albania | I7: =INDEX(B4:B150,MATCH(MIN(D4:D150),D4:D150,0)) -> 4.3705708 | J7: =INDEX(D4:D150,MATCH(MIN(D4:D150),D4:D150,0)) -> 0
A8: Armenia | B8: 4.7882033 | C8: 0 | D8: =C8/$C$151 -> 0 | G8: Maximum | H8: =INDEX(A4:A150,MATCH(MAX(D4:D150),D4:D150,0)) -> United States | I8: =INDEX(B4:B150,MATCH(MAX(D4:D150),D4:D150,0)) -> 4.1903554 | J8: =INDEX(D4:D150,MATCH(MAX(D4:D150),D4:D150,0)) -> 0.33784253
A9: Australia | B9: 3.2228923 | C9: 0 | D9: =C9/$C$151 -> 0 | G9: Component - Revenues | J9: =SUMPRODUCT(B4:B150,D4:D150) -> 4.0305108
A10: Austria | B10: 3.4101851 | C10: 0 | D10: =C10/$C$151 -> 0
A11: Azerbaijan | B11: 5.2109259 | C11: 0 | D11: =C11/$C$151 -> 0
A12: Bahrain | B12: 4.2572307 | C12: 0 | D12: =C12/$C$151 -> 0
A13: Bangladesh | B13: 6.2938646 | C13: 0 | D13: =C13/$C$151 -> 0
A14: Belarus | B14: 5.4470392 | C14: 0 | D14: =C14/$C$151 -> 0
A15: Belgium | B15: 3.3272157 | C15: 0 | D15: =C15/$C$151 -> 0
A16: Benin | B16: 5.9976204 | C16: 0 | D16: =C16/$C$151 -> 0
A17: Bhutan | B17: 5.0248646 | C17: 0 | D17: =C17/$C$151 -> 0
A18: Bolivia | B18: 5.4119735 | C18: 0 | D18: =C18/$C$151 -> 0
A19: Bosnia and Herzegovina | B19: 5.3424605 | C19: 0 | D19: =C19/$C$151 -> 0
A20: Botswana | B20: 4.3392269 | C20: 0 | D20: =C20/$C$151 -> 0
A21: Brazil | B21: 5.352888 | C21: 0.0246 | D21: =C21/$C$151 -> 0.028442595
... A30: Chile | B30: 4.3579263 | C30: 0.0094 | D30: =C30/$C$151 -> 0.010868308
A31: China | B31: 4.2558828 | C31: 0.1418 | D31: =C31/$C$151 -> 0.16394959 | E31: Includes Taiwan
A32: Colombia | B32: 5.724794 | C32: 0 | D32: =C32/$C$151 -> 0
A33: Congo, Rep. | B33: 5.6489161 | C33: 0 | D33: =C33/$C$151 -> 0
A34: Costa Rica | B34: 4.2297468 | C34: 0 | D34: =C34/$C$151 -> 0
A35: Cote d'Ivoire | B35: 5.5958392 | C35: 0 | D35: =C35/$C$151 -> 0
A36: Croatia | B36: 4.2818307 | C36: 0 | D36: =C36/$C$151 -> 0
A37: Cyprus | B37: 4.6657023 | C37: 0 | D37: =C37/$C$151 -> 0
A38: Czech Republic | B38: 3.748497 | C38: 0 | D38: =C38/$C$151 -> 0
A39: Denmark | B39: 3.1990776 | C39: 0 | D39: =C39/$C$151 -> 0
A40: Djibouti | B40: 5.9780559 | C40: 0 | D40: =C40/$C$151 -> 0
A41: Dominican Republic | B41: 4.6951386 | C41: 0 | D41: =C41/$C$151 -> 0
A42: Ecuador | B42: 5.7086244 | C42: 0 | D42: =C42/$C$151 -> 0
A43: Egypt | B43: 5.6039767 | C43: 0 | D43: =C43/$C$151 -> 0
... A150: Zimbabwe | B150: 6.1447845 | C150: 0 | D150: =C150/$C$151 -> 0
A151: TOTAL | C151: =SUM(C4:C150) -> 0.8649 | D151: =SUM(D4:D150) -> 1

Sheet Country of Revenues - Amazon
A1: Amazon
A3: Country of Revenue | B3: Country Geopolitical Risk Index | C3: Percentage of Revenues | D3: Percentage of Revenues Standardized
A4: Albania | B4: 4.3705708 | C4: 0 | D4: =C4/$C$151 -> 0
A5: Algeria | B5: 5.2136193 | C5: 0 | D5: =C5/$C$151 -> 0 | G5: Main Data
A6: Angola | B6: 5.6305966 | C6: 0 | D6: =C6/$C$151 -> 0 | H6: Country | I6: Geopolitical Risk Index | J6: Value
A7: Argentina | B7: 4.3620978 | C7: 0 | D7: =C7/$C$151 -> 0 | G7: Minimum | H7: =INDEX(A4:A150,MATCH(MIN(D4:D150),D4:D150,0)) -> Albania | I7: =INDEX(B4:B150,MATCH(MIN(D4:D150),D4:D150,0)) -> 4.3705708 | J7: =INDEX(D4:D150,MATCH(MIN(D4:D150),D4:D150,0)) -> 0
A8: Armenia | B8: 4.7882033 | C8: 0 | D8: =C8/$C$151 -> 0 | G8: Maximum | H8: =INDEX(A4:A150,MATCH(MAX(D4:D150),D4:D150,0)) -> United States | I8: =INDEX(B4:B150,MATCH(MAX(D4:D150),D4:D150,0)) -> 4.1903554 | J8: =INDEX(D4:D150,MATCH(MAX(D4:D150),D4:D150,0)) -> 0.80343489
A9: Australia | B9: 3.2228923 | C9: 0 | D9: =C9/$C$151 -> 0 | G9: Component - Revenues | J9: =SUMPRODUCT(B4:B150,D4:D150) -> 4.0292105
A10: Austria | B10: 3.4101851 | C10: 0 | D10: =C10/$C$151 -> 0
A11: Azerbaijan | B11: 5.2109259 | C11: 0 | D11: =C11/$C$151 -> 0
A12: Bahrain | B12: 4.2572307 | C12: 0 | D12: =C12/$C$151 -> 0
A13: Bangladesh | B13: 6.2938646 | C13: 0 | D13: =C13/$C$151 -> 0
A14: Belarus | B14: 5.4470392 | C14: 0 | D14: =C14/$C$151 -> 0
A15: Belgium | B15: 3.3272157 | C15: 0 | D15: =C15/$C$151 -> 0
A16: Benin | B16: 5.9976204 | C16: 0 | D16: =C16/$C$151 -> 0
A17: Bhutan | B17: 5.0248646 | C17: 0 | D17: =C17/$C$151 -> 0
A18: Bolivia | B18: 5.4119735 | C18: 0 | D18: =C18/$C$151 -> 0
A19: Bosnia and Herzegovina | B19: 5.3424605 | C19: 0 | D19: =C19/$C$151 -> 0
A20: Botswana | B20: 4.3392269 | C20: 0 | D20: =C20/$C$151 -> 0
A21: Brazil | B21: 5.352888 | C21: 0 | D21: =C21/$C$151 -> 0
... A30: Chile | B30: 4.3579263 | C30: 0 | D30: =C30/$C$151 -> 0
A31: China | B31: 4.2558828 | C31: 0 | D31: =C31/$C$151 -> 0 | E31: Includes Taiwan
A32: Colombia | B32: 5.724794 | C32: 0 | D32: =C32/$C$151 -> 0
A33: Congo, Rep. | B33: 5.6489161 | C33: 0 | D33: =C33/$C$151 -> 0
A34: Costa Rica | B34: 4.2297468 | C34: 0 | D34: =C34/$C$151 -> 0
A35: Cote d'Ivoire | B35: 5.5958392 | C35: 0 | D35: =C35/$C$151 -> 0
A36: Croatia | B36: 4.2818307 | C36: 0 | D36: =C36/$C$151 -> 0
A37: Cyprus | B37: 4.6657023 | C37: 0 | D37: =C37/$C$151 -> 0
A38: Czech Republic | B38: 3.748497 | C38: 0 | D38: =C38/$C$151 -> 0
A39: Denmark | B39: 3.1990776 | C39: 0 | D39: =C39/$C$151 -> 0
A40: Djibouti | B40: 5.9780559 | C40: 0 | D40: =C40/$C$151 -> 0
A41: Dominican Republic | B41: 4.6951386 | C41: 0 | D41: =C41/$C$151 -> 0
A42: Ecuador | B42: 5.7086244 | C42: 0 | D42: =C42/$C$151 -> 0
A43: Egypt | B43: 5.6039767 | C43: 0 | D43: =C43/$C$151 -> 0
... A150: Zimbabwe | B150: 6.1447845 | C150: 0 | D150: =C150/$C$151 -> 0
A151: TOTAL | C151: =SUM(C4:C150) -> 0.8501 | D151: =SUM(D4:D150) -> 1

Sheet Country of Revenues - NVIDIA
A1: NVIDIA
A3: Country of Revenue | B3: Country Geopolitical Risk Index | C3: Percentage of Revenues | D3: Percentage of Revenues Standardized
A4: Albania | B4: 4.3705708 | C4: 0 | D4: =C4/$C$151 -> 0
A5: Algeria | B5: 5.2136193 | C5: 0 | D5: =C5/$C$151 -> 0 | G5: Main Data
A6: Angola | B6: 5.6305966 | C6: 0 | D6: =C6/$C$151 -> 0 | H6: Country | I6: Geopolitical Risk Index | J6: Value
A7: Argentina | B7: 4.3620978 | C7: 0 | D7: =C7/$C$151 -> 0 | G7: Minimum | H7: =INDEX(A4:A150,MATCH(MIN(D4:D150),D4:D150,0)) -> Albania | I7: =INDEX(B4:B150,MATCH(MIN(D4:D150),D4:D150,0)) -> 4.3705708 | J7: =INDEX(D4:D150,MATCH(MIN(D4:D150),D4:D150,0)) -> 0
A8: Armenia | B8: 4.7882033 | C8: 0 | D8: =C8/$C$151 -> 0 | G8: Maximum | H8: =INDEX(A4:A150,MATCH(MAX(D4:D150),D4:D150,0)) -> United States | I8: =INDEX(B4:B150,MATCH(MAX(D4:D150),D4:D150,0)) -> 4.1903554 | J8: =INDEX(D4:D150,MATCH(MAX(D4:D150),D4:D150,0)) -> 0.71565792
A9: Australia | B9: 3.2228923 | C9: 0 | D9: =C9/$C$151 -> 0 | G9: Component - Revenues | J9: =SUMPRODUCT(B4:B150,D4:D150) -> 4.2089876
A10: Austria | B10: 3.4101851 | C10: 0 | D10: =C10/$C$151 -> 0
A11: Azerbaijan | B11: 5.2109259 | C11: 0 | D11: =C11/$C$151 -> 0
A12: Bahrain | B12: 4.2572307 | C12: 0 | D12: =C12/$C$151 -> 0
A13: Bangladesh | B13: 6.2938646 | C13: 0 | D13: =C13/$C$151 -> 0
A14: Belarus | B14: 5.4470392 | C14: 0 | D14: =C14/$C$151 -> 0
A15: Belgium | B15: 3.3272157 | C15: 0 | D15: =C15/$C$151 -> 0
A16: Benin | B16: 5.9976204 | C16: 0 | D16: =C16/$C$151 -> 0
A17: Bhutan | B17: 5.0248646 | C17: 0 | D17: =C17/$C$151 -> 0
A18: Bolivia | B18: 5.4119735 | C18: 0 | D18: =C18/$C$151 -> 0
A19: Bosnia and Herzegovina | B19: 5.3424605 | C19: 0 | D19: =C19/$C$151 -> 0
A20: Botswana | B20: 4.3392269 | C20: 0 | D20: =C20/$C$151 -> 0
A21: Brazil | B21: 5.352888 | C21: 0 | D21: =C21/$C$151 -> 0
... A30: Chile | B30: 4.3579263 | C30: 0 | D30: =C30/$C$151 -> 0
A31: China | B31: 4.2558828 | C31: 0.2753 | D31: =C31/$C$151 -> 0.28434208 | E31: Includes Taiwan
A32: Colombia | B32: 5.724794 | C32: 0 | D32: =C32/$C$151 -> 0
A33: Congo, Rep. | B33: 5.6489161 | C33: 0 | D33: =C33/$C$151 -> 0
A34: Costa Rica | B34: 4.2297468 | C34: 0 | D34: =C34/$C$151 -> 0
A35: Cote d'Ivoire | B35: 5.5958392 | C35: 0 | D35: =C35/$C$151 -> 0
A36: Croatia | B36: 4.2818307 | C36: 0 | D36: =C36/$C$151 -> 0
A37: Cyprus | B37: 4.6657023 | C37: 0 | D37: =C37/$C$151 -> 0
A38: Czech Republic | B38: 3.748497 | C38: 0 | D38: =C38/$C$151 -> 0
A39: Denmark | B39: 3.1990776 | C39: 0 | D39: =C39/$C$151 -> 0
A40: Djibouti | B40: 5.9780559 | C40: 0 | D40: =C40/$C$151 -> 0
A41: Dominican Republic | B41: 4.6951386 | C41: 0 | D41: =C41/$C$151 -> 0
A42: Ecuador | B42: 5.7086244 | C42: 0 | D42: =C42/$C$151 -> 0
A43: Egypt | B43: 5.6039767 | C43: 0 | D43: =C43/$C$151 -> 0
... A150: Zimbabwe | B150: 6.1447845 | C150: 0 | D150: =C150/$C$151 -> 0
A151: TOTAL | C151: =SUM(C4:C150) -> 0.9682 | D151: =SUM(D4:D150) -> 1

Sheet Country of Revenues - Allianz
A1: Allianz
A3: Country of Revenue | B3: Country Geopolitical Risk Index | C3: Percentage of Revenues | D3: Percentage of Revenues Standardized
A4: Albania | B4: 4.3705708 | C4: 0 | D4: =C4/$C$151 -> 0
A5: Algeria | B5: 5.2136193 | C5: 0 | D5: =C5/$C$151 -> 0 | G5: Main Data
A6: Angola | B6: 5.6305966 | C6: 0 | D6: =C6/$C$151 -> 0 | H6: Country | I6: Geopolitical Risk Index | J6: Value
A7: Argentina | B7: 4.3620978 | C7: 0.0033 | D7: =C7/$C$151 -> 0.0035939882 | G7: Minimum | H7: =INDEX(A4:A150,MATCH(MIN(D4:D150),D4:D150,0)) -> Albania | I7: =INDEX(B4:B150,MATCH(MIN(D4:D150),D4:D150,0)) -> 4.3705708 | J7: =INDEX(D4:D150,MATCH(MIN(D4:D150),D4:D150,0)) -> 0
A8: Armenia | B8: 4.7882033 | C8: 0 | D8: =C8/$C$151 -> 0 | G8: Maximum | H8: =INDEX(A4:A150,MATCH(MAX(D4:D150),D4:D150,0)) -> Germany | I8: =INDEX(B4:B150,MATCH(MAX(D4:D150),D4:D150,0)) -> 3.4167336 | J8: =INDEX(D4:D150,MATCH(MAX(D4:D150),D4:D150,0)) -> 0.18133304
A9: Australia | B9: 3.2228923 | C9: 0.0559 | D9: =C9/$C$151 -> 0.060879983 | G9: Component - Revenues | J9: =SUMPRODUCT(B4:B150,D4:D150) -> 3.7720216
A10: Austria | B10: 3.4101851 | C10: 0.0158 | D10: =C10/$C$151 -> 0.01720758
A11: Azerbaijan | B11: 5.2109259 | C11: 0 | D11: =C11/$C$151 -> 0
A12: Bahrain | B12: 4.2572307 | C12: 0 | D12: =C12/$C$151 -> 0
A13: Bangladesh | B13: 6.2938646 | C13: 0 | D13: =C13/$C$151 -> 0
A14: Belarus | B14: 5.4470392 | C14: 0 | D14: =C14/$C$151 -> 0
A15: Belgium | B15: 3.3272157 | C15: 0.0397 | D15: =C15/$C$151 -> 0.043236768
A16: Benin | B16: 5.9976204 | C16: 0 | D16: =C16/$C$151 -> 0
A17: Bhutan | B17: 5.0248646 | C17: 0 | D17: =C17/$C$151 -> 0
A18: Bolivia | B18: 5.4119735 | C18: 0 | D18: =C18/$C$151 -> 0
A19: Bosnia and Herzegovina | B19: 5.3424605 | C19: 0 | D19: =C19/$C$151 -> 0
A20: Botswana | B20: 4.3392269 | C20: 0 | D20: =C20/$C$151 -> 0
A21: Brazil | B21: 5.352888 | C21: 0.0128 | D21: =C21/$C$151 -> 0.013940318
... A30: Chile | B30: 4.3579263 | C30: 0.0019 | D30: =C30/$C$151 -> 0.002069266
A31: China | B31: 4.2558828 | C31: 0.0317 | D31: =C31/$C$151 -> 0.034524069 | E31: Includes Taiwan
A32: Colombia | B32: 5.724794 | C32: 0 | D32: =C32/$C$151 -> 0
A33: Congo, Rep. | B33: 5.6489161 | C33: 0 | D33: =C33/$C$151 -> 0
A34: Costa Rica | B34: 4.2297468 | C34: 0 | D34: =C34/$C$151 -> 0
A35: Cote d'Ivoire | B35: 5.5958392 | C35: 0 | D35: =C35/$C$151 -> 0
A36: Croatia | B36: 4.2818307 | C36: 0 | D36: =C36/$C$151 -> 0
A37: Cyprus | B37: 4.6657023 | C37: 0 | D37: =C37/$C$151 -> 0
A38: Czech Republic | B38: 3.748497 | C38: 0.0218 | D38: =C38/$C$151 -> 0.023742104
A39: Denmark | B39: 3.1990776 | C39: 0.0052 | D39: =C39/$C$151 -> 0.0056632542
A40: Djibouti | B40: 5.9780559 | C40: 0 | D40: =C40/$C$151 -> 0
A41: Dominican Republic | B41: 4.6951386 | C41: 0 | D41: =C41/$C$151 -> 0
A42: Ecuador | B42: 5.7086244 | C42: 0 | D42: =C42/$C$151 -> 0
A43: Egypt | B43: 5.6039767 | C43: 0.0018 | D43: =C43/$C$151 -> 0.0019603572
... A150: Zimbabwe | B150: 6.1447845 | C150: 0 | D150: =C150/$C$151 -> 0
A151: TOTAL | C151: =SUM(C4:C150) -> 0.9182 | D151: =SUM(D4:D150) -> 1

Sheet Country of Revenues - ASML
A1: ASML
A3: Country of Revenue | B3: Country Geopolitical Risk Index | C3: Percentage of Revenues | D3: Percentage of Revenues Standardized
A4: Albania | B4: 4.3705708 | C4: 0 | D4: =C4/$C$151 -> 0
A5: Algeria | B5: 5.2136193 | C5: 0 | D5: =C5/$C$151 -> 0 | G5: Main Data
A6: Angola | B6: 5.6305966 | C6: 0 | D6: =C6/$C$151 -> 0 | H6: Country | I6: Geopolitical Risk Index | J6: Value
A7: Argentina | B7: 4.3620978 | C7: 0 | D7: =C7/$C$151 -> 0 | G7: Minimum | H7: =INDEX(A4:A150,MATCH(MIN(D4:D150),D4:D150,0)) -> Albania | I7: =INDEX(B4:B150,MATCH(MIN(D4:D150),D4:D150,0)) -> 4.3705708 | J7: =INDEX(D4:D150,MATCH(MIN(D4:D150),D4:D150,0)) -> 0
A8: Armenia | B8: 4.7882033 | C8: 0 | D8: =C8/$C$151 -> 0 | G8: Maximum | H8: =INDEX(A4:A150,MATCH(MAX(D4:D150),D4:D150,0)) -> China | I8: =INDEX(B4:B150,MATCH(MAX(D4:D150),D4:D150,0)) -> 4.2558828 | J8: =INDEX(D4:D150,MATCH(MAX(D4:D150),D4:D150,0)) -> 0.55560073
A9: Australia | B9: 3.2228923 | C9: 0 | D9: =C9/$C$151 -> 0 | G9: Component - Revenues | J9: =SUMPRODUCT(B4:B150,D4:D150) -> 4.0105683
A10: Austria | B10: 3.4101851 | C10: 0 | D10: =C10/$C$151 -> 0
A11: Azerbaijan | B11: 5.2109259 | C11: 0 | D11: =C11/$C$151 -> 0
A12: Bahrain | B12: 4.2572307 | C12: 0 | D12: =C12/$C$151 -> 0
A13: Bangladesh | B13: 6.2938646 | C13: 0 | D13: =C13/$C$151 -> 0
A14: Belarus | B14: 5.4470392 | C14: 0 | D14: =C14/$C$151 -> 0
A15: Belgium | B15: 3.3272157 | C15: 0 | D15: =C15/$C$151 -> 0
A16: Benin | B16: 5.9976204 | C16: 0 | D16: =C16/$C$151 -> 0
A17: Bhutan | B17: 5.0248646 | C17: 0 | D17: =C17/$C$151 -> 0
A18: Bolivia | B18: 5.4119735 | C18: 0 | D18: =C18/$C$151 -> 0
A19: Bosnia and Herzegovina | B19: 5.3424605 | C19: 0 | D19: =C19/$C$151 -> 0
A20: Botswana | B20: 4.3392269 | C20: 0 | D20: =C20/$C$151 -> 0
A21: Brazil | B21: 5.352888 | C21: 0 | D21: =C21/$C$151 -> 0
... A30: Chile | B30: 4.3579263 | C30: 0 | D30: =C30/$C$151 -> 0
A31: China | B31: 4.2558828 | C31: 0.5466 | D31: =C31/$C$151 -> 0.55560073 | E31: Includes Taiwan
A32: Colombia | B32: 5.724794 | C32: 0 | D32: =C32/$C$151 -> 0
A33: Congo, Rep. | B33: 5.6489161 | C33: 0 | D33: =C33/$C$151 -> 0
A34: Costa Rica | B34: 4.2297468 | C34: 0 | D34: =C34/$C$151 -> 0
A35: Cote d'Ivoire | B35: 5.5958392 | C35: 0 | D35: =C35/$C$151 -> 0
A36: Croatia | B36: 4.2818307 | C36: 0 | D36: =C36/$C$151 -> 0
A37: Cyprus | B37: 4.6657023 | C37: 0 | D37: =C37/$C$151 -> 0
A38: Czech Republic | B38: 3.748497 | C38: 0 | D38: =C38/$C$151 -> 0
A39: Denmark | B39: 3.1990776 | C39: 0 | D39: =C39/$C$151 -> 0
A40: Djibouti | B40: 5.9780559 | C40: 0 | D40: =C40/$C$151 -> 0
A41: Dominican Republic | B41: 4.6951386 | C41: 0 | D41: =C41/$C$151 -> 0
A42: Ecuador | B42: 5.7086244 | C42: 0 | D42: =C42/$C$151 -> 0
A43: Egypt | B43: 5.6039767 | C43: 0 | D43: =C43/$C$151 -> 0
... A150: Zimbabwe | B150: 6.1447845 | C150: 0 | D150: =C150/$C$151 -> 0
A151: TOTAL | C151: =SUM(C4:C150) -> 0.9838 | D151: =SUM(D4:D150) -> 1

Sheet Country of Revenues - BNP
A1: BNP Paribas
A3: Country of Revenue | B3: Country Geopolitical Risk Index | C3: Percentage of Revenues | D3: Percentage of Revenues Standardized
A4: Albania | B4: 4.3705708 | C4: 0 | D4: =C4/$C$151 -> 0
A5: Algeria | B5: 5.2136193 | C5: 0 | D5: =C5/$C$151 -> 0 | G5: Main Data
A6: Angola | B6: 5.6305966 | C6: 0 | D6: =C6/$C$151 -> 0 | H6: Country | I6: Geopolitical Risk Index | J6: Value
A7: Argentina | B7: 4.3620978 | C7: 0 | D7: =C7/$C$151 -> 0 | G7: Minimum | H7: =INDEX(A4:A150,MATCH(MIN(D4:D150),D4:D150,0)) -> Albania | I7: =INDEX(B4:B150,MATCH(MIN(D4:D150),D4:D150,0)) -> 4.3705708 | J7: =INDEX(D4:D150,MATCH(MIN(D4:D150),D4:D150,0)) -> 0
A8: Armenia | B8: 4.7882033 | C8: 0 | D8: =C8/$C$151 -> 0 | G8: Maximum | H8: =INDEX(A4:A150,MATCH(MAX(D4:D150),D4:D150,0)) -> France | I8: =INDEX(B4:B150,MATCH(MAX(D4:D150),D4:D150,0)) -> 3.6488473 | J8: =INDEX(D4:D150,MATCH(MAX(D4:D150),D4:D150,0)) -> 0.27093353
A9: Australia | B9: 3.2228923 | C9: 0 | D9: =C9/$C$151 -> 0 | G9: Component - Revenues | J9: =SUMPRODUCT(B4:B150,D4:D150) -> 3.7290288
A10: Austria | B10: 3.4101851 | C10: 0.0079 | D10: =C10/$C$151 -> 0.0097422617
A11: Azerbaijan | B11: 5.2109259 | C11: 0 | D11: =C11/$C$151 -> 0
A12: Bahrain | B12: 4.2572307 | C12: 0 | D12: =C12/$C$151 -> 0
A13: Bangladesh | B13: 6.2938646 | C13: 0 | D13: =C13/$C$151 -> 0
A14: Belarus | B14: 5.4470392 | C14: 0 | D14: =C14/$C$151 -> 0
A15: Belgium | B15: 3.3272157 | C15: 0.0496 | D15: =C15/$C$151 -> 0.061166605
A16: Benin | B16: 5.9976204 | C16: 0 | D16: =C16/$C$151 -> 0
A17: Bhutan | B17: 5.0248646 | C17: 0 | D17: =C17/$C$151 -> 0
A18: Bolivia | B18: 5.4119735 | C18: 0 | D18: =C18/$C$151 -> 0
A19: Bosnia and Herzegovina | B19: 5.3424605 | C19: 0 | D19: =C19/$C$151 -> 0
A20: Botswana | B20: 4.3392269 | C20: 0 | D20: =C20/$C$151 -> 0
A21: Brazil | B21: 5.352888 | C21: 0 | D21: =C21/$C$151 -> 0
... A30: Chile | B30: 4.3579263 | C30: 0 | D30: =C30/$C$151 -> 0
A31: China | B31: 4.2558828 | C31: 0.0393 | D31: =C31/$C$151 -> 0.048464669 | E31: Includes Taiwan
A32: Colombia | B32: 5.724794 | C32: 0 | D32: =C32/$C$151 -> 0
A33: Congo, Rep. | B33: 5.6489161 | C33: 0 | D33: =C33/$C$151 -> 0
A34: Costa Rica | B34: 4.2297468 | C34: 0 | D34: =C34/$C$151 -> 0
A35: Cote d'Ivoire | B35: 5.5958392 | C35: 0 | D35: =C35/$C$151 -> 0
A36: Croatia | B36: 4.2818307 | C36: 0 | D36: =C36/$C$151 -> 0
A37: Cyprus | B37: 4.6657023 | C37: 0 | D37: =C37/$C$151 -> 0
A38: Czech Republic | B38: 3.748497 | C38: 0.0078 | D38: =C38/$C$151 -> 0.0096189419
A39: Denmark | B39: 3.1990776 | C39: 0 | D39: =C39/$C$151 -> 0
A40: Djibouti | B40: 5.9780559 | C40: 0 | D40: =C40/$C$151 -> 0
A41: Dominican Republic | B41: 4.6951386 | C41: 0 | D41: =C41/$C$151 -> 0
A42: Ecuador | B42: 5.7086244 | C42: 0 | D42: =C42/$C$151 -> 0
A43: Egypt | B43: 5.6039767 | C43: 0 | D43: =C43/$C$151 -> 0
... A150: Zimbabwe | B150: 6.1447845 | C150: 0 | D150: =C150/$C$151 -> 0
A151: TOTAL | C151: =SUM(C4:C150) -> 0.8109 | D151: =SUM(D4:D150) -> 1

Sheet Country of Revenues - Eli LIlly
A1: Eli Lilly
A3: Country of Revenue | B3: Country Geopolitical Risk Index | C3: Percentage of Revenues | D3: Percentage of Revenues Standardized
A4: Albania | B4: 4.3705708 | C4: 0 | D4: =C4/$C$151 -> 0
A5: Algeria | B5: 5.2136193 | C5: 0 | D5: =C5/$C$151 -> 0 | G5: Main Data
A6: Angola | B6: 5.6305966 | C6: 0 | D6: =C6/$C$151 -> 0 | H6: Country | I6: Geopolitical Risk Index | J6: Value
A7: Argentina | B7: 4.3620978 | C7: 0 | D7: =C7/$C$151 -> 0 | G7: Minimum | H7: =INDEX(A4:A150,MATCH(MIN(D4:D150),D4:D150,0)) -> Albania | I7: =INDEX(B4:B150,MATCH(MIN(D4:D150),D4:D150,0)) -> 4.3705708 | J7: =INDEX(D4:D150,MATCH(MIN(D4:D150),D4:D150,0)) -> 0
A8: Armenia | B8: 4.7882033 | C8: 0 | D8: =C8/$C$151 -> 0 | G8: Maximum | H8: =INDEX(A4:A150,MATCH(MAX(D4:D150),D4:D150,0)) -> United States | I8: =INDEX(B4:B150,MATCH(MAX(D4:D150),D4:D150,0)) -> 4.1903554 | J8: =INDEX(D4:D150,MATCH(MAX(D4:D150),D4:D150,0)) -> 0.33785952
A9: Australia | B9: 3.2228923 | C9: 0.0103 | D9: =C9/$C$151 -> 0.01271448 | G9: Component - Revenues | J9: =SUMPRODUCT(B4:B150,D4:D150) -> 4.1002007
A10: Austria | B10: 3.4101851 | C10: 0 | D10: =C10/$C$151 -> 0
A11: Azerbaijan | B11: 5.2109259 | C11: 0 | D11: =C11/$C$151 -> 0
A12: Bahrain | B12: 4.2572307 | C12: 0 | D12: =C12/$C$151 -> 0
A13: Bangladesh | B13: 6.2938646 | C13: 0 | D13: =C13/$C$151 -> 0
A14: Belarus | B14: 5.4470392 | C14: 0 | D14: =C14/$C$151 -> 0
A15: Belgium | B15: 3.3272157 | C15: 0 | D15: =C15/$C$151 -> 0
A16: Benin | B16: 5.9976204 | C16: 0 | D16: =C16/$C$151 -> 0
A17: Bhutan | B17: 5.0248646 | C17: 0 | D17: =C17/$C$151 -> 0
A18: Bolivia | B18: 5.4119735 | C18: 0 | D18: =C18/$C$151 -> 0
A19: Bosnia and Herzegovina | B19: 5.3424605 | C19: 0 | D19: =C19/$C$151 -> 0
A20: Botswana | B20: 4.3392269 | C20: 0 | D20: =C20/$C$151 -> 0
A21: Brazil | B21: 5.352888 | C21: 0.0147 | D21: =C21/$C$151 -> 0.018145908
... A30: Chile | B30: 4.3579263 | C30: 0 | D30: =C30/$C$151 -> 0
A31: China | B31: 4.2558828 | C31: 0.1391 | D31: =C31/$C$151 -> 0.1717072 | E31: Includes Taiwan
A32: Colombia | B32: 5.724794 | C32: 0 | D32: =C32/$C$151 -> 0
A33: Congo, Rep. | B33: 5.6489161 | C33: 0 | D33: =C33/$C$151 -> 0
A34: Costa Rica | B34: 4.2297468 | C34: 0 | D34: =C34/$C$151 -> 0
A35: Cote d'Ivoire | B35: 5.5958392 | C35: 0 | D35: =C35/$C$151 -> 0
A36: Croatia | B36: 4.2818307 | C36: 0 | D36: =C36/$C$151 -> 0
A37: Cyprus | B37: 4.6657023 | C37: 0 | D37: =C37/$C$151 -> 0
A38: Czech Republic | B38: 3.748497 | C38: 0 | D38: =C38/$C$151 -> 0
A39: Denmark | B39: 3.1990776 | C39: 0 | D39: =C39/$C$151 -> 0
A40: Djibouti | B40: 5.9780559 | C40: 0 | D40: =C40/$C$151 -> 0
A41: Dominican Republic | B41: 4.6951386 | C41: 0 | D41: =C41/$C$151 -> 0
A42: Ecuador | B42: 5.7086244 | C42: 0 | D42: =C42/$C$151 -> 0
A43: Egypt | B43: 5.6039767 | C43: 0 | D43: =C43/$C$151 -> 0
... A150: Zimbabwe | B150: 6.1447845 | C150: 0 | D150: =C150/$C$151 -> 0
A151: TOTAL | C151: =SUM(C4:C150) -> 0.8101 | D151: =SUM(D4:D150) -> 1

Sheet Country of Revenues - ENI
A1: ENI
A3: Country of Revenue | B3: Country Geopolitical Risk Index | C3: Percentage of Revenues | D3: Percentage of Revenues Standardized
A4: Albania | B4: 4.3705708 | C4: 0 | D4: =C4/$C$151 -> 0
A5: Algeria | B5: 5.2136193 | C5: 0.0115 | D5: =C5/$C$151 -> 0.01315338 | G5: Main Data
A6: Angola | B6: 5.6305966 | C6: 0.0025 | D6: =C6/$C$151 -> 0.0028594304 | H6: Country | I6: Geopolitical Risk Index | J6: Value
A7: Argentina | B7: 4.3620978 | C7: 0 | D7: =C7/$C$151 -> 0 | G7: Minimum | H7: =INDEX(A4:A150,MATCH(MIN(D4:D150),D4:D150,0)) -> Albania | I7: =INDEX(B4:B150,MATCH(MIN(D4:D150),D4:D150,0)) -> 4.3705708 | J7: =INDEX(D4:D150,MATCH(MIN(D4:D150),D4:D150,0)) -> 0
A8: Armenia | B8: 4.7882033 | C8: 0 | D8: =C8/$C$151 -> 0 | G8: Maximum | H8: =INDEX(A4:A150,MATCH(MAX(D4:D150),D4:D150,0)) -> Italy | I8: =INDEX(B4:B150,MATCH(MAX(D4:D150),D4:D150,0)) -> 3.8382883 | J8: =INDEX(D4:D150,MATCH(MAX(D4:D150),D4:D150,0)) -> 0.39917648
A9: Australia | B9: 3.2228923 | C9: 0 | D9: =C9/$C$151 -> 0 | G9: Component - Revenues | J9: =SUMPRODUCT(B4:B150,D4:D150) -> 3.9368104
A10: Austria | B10: 3.4101851 | C10: 0.0134 | D10: =C10/$C$151 -> 0.015326547
A11: Azerbaijan | B11: 5.2109259 | C11: 0 | D11: =C11/$C$151 -> 0
A12: Bahrain | B12: 4.2572307 | C12: 0 | D12: =C12/$C$151 -> 0
A13: Bangladesh | B13: 6.2938646 | C13: 0 | D13: =C13/$C$151 -> 0
A14: Belarus | B14: 5.4470392 | C14: 0 | D14: =C14/$C$151 -> 0
A15: Belgium | B15: 3.3272157 | C15: 0.0184 | D15: =C15/$C$151 -> 0.021045408
A16: Benin | B16: 5.9976204 | C16: 0 | D16: =C16/$C$151 -> 0
A17: Bhutan | B17: 5.0248646 | C17: 0 | D17: =C17/$C$151 -> 0
A18: Bolivia | B18: 5.4119735 | C18: 0 | D18: =C18/$C$151 -> 0
A19: Bosnia and Herzegovina | B19: 5.3424605 | C19: 0 | D19: =C19/$C$151 -> 0
A20: Botswana | B20: 4.3392269 | C20: 0 | D20: =C20/$C$151 -> 0
A21: Brazil | B21: 5.352888 | C21: 0 | D21: =C21/$C$151 -> 0
... A30: Chile | B30: 4.3579263 | C30: 0 | D30: =C30/$C$151 -> 0
A31: China | B31: 4.2558828 | C31: 0.05 | D31: =C31/$C$151 -> 0.057188608 | E31: Includes Taiwan
A32: Colombia | B32: 5.724794 | C32: 0 | D32: =C32/$C$151 -> 0
A33: Congo, Rep. | B33: 5.6489161 | C33: 0 | D33: =C33/$C$151 -> 0
A34: Costa Rica | B34: 4.2297468 | C34: 0 | D34: =C34/$C$151 -> 0
A35: Cote d'Ivoire | B35: 5.5958392 | C35: 0.002 | D35: =C35/$C$151 -> 0.0022875443
A36: Croatia | B36: 4.2818307 | C36: 0 | D36: =C36/$C$151 -> 0
A37: Cyprus | B37: 4.6657023 | C37: 0 | D37: =C37/$C$151 -> 0
A38: Czech Republic | B38: 3.748497 | C38: 0.0081 | D38: =C38/$C$151 -> 0.0092645545
A39: Denmark | B39: 3.1990776 | C39: 0 | D39: =C39/$C$151 -> 0
A40: Djibouti | B40: 5.9780559 | C40: 0 | D40: =C40/$C$151 -> 0
A41: Dominican Republic | B41: 4.6951386 | C41: 0 | D41: =C41/$C$151 -> 0
A42: Ecuador | B42: 5.7086244 | C42: 0 | D42: =C42/$C$151 -> 0
A43: Egypt | B43: 5.6039767 | C43: 0.0129 | D43: =C43/$C$151 -> 0.014754661
... A150: Zimbabwe | B150: 6.1447845 | C150: 0 | D150: =C150/$C$151 -> 0
A151: TOTAL | C151: =SUM(C4:C150) -> 0.8743 | D151: =SUM(D4:D150) -> 1

Sheet Country of Revenues - JP Morgan
A1: JP Morgan
A3: Country of Revenue | B3: Country Geopolitical Risk Index | C3: Percentage of Revenues | D3: Percentage of Revenues Standardized
A4: Albania | B4: 4.3705708 | C4: 0 | D4: =C4/$C$151 -> 0
A5: Algeria | B5: 5.2136193 | C5: 0 | D5: =C5/$C$151 -> 0 | G5: Main Data
A6: Angola | B6: 5.6305966 | C6: 0 | D6: =C6/$C$151 -> 0 | H6: Country | I6: Geopolitical Risk Index | J6: Value
A7: Argentina | B7: 4.3620978 | C7: 0 | D7: =C7/$C$151 -> 0 | G7: Minimum | H7: =INDEX(A4:A150,MATCH(MIN(D4:D150),D4:D150,0)) -> Albania | I7: =INDEX(B4:B150,MATCH(MIN(D4:D150),D4:D150,0)) -> 4.3705708 | J7: =INDEX(D4:D150,MATCH(MIN(D4:D150),D4:D150,0)) -> 0
A8: Armenia | B8: 4.7882033 | C8: 0 | D8: =C8/$C$151 -> 0 | G8: Maximum | H8: =INDEX(A4:A150,MATCH(MAX(D4:D150),D4:D150,0)) -> United States | I8: =INDEX(B4:B150,MATCH(MAX(D4:D150),D4:D150,0)) -> 4.1903554 | J8: =INDEX(D4:D150,MATCH(MAX(D4:D150),D4:D150,0)) -> 0.70866231
A9: Australia | B9: 3.2228923 | C9: 0 | D9: =C9/$C$151 -> 0 | G9: Component - Revenues | J9: =SUMPRODUCT(B4:B150,D4:D150) -> 4.0328985
A10: Austria | B10: 3.4101851 | C10: 0 | D10: =C10/$C$151 -> 0
A11: Azerbaijan | B11: 5.2109259 | C11: 0 | D11: =C11/$C$151 -> 0
A12: Bahrain | B12: 4.2572307 | C12: 0 | D12: =C12/$C$151 -> 0
A13: Bangladesh | B13: 6.2938646 | C13: 0 | D13: =C13/$C$151 -> 0
A14: Belarus | B14: 5.4470392 | C14: 0 | D14: =C14/$C$151 -> 0
A15: Belgium | B15: 3.3272157 | C15: 0 | D15: =C15/$C$151 -> 0
A16: Benin | B16: 5.9976204 | C16: 0 | D16: =C16/$C$151 -> 0
A17: Bhutan | B17: 5.0248646 | C17: 0 | D17: =C17/$C$151 -> 0
A18: Bolivia | B18: 5.4119735 | C18: 0 | D18: =C18/$C$151 -> 0
A19: Bosnia and Herzegovina | B19: 5.3424605 | C19: 0 | D19: =C19/$C$151 -> 0
A20: Botswana | B20: 4.3392269 | C20: 0 | D20: =C20/$C$151 -> 0
A21: Brazil | B21: 5.352888 | C21: 0 | D21: =C21/$C$151 -> 0
... A30: Chile | B30: 4.3579263 | C30: 0 | D30: =C30/$C$151 -> 0
A31: China | B31: 4.2558828 | C31: 0.0348 | D31: =C31/$C$151 -> 0.039251072 | E31: Includes Taiwan
A32: Colombia | B32: 5.724794 | C32: 0 | D32: =C32/$C$151 -> 0
A33: Congo, Rep. | B33: 5.6489161 | C33: 0 | D33: =C33/$C$151 -> 0
A34: Costa Rica | B34: 4.2297468 | C34: 0 | D34: =C34/$C$151 -> 0
A35: Cote d'Ivoire | B35: 5.5958392 | C35: 0 | D35: =C35/$C$151 -> 0
A36: Croatia | B36: 4.2818307 | C36: 0 | D36: =C36/$C$151 -> 0
A37: Cyprus | B37: 4.6657023 | C37: 0 | D37: =C37/$C$151 -> 0
A38: Czech Republic | B38: 3.748497 | C38: 0 | D38: =C38/$C$151 -> 0
A39: Denmark | B39: 3.1990776 | C39: 0 | D39: =C39/$C$151 -> 0
A40: Djibouti | B40: 5.9780559 | C40: 0 | D40: =C40/$C$151 -> 0
A41: Dominican Republic | B41: 4.6951386 | C41: 0 | D41: =C41/$C$151 -> 0
A42: Ecuador | B42: 5.7086244 | C42: 0 | D42: =C42/$C$151 -> 0
A43: Egypt | B43: 5.6039767 | C43: 0 | D43: =C43/$C$151 -> 0
... A150: Zimbabwe | B150: 6.1447845 | C150: 0 | D150: =C150/$C$151 -> 0
A151: TOTAL | C151: =SUM(C4:C150) -> 0.8866 | D151: =SUM(D4:D150) -> 1

Sheet Country of Revenues - Oreal
A1: L'Oreal
A3: Country of Revenue | B3: Country Geopolitical Risk Index | C3: Percentage of Revenues | D3: Percentage of Revenues Standardized
A4: Albania | B4: 4.3705708 | C4: 0 | D4: =C4/$C$151 -> 0
A5: Algeria | B5: 5.2136193 | C5: 0 | D5: =C5/$C$151 -> 0 | G5: Main Data
A6: Angola | B6: 5.6305966 | C6: 0 | D6: =C6/$C$151 -> 0 | H6: Country | I6: Geopolitical Risk Index | J6: Value
A7: Argentina | B7: 4.3620978 | C7: 0.0062 | D7: =C7/$C$151 -> 0.0075536062 | G7: Minimum | H7: =INDEX(A4:A150,MATCH(MIN(D4:D150),D4:D150,0)) -> Albania | I7: =INDEX(B4:B150,MATCH(MIN(D4:D150),D4:D150,0)) -> 4.3705708 | J7: =INDEX(D4:D150,MATCH(MIN(D4:D150),D4:D150,0)) -> 0
A8: Armenia | B8: 4.7882033 | C8: 0 | D8: =C8/$C$151 -> 0 | G8: Maximum | H8: =INDEX(A4:A150,MATCH(MAX(D4:D150),D4:D150,0)) -> United States | I8: =INDEX(B4:B150,MATCH(MAX(D4:D150),D4:D150,0)) -> 4.1903554 | J8: =INDEX(D4:D150,MATCH(MAX(D4:D150),D4:D150,0)) -> 0.30129142
A9: Australia | B9: 3.2228923 | C9: 0 | D9: =C9/$C$151 -> 0 | G9: Component - Revenues | J9: =SUMPRODUCT(B4:B150,D4:D150) -> 4.0242964
A10: Austria | B10: 3.4101851 | C10: 0 | D10: =C10/$C$151 -> 0
A11: Azerbaijan | B11: 5.2109259 | C11: 0 | D11: =C11/$C$151 -> 0
A12: Bahrain | B12: 4.2572307 | C12: 0 | D12: =C12/$C$151 -> 0
A13: Bangladesh | B13: 6.2938646 | C13: 0 | D13: =C13/$C$151 -> 0
A14: Belarus | B14: 5.4470392 | C14: 0 | D14: =C14/$C$151 -> 0
A15: Belgium | B15: 3.3272157 | C15: 0.0308 | D15: =C15/$C$151 -> 0.037524366
A16: Benin | B16: 5.9976204 | C16: 0 | D16: =C16/$C$151 -> 0
A17: Bhutan | B17: 5.0248646 | C17: 0 | D17: =C17/$C$151 -> 0
A18: Bolivia | B18: 5.4119735 | C18: 0 | D18: =C18/$C$151 -> 0
A19: Bosnia and Herzegovina | B19: 5.3424605 | C19: 0 | D19: =C19/$C$151 -> 0
A20: Botswana | B20: 4.3392269 | C20: 0 | D20: =C20/$C$151 -> 0
A21: Brazil | B21: 5.352888 | C21: 0.0262 | D21: =C21/$C$151 -> 0.031920078
... A30: Chile | B30: 4.3579263 | C30: 0.0049 | D30: =C30/$C$151 -> 0.0059697856
A31: China | B31: 4.2558828 | C31: 0.1662 | D31: =C31/$C$151 -> 0.20248538 | E31: Includes Taiwan
A32: Colombia | B32: 5.724794 | C32: 0 | D32: =C32/$C$151 -> 0
A33: Congo, Rep. | B33: 5.6489161 | C33: 0 | D33: =C33/$C$151 -> 0
A34: Costa Rica | B34: 4.2297468 | C34: 0 | D34: =C34/$C$151 -> 0
A35: Cote d'Ivoire | B35: 5.5958392 | C35: 0 | D35: =C35/$C$151 -> 0
A36: Croatia | B36: 4.2818307 | C36: 0 | D36: =C36/$C$151 -> 0
A37: Cyprus | B37: 4.6657023 | C37: 0 | D37: =C37/$C$151 -> 0
A38: Czech Republic | B38: 3.748497 | C38: 0 | D38: =C38/$C$151 -> 0
A39: Denmark | B39: 3.1990776 | C39: 0 | D39: =C39/$C$151 -> 0
A40: Djibouti | B40: 5.9780559 | C40: 0 | D40: =C40/$C$151 -> 0
A41: Dominican Republic | B41: 4.6951386 | C41: 0 | D41: =C41/$C$151 -> 0
A42: Ecuador | B42: 5.7086244 | C42: 0 | D42: =C42/$C$151 -> 0
A43: Egypt | B43: 5.6039767 | C43: 0 | D43: =C43/$C$151 -> 0
... A150: Zimbabwe | B150: 6.1447845 | C150: 0 | D150: =C150/$C$151 -> 0
A151: TOTAL | C151: =SUM(C4:C150) -> 0.8208 | D151: =SUM(D4:D150) -> 1

Sheet Country of Revenues - LVMH
A1: LVMH
A3: Country of Revenue | B3: Country Geopolitical Risk Index | C3: Percentage of Revenues | D3: Percentage of Revenues Standardized
