Workbook

Sheet Supply Chain Exposure - Overall
A1: Company Name | B1: Component - Suppliers Distribution | C1: Component - Suppliers' Facilities Distribution | D1: Supply Chain Exposure - Intermediate Component | E1: HHI Index - Value | F1: HHI Index - Submultiplier | G1: Supply Chain Exposure - Final Component
A2: Allianz | B2: ='Country of Suppliers - Allianz'!$K$9 -> 3.8518984 | C2: ='Country of Suppliers - Allianz'!$P$9 -> 4.2183861 | D2: =0.5*Tabella26[[#This Row],[Component - Suppliers Distribution]]+0.5*Tabella26[[#This Row],[Component - Suppliers'' Facilities Distribution]] -> 4.0351423 | E2: 0.10469694 | F2: =IF(E2<0.15,0.9, IF(E2<0.25,1, IF(E2<0.4,1.1, IF(E2<0.6,1.25, 1.5)))) -> 0.9 | G2: =Tabella26[[#This Row],[Supply Chain Exposure - Intermediate Component]]*Tabella26[[#This Row],[HHI Index - Submultiplier]] -> 3.6316281
A3: Amazon | B3: ='Country of Suppliers - Amazon'!$K$9 -> 4.0410797 | C3: ='Country of Suppliers - Amazon'!$P$9 -> 4.1802635 | D3: =0.5*Tabella26[[#This Row],[Component - Suppliers Distribution]]+0.5*Tabella26[[#This Row],[Component - Suppliers'' Facilities Distribution]] -> 4.1106716 | E3: 0.18906949 | F3: =IF(E3<0.15,0.9, IF(E3<0.25,1, IF(E3<0.4,1.1, IF(E3<0.6,1.25, 1.5)))) -> 1 | G3: =Tabella26[[#This Row],[Supply Chain Exposure - Intermediate Component]]*Tabella26[[#This Row],[HHI Index - Submultiplier]] -> 4.1106716
A4: Apple | B4: ='Country of Suppliers - Apple'!$K$9 -> 3.9112072 | C4: ='Country of Suppliers - Apple'!$P$9 -> 4.0663788 | D4: =0.5*Tabella26[[#This Row],[Component - Suppliers Distribution]]+0.5*Tabella26[[#This Row],[Component - Suppliers'' Facilities Distribution]] -> 3.988793 | E4: 0.16029771 | F4: =IF(E4<0.15,0.9, IF(E4<0.25,1, IF(E4<0.4,1.1, IF(E4<0.6,1.25, 1.5)))) -> 1 | G4: =Tabella26[[#This Row],[Supply Chain Exposure - Intermediate Component]]*Tabella26[[#This Row],[HHI Index - Submultiplier]] -> 3.988793
A5: ASML | B5: ='Country of Suppliers - ASML'!$K$9 -> 3.920084 | C5: ='Country of Suppliers - ASML'!$P$9 -> 3.9489018 | D5: =0.5*Tabella26[[#This Row],[Component - Suppliers Distribution]]+0.5*Tabella26[[#This Row],[Component - Suppliers'' Facilities Distribution]] -> 3.9344929 | E5: 0.16600412 | F5: =IF(E5<0.15,0.9, IF(E5<0.25,1, IF(E5<0.4,1.1, IF(E5<0.6,1.25, 1.5)))) -> 1 | G5: =Tabella26[[#This Row],[Supply Chain Exposure - Intermediate Component]]*Tabella26[[#This Row],[HHI Index - Submultiplier]] -> 3.9344929
A6: BNP Paribas | B6: ='Country of Suppliers - BNP'!$K$9 -> 3.752411 | C6: ='Country of Suppliers - BNP'!$P$9 -> 4.1784399 | D6: =0.5*Tabella26[[#This Row],[Component - Suppliers Distribution]]+0.5*Tabella26[[#This Row],[Component - Suppliers'' Facilities Distribution]] -> 3.9654255 | E6: 0.11550054 | F6: =IF(E6<0.15,0.9, IF(E6<0.25,1, IF(E6<0.4,1.1, IF(E6<0.6,1.25, 1.5)))) -> 0.9 | G6: =Tabella26[[#This Row],[Supply Chain Exposure - Intermediate Component]]*Tabella26[[#This Row],[HHI Index - Submultiplier]] -> 3.5688829
A7: Eli Lilly | B7: ='Country of Suppliers - EliLilly'!$K$9 -> 3.9356946 | C7: ='Country of Suppliers - EliLilly'!$P$9 -> 4.0546902 | D7: =0.5*Tabella26[[#This Row],[Component - Suppliers Distribution]]+0.5*Tabella26[[#This Row],[Component - Suppliers'' Facilities Distribution]] -> 3.9951924 | E7: 0.2702636 | F7: =IF(E7<0.15,0.9, IF(E7<0.25,1, IF(E7<0.4,1.1, IF(E7<0.6,1.25, 1.5)))) -> 1.1 | G7: =Tabella26[[#This Row],[Supply Chain Exposure - Intermediate Component]]*Tabella26[[#This Row],[HHI Index - Submultiplier]] -> 4.3947116
A8: ENI | B8: ='Country of Suppliers - ENI'!$K$9 -> 3.9963828 | C8: ='Country of Suppliers - ENI'!$P$9 -> 4.0596892 | D8: =0.5*Tabella26[[#This Row],[Component - Suppliers Distribution]]+0.5*Tabella26[[#This Row],[Component - Suppliers'' Facilities Distribution]] -> 4.028036 | E8: 0.13054742 | F8: =IF(E8<0.15,0.9, IF(E8<0.25,1, IF(E8<0.4,1.1, IF(E8<0.6,1.25, 1.5)))) -> 0.9 | G8: =Tabella26[[#This Row],[Supply Chain Exposure - Intermediate Component]]*Tabella26[[#This Row],[HHI Index - Submultiplier]] -> 3.6252324
A9: Ford | B9: ='Country of Suppliers - Ford'!$K$9 -> 4.0222691 | C9: ='Country of Suppliers - Ford'!$P$9 -> 4.1259865 | D9: =0.5*Tabella26[[#This Row],[Component - Suppliers Distribution]]+0.5*Tabella26[[#This Row],[Component - Suppliers'' Facilities Distribution]] -> 4.0741278 | E9: 0.11981291 | F9: =IF(E9<0.15,0.9, IF(E9<0.25,1, IF(E9<0.4,1.1, IF(E9<0.6,1.25, 1.5)))) -> 0.9 | G9: =Tabella26[[#This Row],[Supply Chain Exposure - Intermediate Component]]*Tabella26[[#This Row],[HHI Index - Submultiplier]] -> 3.666715
A10: JP Morgan | B10: ='Country of Suppliers - JPMorgan'!$K$9 -> 3.9976963 | C10: ='Country of Suppliers - JPMorgan'!$P$9 -> 4.2375296 | D10: =0.5*Tabella26[[#This Row],[Component - Suppliers Distribution]]+0.5*Tabella26[[#This Row],[Component - Suppliers'' Facilities Distribution]] -> 4.117613 | E10: 0.23843659 | F10: =IF(E10<0.15,0.9, IF(E10<0.25,1, IF(E10<0.4,1.1, IF(E10<0.6,1.25, 1.5)))) -> 1 | G10: =Tabella26[[#This Row],[Supply Chain Exposure - Intermediate Component]]*Tabella26[[#This Row],[HHI Index - Submultiplier]] -> 4.117613
A11: L'Oreal | B11: ='Country of Suppliers - Oreal'!$K$9 -> 3.9195712 | C11: ='Country of Suppliers - Oreal'!$P$9 -> 4.0681062 | D11: =0.5*Tabella26[[#This Row],[Component - Suppliers Distribution]]+0.5*Tabella26[[#This Row],[Component - Suppliers'' Facilities Distribution]] -> 3.9938387 | E11: 0.14024297 | F11: =IF(E11<0.15,0.9, IF(E11<0.25,1, IF(E11<0.4,1.1, IF(E11<0.6,1.25, 1.5)))) -> 0.9 | G11: =Tabella26[[#This Row],[Supply Chain Exposure - Intermediate Component]]*Tabella26[[#This Row],[HHI Index - Submultiplier]] -> 3.5944548
A12: LVMH | B12: ='Country of Suppliers - LVMH'!$K$9 -> 3.8057601 | C12: ='Country of Suppliers - LVMH'!$P$9 -> 4.0393145 | D12: =0.5*Tabella26[[#This Row],[Component - Suppliers Distribution]]+0.5*Tabella26[[#This Row],[Component - Suppliers'' Facilities Distribution]] -> 3.9225373 | E12: 0.11369436 | F12: =IF(E12<0.15,0.9, IF(E12<0.25,1, IF(E12<0.4,1.1, IF(E12<0.6,1.25, 1.5)))) -> 0.9 | G12: =Tabella26[[#This Row],[Supply Chain Exposure - Intermediate Component]]*Tabella26[[#This Row],[HHI Index - Submultiplier]] -> 3.5302836
A13: Meta | B13: ='Country of Suppliers - Meta'!$K$9 -> 3.9636017 | C13: ='Country of Suppliers - Meta'!$P$9 -> 4.0689945 | D13: =0.5*Tabella26[[#This Row],[Component - Suppliers Distribution]]+0.5*Tabella26[[#This Row],[Component - Suppliers'' Facilities Distribution]] -> 4.0162981 | E13: 0.14675068 | F13: =IF(E13<0.15,0.9, IF(E13<0.25,1, IF(E13<0.4,1.1, IF(E13<0.6,1.25, 1.5)))) -> 0.9 | G13: =Tabella26[[#This Row],[Supply Chain Exposure - Intermediate Component]]*Tabella26[[#This Row],[HHI Index - Submultiplier]] -> 3.6146683
A14: Microsoft | B14: ='Country of Suppliers Microsoft'!$K$9 -> 3.965653 | C14: ='Country of Suppliers Microsoft'!$P$9 -> 4.156679 | D14: =0.5*Tabella26[[#This Row],[Component - Suppliers Distribution]]+0.5*Tabella26[[#This Row],[Component - Suppliers'' Facilities Distribution]] -> 4.061166 | E14: 0.15079362 | F14: =IF(E14<0.15,0.9, IF(E14<0.25,1, IF(E14<0.4,1.1, IF(E14<0.6,1.25, 1.5)))) -> 1 | G14: =Tabella26[[#This Row],[Supply Chain Exposure - Intermediate Component]]*Tabella26[[#This Row],[HHI Index - Submultiplier]] -> 4.061166
A15: Novo Nordisk | B15: ='Country of Suppliers - Nordisk'!$K$9 -> 3.7931161 | C15: ='Country of Suppliers - Nordisk'!$P$9 -> 4.0044573 | D15: =0.5*Tabella26[[#This Row],[Component - Suppliers Distribution]]+0.5*Tabella26[[#This Row],[Component - Suppliers'' Facilities Distribution]] -> 3.8987867 | E15: 0.14603327 | F15: =IF(E15<0.15,0.9, IF(E15<0.25,1, IF(E15<0.4,1.1, IF(E15<0.6,1.25, 1.5)))) -> 0.9 | G15: =Tabella26[[#This Row],[Supply Chain Exposure - Intermediate Component]]*Tabella26[[#This Row],[HHI Index - Submultiplier]] -> 3.508908
A16: NVIDIA | B16: ='Country of Suppliers - NVIDIA'!$K$9 -> 4.0426345 | C16: ='Country of Suppliers - NVIDIA'!$P$9 -> 4.099785 | D16: =0.5*Tabella26[[#This Row],[Component - Suppliers Distribution]]+0.5*Tabella26[[#This Row],[Component - Suppliers'' Facilities Distribution]] -> 4.0712098 | E16: 0.19643558 | F16: =IF(E16<0.15,0.9, IF(E16<0.25,1, IF(E16<0.4,1.1, IF(E16<0.6,1.25, 1.5)))) -> 1 | G16: =Tabella26[[#This Row],[Supply Chain Exposure - Intermediate Component]]*Tabella26[[#This Row],[HHI Index - Submultiplier]] -> 4.0712098
A17: Procter & Gamble | B17: ='Country of Suppliers - P&G'!$K$9 -> 4.068843 | C17: ='Country of Suppliers - P&G'!$P$9 -> 4.1888836 | D17: =0.5*Tabella26[[#This Row],[Component - Suppliers Distribution]]+0.5*Tabella26[[#This Row],[Component - Suppliers'' Facilities Distribution]] -> 4.1288633 | E17: 0.15053713 | F17: =IF(E17<0.15,0.9, IF(E17<0.25,1, IF(E17<0.4,1.1, IF(E17<0.6,1.25, 1.5)))) -> 1 | G17: =Tabella26[[#This Row],[Supply Chain Exposure - Intermediate Component]]*Tabella26[[#This Row],[HHI Index - Submultiplier]] -> 4.1288633
A18: Reliance Industries | B18: ='Country of Suppliers - Reliance'!$K$9 -> 4.7468175 | C18: ='Country of Suppliers - Reliance'!$P$9 -> 4.4696098 | D18: =0.5*Tabella26[[#This Row],[Component - Suppliers Distribution]]+0.5*Tabella26[[#This Row],[Component - Suppliers'' Facilities Distribution]] -> 4.6082136 | E18: 0.33973988 | F18: =IF(E18<0.15,0.9, IF(E18<0.25,1, IF(E18<0.4,1.1, IF(E18<0.6,1.25, 1.5)))) -> 1.1 | G18: =Tabella26[[#This Row],[Supply Chain Exposure - Intermediate Component]]*Tabella26[[#This Row],[HHI Index - Submultiplier]] -> 5.069035
A19: Samsung | B19: ='Country of Suppliers - Samsung'!$K$9 -> 3.8782523 | C19: ='Country of Suppliers - Samsung'!$P$9 -> 4.0275142 | D19: =0.5*Tabella26[[#This Row],[Component - Suppliers Distribution]]+0.5*Tabella26[[#This Row],[Component - Suppliers'' Facilities Distribution]] -> 3.9528832 | E19: 0.17652611 | F19: =IF(E19<0.15,0.9, IF(E19<0.25,1, IF(E19<0.4,1.1, IF(E19<0.6,1.25, 1.5)))) -> 1 | G19: =Tabella26[[#This Row],[Supply Chain Exposure - Intermediate Component]]*Tabella26[[#This Row],[HHI Index - Submultiplier]] -> 3.9528832
A20: SAP | B20: ='Country of Suppliers - SAP'!$K$9 -> 3.9442869 | C20: ='Country of Suppliers - SAP'!$P$9 -> 3.9114256 | D20: =0.5*Tabella26[[#This Row],[Component - Suppliers Distribution]]+0.5*Tabella26[[#This Row],[Component - Suppliers'' Facilities Distribution]] -> 3.9278562 | E20: 0.23272571 | F20: =IF(E20<0.15,0.9, IF(E20<0.25,1, IF(E20<0.4,1.1, IF(E20<0.6,1.25, 1.5)))) -> 1 | G20: =Tabella26[[#This Row],[Supply Chain Exposure - Intermediate Component]]*Tabella26[[#This Row],[HHI Index - Submultiplier]] -> 3.9278562
A21: Sony | B21: ='Country of Suppliers - Sony'!$K$9 -> 3.8594282 | C21: ='Country of Suppliers - Sony'!$P$9 -> 4.0276283 | D21: =0.5*Tabella26[[#This Row],[Component - Suppliers Distribution]]+0.5*Tabella26[[#This Row],[Component - Suppliers'' Facilities Distribution]] -> 3.9435283 | E21: 0.16019854 | F21: =IF(E21<0.15,0.9, IF(E21<0.25,1, IF(E21<0.4,1.1, IF(E21<0.6,1.25, 1.5)))) -> 1 | G21: =Tabella26[[#This Row],[Supply Chain Exposure - Intermediate Component]]*Tabella26[[#This Row],[HHI Index - Submultiplier]] -> 3.9435283
A22: Tencent | B22: ='Country of Suppliers - Tencent'!$K$9 -> 4.1219074 | C22: ='Country of Suppliers - Tencent'!$P$9 -> 4.1842032 | D22: =0.5*Tabella26[[#This Row],[Component - Suppliers Distribution]]+0.5*Tabella26[[#This Row],[Component - Suppliers'' Facilities Distribution]] -> 4.1530553 | E22: 0.4620186 | F22: =IF(E22<0.15,0.9, IF(E22<0.25,1, IF(E22<0.4,1.1, IF(E22<0.6,1.25, 1.5)))) -> 1.25 | G22: =Tabella26[[#This Row],[Supply Chain Exposure - Intermediate Component]]*Tabella26[[#This Row],[HHI Index - Submultiplier]] -> 5.1913192
A23: Total Energies | B23: ='Country of Suppliers - Total En'!$K$9 -> 4.0376206 | C23: ='Country of Suppliers - Total En'!$P$9 -> 4.0256848 | D23: =0.5*Tabella26[[#This Row],[Component - Suppliers Distribution]]+0.5*Tabella26[[#This Row],[Component - Suppliers'' Facilities Distribution]] -> 4.0316527 | E23: 0.093193661 | F23: =IF(E23<0.15,0.9, IF(E23<0.25,1, IF(E23<0.4,1.1, IF(E23<0.6,1.25, 1.5)))) -> 0.9 | G23: =Tabella26[[#This Row],[Supply Chain Exposure - Intermediate Component]]*Tabella26[[#This Row],[HHI Index - Submultiplier]] -> 3.6284874
A24: Toyota | B24: ='Country of Suppliers - Toyota'!$K$9 -> 3.9433374 | C24: ='Country of Suppliers - Toyota'!$P$9 -> 4.0721256 | D24: =0.5*Tabella26[[#This Row],[Component - Suppliers Distribution]]+0.5*Tabella26[[#This Row],[Component - Suppliers'' Facilities Distribution]] -> 4.0077315 | E24: 0.14344647 | F24: =IF(E24<0.15,0.9, IF(E24<0.25,1, IF(E24<0.4,1.1, IF(E24<0.6,1.25, 1.5)))) -> 0.9 | G24: =Tabella26[[#This Row],[Supply Chain Exposure - Intermediate Component]]*Tabella26[[#This Row],[HHI Index - Submultiplier]] -> 3.6069583
A25: TSMC | B25: ='Country of Suppliers - TSMC'!$K$9 -> 3.9315003 | C25: ='Country of Suppliers - TSMC'!$P$9 -> 3.9450118 | D25: =0.5*Tabella26[[#This Row],[Component - Suppliers Distribution]]+0.5*Tabella26[[#This Row],[Component - Suppliers'' Facilities Distribution]] -> 3.938256 | E25: 0.19222534 | F25: =IF(E25<0.15,0.9, IF(E25<0.25,1, IF(E25<0.4,1.1, IF(E25<0.6,1.25, 1.5)))) -> 1 | G25: =Tabella26[[#This Row],[Supply Chain Exposure - Intermediate Component]]*Tabella26[[#This Row],[HHI Index - Submultiplier]] -> 3.938256
A26: Volkswagen | B26: ='Country of Suppliers - VW'!$K$9 -> 4.0446343 | C26: ='Country of Suppliers - VW'!$P$9 -> 4.1522496 | D26: =0.5*Tabella26[[#This Row],[Component - Suppliers Distribution]]+0.5*Tabella26[[#This Row],[Component - Suppliers'' Facilities Distribution]] -> 4.0984419 | E26: 0.12974581 | F26: =IF(E26<0.15,0.9, IF(E26<0.25,1, IF(E26<0.4,1.1, IF(E26<0.6,1.25, 1.5)))) -> 0.9 | G26: =Tabella26[[#This Row],[Supply Chain Exposure - Intermediate Component]]*Tabella26[[#This Row],[HHI Index - Submultiplier]] -> 3.6885977

Sheet HHI Index - Submultiplier
A1: Company Name | B1: HHI Index - Suppliers Distribution | C1: HHI Index - Suppliers' Facilities Distribution | D1: HHI Index - Value | E1: HHI Index - Submultiplier
A2: Allianz | B2: =SUMPRODUCT('Country of Suppliers - Allianz'!$D$4:$D$150,'Country of Suppliers - Allianz'!$D$4:$D$150) -> 0.12621524 | C2: =SUMPRODUCT('Country of Suppliers - Allianz'!$F$4:$F$150,'Country of Suppliers - Allianz'!$F$4:$F$150) -> 0.083178644 | D2: =0.5*B2+0.5*C2 -> 0.10469694 | E2: =IF(D2<0.15,0.9, IF(D2<0.25,1, IF(D2<0.4,1.1, IF(D2<0.6,1.25, 1.5)))) -> 0.9
A3: Amazon | B3: =SUMPRODUCT('Country of Suppliers - Amazon'!$D$4:$D$150,'Country of Suppliers - Amazon'!$D$4:$D$150) -> 0.20745614 | C3: =SUMPRODUCT('Country of Suppliers - Amazon'!$F$4:$F$150,'Country of Suppliers - Amazon'!$F$4:$F$150) -> 0.17068284 | D3: =0.5*B3+0.5*C3 -> 0.18906949 | E3: =IF(D3<0.15,0.9, IF(D3<0.25,1, IF(D3<0.4,1.1, IF(D3<0.6,1.25, 1.5)))) -> 1
A4: Apple | B4: =SUMPRODUCT('Country of Suppliers - Apple'!$D$4:$D$150,'Country of Suppliers - Apple'!$D$4:$D$150) -> 0.20018978 | C4: =SUMPRODUCT('Country of Suppliers - Apple'!$F$4:$F$150,'Country of Suppliers - Apple'!$F$4:$F$150) -> 0.12040564 | D4: =0.5*B4+0.5*C4 -> 0.16029771 | E4: =IF(D4<0.15,0.9, IF(D4<0.25,1, IF(D4<0.4,1.1, IF(D4<0.6,1.25, 1.5)))) -> 1
A5: ASML | B5: =SUMPRODUCT('Country of Suppliers - ASML'!$D$4:$D$150,'Country of Suppliers - ASML'!$D$4:$D$150) -> 0.21636386 | C5: =SUMPRODUCT('Country of Suppliers - ASML'!$F$4:$F$150,'Country of Suppliers - ASML'!$F$4:$F$150) -> 0.11564437 | D5: =0.5*B5+0.5*C5 -> 0.16600412 | E5: =IF(D5<0.15,0.9, IF(D5<0.25,1, IF(D5<0.4,1.1, IF(D5<0.6,1.25, 1.5)))) -> 1
A6: BNP Paribas | B6: =SUMPRODUCT('Country of Suppliers - BNP'!$D$4:$D$150,'Country of Suppliers - BNP'!$D$4:$D$150) -> 0.12358652 | C6: =SUMPRODUCT('Country of Suppliers - BNP'!$F$4:$F$150,'Country of Suppliers - BNP'!$F$4:$F$150) -> 0.10741455 | D6: =0.5*B6+0.5*C6 -> 0.11550054 | E6: =IF(D6<0.15,0.9, IF(D6<0.25,1, IF(D6<0.4,1.1, IF(D6<0.6,1.25, 1.5)))) -> 0.9
A7: Eli Lilly | B7: =SUMPRODUCT('Country of Suppliers - EliLilly'!$D$4:$D$150,'Country of Suppliers - EliLilly'!$D$4:$D$150) -> 0.29147778 | C7: =SUMPRODUCT('Country of Suppliers - EliLilly'!$F$4:$F$150,'Country of Suppliers - EliLilly'!$F$4:$F$150) -> 0.24904943 | D7: =0.5*B7+0.5*C7 -> 0.2702636 | E7: =IF(D7<0.15,0.9, IF(D7<0.25,1, IF(D7<0.4,1.1, IF(D7<0.6,1.25, 1.5)))) -> 1.1
A8: ENI | B8: =SUMPRODUCT('Country of Suppliers - ENI'!$D$4:$D$150,'Country of Suppliers - ENI'!$D$4:$D$150) -> 0.1012574 | C8: =SUMPRODUCT('Country of Suppliers - ENI'!$F$4:$F$150,'Country of Suppliers - ENI'!$F$4:$F$150) -> 0.15983744 | D8: =0.5*B8+0.5*C8 -> 0.13054742 | E8: =IF(D8<0.15,0.9, IF(D8<0.25,1, IF(D8<0.4,1.1, IF(D8<0.6,1.25, 1.5)))) -> 0.9
A9: Ford | B9: =SUMPRODUCT('Country of Suppliers - Ford'!$D$4:$D$150,'Country of Suppliers - Ford'!$D$4:$D$150) -> 0.14357264 | C9: =SUMPRODUCT('Country of Suppliers - Ford'!$F$4:$F$150,'Country of Suppliers - Ford'!$F$4:$F$150) -> 0.096053183 | D9: =0.5*B9+0.5*C9 -> 0.11981291 | E9: =IF(D9<0.15,0.9, IF(D9<0.25,1, IF(D9<0.4,1.1, IF(D9<0.6,1.25, 1.5)))) -> 0.9
A10: JP Morgan | B10: =SUMPRODUCT('Country of Suppliers - JPMorgan'!$D$4:$D$150,'Country of Suppliers - JPMorgan'!$D$4:$D$150) -> 0.34613045 | C10: =SUMPRODUCT('Country of Suppliers - JPMorgan'!$F$4:$F$150,'Country of Suppliers - JPMorgan'!$F$4:$F$150) -> 0.13074272 | D10: =0.5*B10+0.5*C10 -> 0.23843659 | E10: =IF(D10<0.15,0.9, IF(D10<0.25,1, IF(D10<0.4,1.1, IF(D10<0.6,1.25, 1.5)))) -> 1
A11: L'Oreal | B11: =SUMPRODUCT('Country of Suppliers - Oreal'!$D$4:$D$150,'Country of Suppliers - Oreal'!$D$4:$D$150) -> 0.13167185 | C11: =SUMPRODUCT('Country of Suppliers - Oreal'!$F$4:$F$150,'Country of Suppliers - Oreal'!$F$4:$F$150) -> 0.14881409 | D11: =0.5*B11+0.5*C11 -> 0.14024297 | E11: =IF(D11<0.15,0.9, IF(D11<0.25,1, IF(D11<0.4,1.1, IF(D11<0.6,1.25, 1.5)))) -> 0.9
A12: LVMH | B12: =SUMPRODUCT('Country of Suppliers - LVMH'!$D$4:$D$150,'Country of Suppliers - LVMH'!$D$4:$D$150) -> 0.12568753 | C12: =SUMPRODUCT('Country of Suppliers - LVMH'!$F$4:$F$150,'Country of Suppliers - LVMH'!$F$4:$F$150) -> 0.10170119 | D12: =0.5*B12+0.5*C12 -> 0.11369436 | E12: =IF(D12<0.15,0.9, IF(D12<0.25,1, IF(D12<0.4,1.1, IF(D12<0.6,1.25, 1.5)))) -> 0.9
A13: Meta | B13: =SUMPRODUCT('Country of Suppliers - Meta'!$D$4:$D$150,'Country of Suppliers - Meta'!$D$4:$D$150) -> 0.18838392 | C13: =SUMPRODUCT('Country of Suppliers - Meta'!$F$4:$F$150,'Country of Suppliers - Meta'!$F$4:$F$150) -> 0.10511744 | D13: =0.5*B13+0.5*C13 -> 0.14675068 | E13: =IF(D13<0.15,0.9, IF(D13<0.25,1, IF(D13<0.4,1.1, IF(D13<0.6,1.25, 1.5)))) -> 0.9
A14: Microsoft | B14: =SUMPRODUCT('Country of Suppliers Microsoft'!$D$4:$D$150,'Country of Suppliers Microsoft'!$D$4:$D$150) -> 0.19752879 | C14: =SUMPRODUCT('Country of Suppliers Microsoft'!$F$4:$F$150,'Country of Suppliers Microsoft'!$F$4:$F$150) -> 0.10405845 | D14: =0.5*B14+0.5*C14 -> 0.15079362 | E14: =IF(D14<0.15,0.9, IF(D14<0.25,1, IF(D14<0.4,1.1, IF(D14<0.6,1.25, 1.5)))) -> 1
A15: Novo Nordisk | B15: =SUMPRODUCT('Country of Suppliers - Nordisk'!$D$4:$D$150,'Country of Suppliers - Nordisk'!$D$4:$D$150) -> 0.22130014 | C15: =SUMPRODUCT('Country of Suppliers - Nordisk'!$F$4:$F$150,'Country of Suppliers - Nordisk'!$F$4:$F$150) -> 0.070766399 | D15: =0.5*B15+0.5*C15 -> 0.14603327 | E15: =IF(D15<0.15,0.9, IF(D15<0.25,1, IF(D15<0.4,1.1, IF(D15<0.6,1.25, 1.5)))) -> 0.9
A16: NVIDIA | B16: =SUMPRODUCT('Country of Suppliers - NVIDIA'!$D$4:$D$150,'Country of Suppliers - NVIDIA'!$D$4:$D$150) -> 0.26814147 | C16: =SUMPRODUCT('Country of Suppliers - NVIDIA'!$F$4:$F$150,'Country of Suppliers - NVIDIA'!$F$4:$F$150) -> 0.1247297 | D16: =0.5*B16+0.5*C16 -> 0.19643558 | E16: =IF(D16<0.15,0.9, IF(D16<0.25,1, IF(D16<0.4,1.1, IF(D16<0.6,1.25, 1.5)))) -> 1
A17: Procter & Gamble | B17: =SUMPRODUCT('Country of Suppliers - P&G'!$D$4:$D$150,'Country of Suppliers - P&G'!$D$4:$D$150) -> 0.15596612 | C17: =SUMPRODUCT('Country of Suppliers - P&G'!$F$4:$F$150,'Country of Suppliers - P&G'!$F$4:$F$150) -> 0.14510814 | D17: =0.5*B17+0.5*C17 -> 0.15053713 | E17: =IF(D17<0.15,0.9, IF(D17<0.25,1, IF(D17<0.4,1.1, IF(D17<0.6,1.25, 1.5)))) -> 1
A18: Reliance Industries | B18: =SUMPRODUCT('Country of Suppliers - Reliance'!$D$4:$D$150,'Country of Suppliers - Reliance'!$D$4:$D$150) -> 0.49937949 | C18: =SUMPRODUCT('Country of Suppliers - Reliance'!$F$4:$F$150,'Country of Suppliers - Reliance'!$F$4:$F$150) -> 0.18010028 | D18: =0.5*B18+0.5*C18 -> 0.33973988 | E18: =IF(D18<0.15,0.9, IF(D18<0.25,1, IF(D18<0.4,1.1, IF(D18<0.6,1.25, 1.5)))) -> 1.1
A19: Samsung | B19: =SUMPRODUCT('Country of Suppliers - Samsung'!$D$4:$D$150,'Country of Suppliers - Samsung'!$D$4:$D$150) -> 0.24571544 | C19: =SUMPRODUCT('Country of Suppliers - Samsung'!$F$4:$F$150,'Country of Suppliers - Samsung'!$F$4:$F$150) -> 0.10733678 | D19: =0.5*B19+0.5*C19 -> 0.17652611 | E19: =IF(D19<0.15,0.9, IF(D19<0.25,1, IF(D19<0.4,1.1, IF(D19<0.6,1.25, 1.5)))) -> 1
A20: SAP | B20: =SUMPRODUCT('Country of Suppliers - SAP'!$D$4:$D$150,'Country of Suppliers - SAP'!$D$4:$D$150) -> 0.25490393 | C20: =SUMPRODUCT('Country of Suppliers - SAP'!$F$4:$F$150,'Country of Suppliers - SAP'!$F$4:$F$150) -> 0.21054749 | D20: =0.5*B20+0.5*C20 -> 0.23272571 | E20: =IF(D20<0.15,0.9, IF(D20<0.25,1, IF(D20<0.4,1.1, IF(D20<0.6,1.25, 1.5)))) -> 1
A21: Sony | B21: =SUMPRODUCT('Country of Suppliers - Sony'!$D$4:$D$150,'Country of Suppliers - Sony'!$D$4:$D$150) -> 0.18135067 | C21: =SUMPRODUCT('Country of Suppliers - Sony'!$F$4:$F$150,'Country of Suppliers - Sony'!$F$4:$F$150) -> 0.13904642 | D21: =0.5*B21+0.5*C21 -> 0.16019854 | E21: =IF(D21<0.15,0.9, IF(D21<0.25,1, IF(D21<0.4,1.1, IF(D21<0.6,1.25, 1.5)))) -> 1
A22: Tencent | B22: =SUMPRODUCT('Country of Suppliers - Tencent'!$D$4:$D$150,'Country of Suppliers - Tencent'!$D$4:$D$150) -> 0.55148999 | C22: =SUMPRODUCT('Country of Suppliers - Tencent'!$F$4:$F$150,'Country of Suppliers - Tencent'!$F$4:$F$150) -> 0.3725472 | D22: =0.5*B22+0.5*C22 -> 0.4620186 | E22: =IF(D22<0.15,0.9, IF(D22<0.25,1, IF(D22<0.4,1.1, IF(D22<0.6,1.25, 1.5)))) -> 1.25
A23: Total Energies | B23: =SUMPRODUCT('Country of Suppliers - Total En'!$D$4:$D$150,'Country of Suppliers - Total En'!$D$4:$D$150) -> 0.08242483 | C23: =SUMPRODUCT('Country of Suppliers - Total En'!$F$4:$F$150,'Country of Suppliers - Total En'!$F$4:$F$150) -> 0.10396249 | D23: =0.5*B23+0.5*C23 -> 0.093193661 | E23: =IF(D23<0.15,0.9, IF(D23<0.25,1, IF(D23<0.4,1.1, IF(D23<0.6,1.25, 1.5)))) -> 0.9
A24: Toyota | B24: =SUMPRODUCT('Country of Suppliers - Toyota'!$D$4:$D$150,'Country of Suppliers - Toyota'!$D$4:$D$150) -> 0.18357072 | C24: =SUMPRODUCT('Country of Suppliers - Toyota'!$F$4:$F$150,'Country of Suppliers - Toyota'!$F$4:$F$150) -> 0.10332222 | D24: =0.5*B24+0.5*C24 -> 0.14344647 | E24: =IF(D24<0.15,0.9, IF(D24<0.25,1, IF(D24<0.4,1.1, IF(D24<0.6,1.25, 1.5)))) -> 0.9
A25: TSMC | B25: =SUMPRODUCT('Country of Suppliers - TSMC'!$D$4:$D$150,'Country of Suppliers - TSMC'!$D$4:$D$150) -> 0.28573544 | C25: =SUMPRODUCT('Country of Suppliers - TSMC'!$F$4:$F$150,'Country of Suppliers - TSMC'!$F$4:$F$150) -> 0.098715233 | D25: =0.5*B25+0.5*C25 -> 0.19222534 | E25: =IF(D25<0.15,0.9, IF(D25<0.25,1, IF(D25<0.4,1.1, IF(D25<0.6,1.25, 1.5)))) -> 1
A26: Volkswagen | B26: =SUMPRODUCT('Country of Suppliers - VW'!$D$4:$D$150,'Country of Suppliers - VW'!$D$4:$D$150) -> 0.16624811 | C26: =SUMPRODUCT('Country of Suppliers - VW'!$F$4:$F$150,'Country of Suppliers - VW'!$F$4:$F$150) -> 0.093243509 | D26: =0.5*B26+0.5*C26 -> 0.12974581 | E26: =IF(D26<0.15,0.9, IF(D26<0.25,1, IF(D26<0.4,1.1, IF(D26<0.6,1.25, 1.5)))) -> 0.9

Sheet Country of Suppliers - Apple
A1: Apple Inc.
A3: Country of Supplier | B3: Country Geopolitical Risk Index | C3: Percentage of Suppliers - Raw | D3: Percentage of Suppliers - Standardized | E3: Percentage of Supplier's Facilities - Raw | F3: Percentage of Supplier's Facilities - Standardize
A4: Albania | B4: 4.3705708 | C4: 0 | D4: =Tabella1[[#This Row],[Percentage of Suppliers - Raw]]/$C$151 -> 0 | E4: 0.0001 | F4: =Tabella1[[#This Row],[Percentage of Supplier''s Facilities - Raw]]/$E$151 -> 0.00010091836
A5: Algeria | B5: 5.2136193 | C5: 0 | D5: =Tabella1[[#This Row],[Percentage of Suppliers - Raw]]/$C$151 -> 0 | E5: 0.0004 | F5: =Tabella1[[#This Row],[Percentage of Supplier''s Facilities - Raw]]/$E$151 -> 0.00040367343 | H5: Main Data | M5: Main Data
A6: Angola | B6: 5.6305966 | C6: 0 | D6: =Tabella1[[#This Row],[Percentage of Suppliers - Raw]]/$C$151 -> 0 | E6: 0.0005 | F6: =Tabella1[[#This Row],[Percentage of Supplier''s Facilities - Raw]]/$E$151 -> 0.00050459179 | I6: Country | J6: Geopolitical Risk Index | K6: Value | N6: Country | O6: Geopolitical Risk Index | P6: Value
A7: Argentina | B7: 4.3620978 | C7: 0 | D7: =Tabella1[[#This Row],[Percentage of Suppliers - Raw]]/$C$151 -> 0 | E7: 0.0026 | F7: =Tabella1[[#This Row],[Percentage of Supplier''s Facilities - Raw]]/$E$151 -> 0.0026238773 | H7: Minimum | I7: =INDEX(A4:A150,MATCH(MIN(D4:D150),D4:D150,0)) -> Albania | J7: =INDEX(B4:B150,MATCH(MIN(D4:D150),D4:D150,0)) -> 4.3705708 | K7: =INDEX(D4:D150,MATCH(MIN(D4:D150),D4:D150,0)) -> 0 | M7: Minimum | N7: =INDEX(A4:A150,MATCH(MIN(F4:F150),F4:F150,0)) -> Bahrain | O7: =INDEX(B4:B150,MATCH(MIN(F4:F150),F4:F150,0)) -> 4.2572307 | P7: =INDEX(F4:F150,MATCH(MIN(F4:F150),F4:F150,0)) -> 0
A8: Armenia | B8: 4.7882033 | C8: 0 | D8: =Tabella1[[#This Row],[Percentage of Suppliers - Raw]]/$C$151 -> 0 | E8: 0.0001 | F8: =Tabella1[[#This Row],[Percentage of Supplier''s Facilities - Raw]]/$E$151 -> 0.00010091836 | H8: Maximum | I8: =INDEX(A4:A150,MATCH(MAX(D4:D150),D4:D150,0)) -> China | J8: =INDEX(B4:B150,MATCH(MAX(D4:D150),D4:D150,0)) -> 4.2558828 | K8: =INDEX(D4:D150,MATCH(MAX(D4:D150),D4:D150,0)) -> 0.33131081 | M8: Maximum | N8: =INDEX(A4:A150,MATCH(MAX(F4:F150),F4:F150,0)) -> China | O8: =INDEX(B4:B150,MATCH(MAX(F4:F150),F4:F150,0)) -> 4.2558828 | P8: =INDEX(F4:F150,MATCH(MAX(F4:F150),F4:F150,0)) -> 0.2248461
A9: Australia | B9: 3.2228923 | C9: 0.01 | D9: =Tabella1[[#This Row],[Percentage of Suppliers - Raw]]/$C$151 -> 0.010461345 | E9: 0.0103 | F9: =Tabella1[[#This Row],[Percentage of Supplier''s Facilities - Raw]]/$E$151 -> 0.010394591 | H9: Component - Suppliers | K9: =SUMPRODUCT(B4:B150,D4:D150) -> 3.9112072 | M9: Component - Suppliers' Facilities | P9: =SUMPRODUCT(B4:B150,F4:F150) -> 4.0663788
A10: Austria | B10: 3.4101851 | C10: 0 | D10: =Tabella1[[#This Row],[Percentage of Suppliers - Raw]]/$C$151 -> 0 | E10: 0.0037 | F10: =Tabella1[[#This Row],[Percentage of Supplier''s Facilities - Raw]]/$E$151 -> 0.0037339792
A11: Azerbaijan | B11: 5.2109259 | C11: 0 | D11: =Tabella1[[#This Row],[Percentage of Suppliers - Raw]]/$C$151 -> 0 | E11: 0.0001 | F11: =Tabella1[[#This Row],[Percentage of Supplier''s Facilities - Raw]]/$E$151 -> 0.00010091836
A12: Bahrain | B12: 4.2572307 | C12: 0 | D12: =Tabella1[[#This Row],[Percentage of Suppliers - Raw]]/$C$151 -> 0 | E12: 0 | F12: =Tabella1[[#This Row],[Percentage of Supplier''s Facilities - Raw]]/$E$151 -> 0
A13: Bangladesh | B13: 6.2938646 | C13: 0 | D13: =Tabella1[[#This Row],[Percentage of Suppliers - Raw]]/$C$151 -> 0 | E13: 0 | F13: =Tabella1[[#This Row],[Percentage of Supplier''s Facilities - Raw]]/$E$151 -> 0
A14: Belarus | B14: 5.4470392 | C14: 0 | D14: =Tabella1[[#This Row],[Percentage of Suppliers - Raw]]/$C$151 -> 0 | E14: 0.0006 | F14: =Tabella1[[#This Row],[Percentage of Supplier''s Facilities - Raw]]/$E$151 -> 0.00060551014
A15: Belgium | B15: 3.3272157 | C15: 0 | D15: =Tabella1[[#This Row],[Percentage of Suppliers - Raw]]/$C$151 -> 0 | E15: 0.0054 | F15: =Tabella1[[#This Row],[Percentage of Supplier''s Facilities - Raw]]/$E$151 -> 0.0054495913
A16: Benin | B16: 5.9976204 | C16: 0 | D16: =Tabella1[[#This Row],[Percentage of Suppliers - Raw]]/$C$151 -> 0 | E16: 0.0001 | F16: =Tabella1[[#This Row],[Percentage of Supplier''s Facilities - Raw]]/$E$151 -> 0.00010091836
A17: Bhutan | B17: 5.0248646 | C17: 0 | D17: =Tabella1[[#This Row],[Percentage of Suppliers - Raw]]/$C$151 -> 0 | E17: 0 | F17: =Tabella1[[#This Row],[Percentage of Supplier''s Facilities - Raw]]/$E$151 -> 0
A18: Bolivia | B18: 5.4119735 | C18: 0 | D18: =Tabella1[[#This Row],[Percentage of Suppliers - Raw]]/$C$151 -> 0 | E18: 0 | F18: =Tabella1[[#This Row],[Percentage of Supplier''s Facilities - Raw]]/$E$151 -> 0
A19: Bosnia and Herzegovina | B19: 5.3424605 | C19: 0 | D19: =Tabella1[[#This Row],[Percentage of Suppliers - Raw]]/$C$151 -> 0 | E19: 0.0001 | F19: =Tabella1[[#This Row],[Percentage of Supplier''s Facilities - Raw]]/$E$151 -> 0.00010091836
A20: Botswana | B20: 4.3392269 | C20: 0 | D20: =Tabella1[[#This Row],[Percentage of Suppliers - Raw]]/$C$151 -> 0 | E20: 0.0001 | F20: =Tabella1[[#This Row],[Percentage of Supplier''s Facilities - Raw]]/$E$151 -> 0.00010091836
A21: Brazil | B21: 5.352888 | C21: 0 | D21: =Tabella1[[#This Row],[Percentage of Suppliers - Raw]]/$C$151 -> 0 | E21: 0.0141 | F21: =Tabella1[[#This Row],[Percentage of Supplier''s Facilities - Raw]]/$E$151 -> 0.014229488
... A30: Chile | B30: 4.3579263 | C30: 0 | D30: =Tabella1[[#This Row],[Percentage of Suppliers - Raw]]/$C$151 -> 0 | E30: 0.0015 | F30: =Tabella1[[#This Row],[Percentage of Supplier''s Facilities - Raw]]/$E$151 -> 0.0015137754
A31: China | B31: 4.2558828 | C31: =19.4% + 12.27% -> 0.3167 | D31: =Tabella1[[#This Row],[Percentage of Suppliers - Raw]]/$C$151 -> 0.33131081 | E31: 0.2228 | F31: =Tabella1[[#This Row],[Percentage of Supplier''s Facilities - Raw]]/$E$151 -> 0.2248461 | G31: Includes Taiwan
A32: Colombia | B32: 5.724794 | C32: 0 | D32: =Tabella1[[#This Row],[Percentage of Suppliers - Raw]]/$C$151 -> 0 | E32: 0.0011 | F32: =Tabella1[[#This Row],[Percentage of Supplier''s Facilities - Raw]]/$E$151 -> 0.0011101019
A33: Congo, Rep. | B33: 5.6489161 | C33: 0 | D33: =Tabella1[[#This Row],[Percentage of Suppliers - Raw]]/$C$151 -> 0 | E33: 0.0001 | F33: =Tabella1[[#This Row],[Percentage of Supplier''s Facilities - Raw]]/$E$151 -> 0.00010091836
A34: Costa Rica | B34: 4.2297468 | C34: 0 | D34: =Tabella1[[#This Row],[Percentage of Suppliers - Raw]]/$C$151 -> 0 | E34: 0.001 | F34: =Tabella1[[#This Row],[Percentage of Supplier''s Facilities - Raw]]/$E$151 -> 0.0010091836
A35: Cote d'Ivoire | B35: 5.5958392 | C35: 0 | D35: =Tabella1[[#This Row],[Percentage of Suppliers - Raw]]/$C$151 -> 0 | E35: 0.0001 | F35: =Tabella1[[#This Row],[Percentage of Supplier''s Facilities - Raw]]/$E$151 -> 0.00010091836
A36: Croatia | B36: 4.2818307 | C36: 0 | D36: =Tabella1[[#This Row],[Percentage of Suppliers - Raw]]/$C$151 -> 0 | E36: 0.001 | F36: =Tabella1[[#This Row],[Percentage of Supplier''s Facilities - Raw]]/$E$151 -> 0.0010091836
A37: Cyprus | B37: 4.6657023 | C37: 0 | D37: =Tabella1[[#This Row],[Percentage of Suppliers - Raw]]/$C$151 -> 0 | E37: 0 | F37: =Tabella1[[#This Row],[Percentage of Supplier''s Facilities - Raw]]/$E$151 -> 0
A38: Czech Republic | B38: 3.748497 | C38: 0 | D38: =Tabella1[[#This Row],[Percentage of Suppliers - Raw]]/$C$151 -> 0 | E38: 0.0063 | F38: =Tabella1[[#This Row],[Percentage of Supplier''s Facilities - Raw]]/$E$151 -> 0.0063578565
A39: Denmark | B39: 3.1990776 | C39: 0.0014 | D39: =Tabella1[[#This Row],[Percentage of Suppliers - Raw]]/$C$151 -> 0.0014645883 | E39: 0.0029 | F39: =Tabella1[[#This Row],[Percentage of Supplier''s Facilities - Raw]]/$E$151 -> 0.0029266324
A40: Djibouti | B40: 5.9780559 | C40: 0 | D40: =Tabella1[[#This Row],[Percentage of Suppliers - Raw]]/$C$151 -> 0 | E40: 0 | F40: =Tabella1[[#This Row],[Percentage of Supplier''s Facilities - Raw]]/$E$151 -> 0
A41: Dominican Republic | B41: 4.6951386 | C41: 0 | D41: =Tabella1[[#This Row],[Percentage of Suppliers - Raw]]/$C$151 -> 0 | E41: 0.0009 | F41: =Tabella1[[#This Row],[Percentage of Supplier''s Facilities - Raw]]/$E$151 -> 0.00090826521
A42: Ecuador | B42: 5.7086244 | C42: 0 | D42: =Tabella1[[#This Row],[Percentage of Suppliers - Raw]]/$C$151 -> 0 | E42: 0.0001 | F42: =Tabella1[[#This Row],[Percentage of Supplier''s Facilities - Raw]]/$E$151 -> 0.00010091836
A43: Egypt | B43: 5.6039767 | C43: 0 | D43: =Tabella1[[#This Row],[Percentage of Suppliers - Raw]]/$C$151 -> 0 | E43: 0.0015 | F43: =Tabella1[[#This Row],[Percentage of Supplier''s Facilities - Raw]]/$E$151 -> 0.0015137754
... A150: Zimbabwe | B150: 6.1447845 | C150: 0 | D150: =Tabella1[[#This Row],[Percentage of Suppliers - Raw]]/$C$151 -> 0 | E150: 0.0001 | F150: =Tabella1[[#This Row],[Percentage of Supplier''s Facilities - Raw]]/$E$151 -> 0.00010091836
A151: TOTAL | B151: =0.25*INDEX('[1]Political Risk Index'!$B$2:$Q$171,MATCH($A151,'[1]Political Risk Index'!$A$2:$A$171,0),MATCH(B$1,'[1]Political Risk Index'!$B$1:$Q$1,0))+0.15*INDEX('[1]Govt Interference Index'!$B$2:$O$153,MATCH($A151,'[1]Govt Interference Index'!$A$2:$A$153,0),MATCH(B$1,'[1]Govt Interference Index'!$B$1:$O$1,0))+0.1*INDEX('[1]Globalization Index'!$B$2:$Q$217,MATCH($A151,'[1]Globalization Index'!$A$2:$A$217,0),MATCH(B$1,'[1]Globalization Index'!$B$1:$Q$1,0))+0.3*INDEX('[1]Conflict & Unrest Index'!$B$2:$R$161,MATCH($A151,'[1]Conflict & Unrest Index'!$A$2:$A$161,0),MATCH(B$1,'[1]Conflict & Unrest Index'!$B$1:$R$1,0))+0.1*INDEX('[1]Geographical Risk Index'!$B$2:$O$168,MATCH($A151,'[1]Geographical Risk Index'!$A$2:$A$168,0),MATCH(B$1,'[1]Geographical Risk Index'!$B$1:$O$1,0))+0.1*INDEX('[1]Geoeconomic Dependency Index'!$B$2:$S$253,MATCH($A151,'[1]Geoeconomic Dependency Index'!$A$2:$A$253,0),MATCH(B$1,'[1]Geoeconomic Dependency Index'!$B$1:$S$1,0)) -> #N/A | C151: =SUM(C4:C150) -> 0.9559 | D151: =Tabella1[[#This Row],[Percentage of Suppliers - Raw]]/$C$151 -> 1 | E151: =SUM(E4:E150) -> 0.9909 | F151: =SUM(F4:F150) -> 1

Sheet Country of Suppliers - Sony
A1: Sony
A3: Country of Supplier | B3: Country Geopolitical Risk Index | C3: Percentage of Suppliers - Raw | D3: Percentage of Suppliers - Standardized | E3: Percentage of Supplier's Facilities - Raw | F3: Percentage of Supplier's Facilities - Standardized
A4: Albania | B4: 4.3705708 | C4: 0 | D4: =Tabella13[[#This Row],[Percentage of Suppliers - Raw]]/$C$151 -> 0 | E4: 0 | F4: =Tabella13[[#This Row],[Percentage of Supplier''s Facilities - Raw]]/$E$151 -> 0
A5: Algeria | B5: 5.2136193 | C5: 0 | D5: =Tabella13[[#This Row],[Percentage of Suppliers - Raw]]/$C$151 -> 0 | E5: 0 | F5: =Tabella13[[#This Row],[Percentage of Supplier''s Facilities - Raw]]/$E$151 -> 0 | H5: Main Data | M5: Main Data
A6: Angola | B6: 5.6305966 | C6: 0 | D6: =Tabella13[[#This Row],[Percentage of Suppliers - Raw]]/$C$151 -> 0 | E6: 0.0007 | F6: =Tabella13[[#This Row],[Percentage of Supplier''s Facilities - Raw]]/$E$151 -> 0.00070771408 | I6: Country | J6: Geopolitical Risk Index | K6: Value | N6: Country | O6: Geopolitical Risk Index | P6: Value
A7: Argentina | B7: 4.3620978 | C7: 0.0025 | D7: =Tabella13[[#This Row],[Percentage of Suppliers - Raw]]/$C$151 -> 0.0025388443 | E7: 0.0027 | F7: =Tabella13[[#This Row],[Percentage of Supplier''s Facilities - Raw]]/$E$151 -> 0.0027297543 | H7: Minimum | I7: =INDEX(A4:A150,MATCH(MIN(D4:D150),D4:D150,0)) -> Albania | J7: =INDEX(B4:B150,MATCH(MIN(D4:D150),D4:D150,0)) -> 4.3705708 | K7: =INDEX(D4:D150,MATCH(MIN(D4:D150),D4:D150,0)) -> 0 | M7: Minimum | N7: =INDEX(A4:A150,MATCH(MIN(F4:F150),F4:F150,0)) -> Albania | O7: =INDEX(B4:B150,MATCH(MIN(F4:F150),F4:F150,0)) -> 4.3705708 | P7: =INDEX(F4:F150,MATCH(MIN(F4:F150),F4:F150,0)) -> 0
A8: Armenia | B8: 4.7882033 | C8: 0 | D8: =Tabella13[[#This Row],[Percentage of Suppliers - Raw]]/$C$151 -> 0 | E8: 0.0004 | F8: =Tabella13[[#This Row],[Percentage of Supplier''s Facilities - Raw]]/$E$151 -> 0.00040440805 | H8: Maximum | I8: =INDEX(A4:A150,MATCH(MAX(D4:D150),D4:D150,0)) -> Japan | J8: =INDEX(B4:B150,MATCH(MAX(D4:D150),D4:D150,0)) -> 3.3755879 | K8: =INDEX(D4:D150,MATCH(MAX(D4:D150),D4:D150,0)) -> 0.25449375 | M8: Maximum | N8: =INDEX(A4:A150,MATCH(MAX(F4:F150),F4:F150,0)) -> China | O8: =INDEX(B4:B150,MATCH(MAX(F4:F150),F4:F150,0)) -> 4.2558828 | P8: =INDEX(F4:F150,MATCH(MAX(F4:F150),F4:F150,0)) -> 0.26852694
A9: Australia | B9: 3.2228923 | C9: 0.01 | D9: =Tabella13[[#This Row],[Percentage of Suppliers - Raw]]/$C$151 -> 0.010155377 | E9: 0.0055 | F9: =Tabella13[[#This Row],[Percentage of Supplier''s Facilities - Raw]]/$E$151 -> 0.0055606107 | H9: Component - Suppliers | K9: =SUMPRODUCT(B4:B150,D4:D150) -> 3.8594282 | M9: Component - Suppliers' Facilities | P9: =SUMPRODUCT(B4:B150,F4:F150) -> 4.0276283
A10: Austria | B10: 3.4101851 | C10: 0.0025 | D10: =Tabella13[[#This Row],[Percentage of Suppliers - Raw]]/$C$151 -> 0.0025388443 | E10: 0.0024 | F10: =Tabella13[[#This Row],[Percentage of Supplier''s Facilities - Raw]]/$E$151 -> 0.0024264483
A11: Azerbaijan | B11: 5.2109259 | C11: 0 | D11: =Tabella13[[#This Row],[Percentage of Suppliers - Raw]]/$C$151 -> 0 | E11: 0 | F11: =Tabella13[[#This Row],[Percentage of Supplier''s Facilities - Raw]]/$E$151 -> 0
A12: Bahrain | B12: 4.2572307 | C12: 0 | D12: =Tabella13[[#This Row],[Percentage of Suppliers - Raw]]/$C$151 -> 0 | E12: 0 | F12: =Tabella13[[#This Row],[Percentage of Supplier''s Facilities - Raw]]/$E$151 -> 0
A13: Bangladesh | B13: 6.2938646 | C13: 0 | D13: =Tabella13[[#This Row],[Percentage of Suppliers - Raw]]/$C$151 -> 0 | E13: 0.0004 | F13: =Tabella13[[#This Row],[Percentage of Supplier''s Facilities - Raw]]/$E$151 -> 0.00040440805
A14: Belarus | B14: 5.4470392 | C14: 0 | D14: =Tabella13[[#This Row],[Percentage of Suppliers - Raw]]/$C$151 -> 0 | E14: 0.0015 | F14: =Tabella13[[#This Row],[Percentage of Supplier''s Facilities - Raw]]/$E$151 -> 0.0015165302
A15: Belgium | B15: 3.3272157 | C15: 0 | D15: =Tabella13[[#This Row],[Percentage of Suppliers - Raw]]/$C$151 -> 0 | E15: 0.0073 | F15: =Tabella13[[#This Row],[Percentage of Supplier''s Facilities - Raw]]/$E$151 -> 0.0073804469
A16: Benin | B16: 5.9976204 | C16: 0 | D16: =Tabella13[[#This Row],[Percentage of Suppliers - Raw]]/$C$151 -> 0 | E16: 0.0002 | F16: =Tabella13[[#This Row],[Percentage of Supplier''s Facilities - Raw]]/$E$151 -> 0.00020220402
A17: Bhutan | B17: 5.0248646 | C17: 0 | D17: =Tabella13[[#This Row],[Percentage of Suppliers - Raw]]/$C$151 -> 0 | E17: 0 | F17: =Tabella13[[#This Row],[Percentage of Supplier''s Facilities - Raw]]/$E$151 -> 0
A18: Bolivia | B18: 5.4119735 | C18: 0 | D18: =Tabella13[[#This Row],[Percentage of Suppliers - Raw]]/$C$151 -> 0 | E18: 0 | F18: =Tabella13[[#This Row],[Percentage of Supplier''s Facilities - Raw]]/$E$151 -> 0
A19: Bosnia and Herzegovina | B19: 5.3424605 | C19: 0 | D19: =Tabella13[[#This Row],[Percentage of Suppliers - Raw]]/$C$151 -> 0 | E19: 0 | F19: =Tabella13[[#This Row],[Percentage of Supplier''s Facilities - Raw]]/$E$151 -> 0
A20: Botswana | B20: 4.3392269 | C20: 0 | D20: =Tabella13[[#This Row],[Percentage of Suppliers - Raw]]/$C$151 -> 0 | E20: 0.0002 | F20: =Tabella13[[#This Row],[Percentage of Supplier''s Facilities - Raw]]/$E$151 -> 0.00020220402
A21: Brazil | B21: 5.352888 | C21: 0 | D21: =Tabella13[[#This Row],[Percentage of Suppliers - Raw]]/$C$151 -> 0 | E21: 0.0082 | F21: =Tabella13[[#This Row],[Percentage of Supplier''s Facilities - Raw]]/$E$151 -> 0.008290365
... A30: Chile | B30: 4.3579263 | C30: 0 | D30: =Tabella13[[#This Row],[Percentage of Suppliers - Raw]]/$C$151 -> 0 | E30: 0.0009 | F30: =Tabella13[[#This Row],[Percentage of Supplier''s Facilities - Raw]]/$E$151 -> 0.00090991811
A31: China | B31: 4.2558828 | C31: =13.53% + 11.28% -> 0.2481 | D31: =Tabella13[[#This Row],[Percentage of Suppliers - Raw]]/$C$151 -> 0.25195491 | E31: 0.2656 | F31: =Tabella13[[#This Row],[Percentage of Supplier''s Facilities - Raw]]/$E$151 -> 0.26852694 | G31: Includes Taiwan
A32: Colombia | B32: 5.724794 | C32: 0 | D32: =Tabella13[[#This Row],[Percentage of Suppliers - Raw]]/$C$151 -> 0 | E32: 0.0004 | F32: =Tabella13[[#This Row],[Percentage of Supplier''s Facilities - Raw]]/$E$151 -> 0.00040440805
A33: Congo, Rep. | B33: 5.6489161 | C33: 0 | D33: =Tabella13[[#This Row],[Percentage of Suppliers - Raw]]/$C$151 -> 0 | E33: 0.0002 | F33: =Tabella13[[#This Row],[Percentage of Supplier''s Facilities - Raw]]/$E$151 -> 0.00020220402
A34: Costa Rica | B34: 4.2297468 | C34: 0 | D34: =Tabella13[[#This Row],[Percentage of Suppliers - Raw]]/$C$151 -> 0 | E34: 0.0002 | F34: =Tabella13[[#This Row],[Percentage of Supplier''s Facilities - Raw]]/$E$151 -> 0.00020220402
A35: Cote d'Ivoire | B35: 5.5958392 | C35: 0 | D35: =Tabella13[[#This Row],[Percentage of Suppliers - Raw]]/$C$151 -> 0 | E35: 0.0002 | F35: =Tabella13[[#This Row],[Percentage of Supplier''s Facilities - Raw]]/$E$151 -> 0.00020220402
A36: Croatia | B36: 4.2818307 | C36: 0 | D36: =Tabella13[[#This Row],[Percentage of Suppliers - Raw]]/$C$151 -> 0 | E36: 0.0004 | F36: =Tabella13[[#This Row],[Percentage of Supplier''s Facilities - Raw]]/$E$151 -> 0.00040440805
A37: Cyprus | B37: 4.6657023 | C37: 0 | D37: =Tabella13[[#This Row],[Percentage of Suppliers - Raw]]/$C$151 -> 0 | E37: 0 | F37: =Tabella13[[#This Row],[Percentage of Supplier''s Facilities - Raw]]/$E$151 -> 0
A38: Czech Republic | B38: 3.748497 | C38: 0 | D38: =Tabella13[[#This Row],[Percentage of Suppliers - Raw]]/$C$151 -> 0 | E38: 0.0075 | F38: =Tabella13[[#This Row],[Percentage of Supplier''s Facilities - Raw]]/$E$151 -> 0.0075826509
A39: Denmark | B39: 3.1990776 | C39: 0 | D39: =Tabella13[[#This Row],[Percentage of Suppliers - Raw]]/$C$151 -> 0 | E39: 0.0031 | F39: =Tabella13[[#This Row],[Percentage of Supplier''s Facilities - Raw]]/$E$151 -> 0.0031341624
A40: Djibouti | B40: 5.9780559 | C40: 0 | D40: =Tabella13[[#This Row],[Percentage of Suppliers - Raw]]/$C$151 -> 0 | E40: 0 | F40: =Tabella13[[#This Row],[Percentage of Supplier''s Facilities - Raw]]/$E$151 -> 0
A41: Dominican Republic | B41: 4.6951386 | C41: 0 | D41: =Tabella13[[#This Row],[Percentage of Suppliers - Raw]]/$C$151 -> 0 | E41: 0.0013 | F41: =Tabella13[[#This Row],[Percentage of Supplier''s Facilities - Raw]]/$E$151 -> 0.0013143262
A42: Ecuador | B42: 5.7086244 | C42: 0 | D42: =Tabella13[[#This Row],[Percentage of Suppliers - Raw]]/$C$151 -> 0 | E42: 0 | F42: =Tabella13[[#This Row],[Percentage of Supplier''s Facilities - Raw]]/$E$151 -> 0
A43: Egypt | B43: 5.6039767 | C43: 0 | D43: =Tabella13[[#This Row],[Percentage of Suppliers - Raw]]/$C$151 -> 0 | E43: 0.0004 | F43: =Tabella13[[#This Row],[Percentage of Supplier''s Facilities - Raw]]/$E$151 -> 0.00040440805
... A150: Zimbabwe | B150: 6.1447845 | C150: 0 | D150: =Tabella13[[#This Row],[Percentage of Suppliers - Raw]]/$C$151 -> 0 | E150: 0 | F150: =Tabella13[[#This Row],[Percentage of Supplier''s Facilities - Raw]]/$E$151 -> 0
A151: TOTAL | B151: =0.25*INDEX('[1]Political Risk Index'!$B$2:$Q$171,MATCH($A151,'[1]Political Risk Index'!$A$2:$A$171,0),MATCH(B$1,'[1]Political Risk Index'!$B$1:$Q$1,0))+0.15*INDEX('[1]Govt Interference Index'!$B$2:$O$153,MATCH($A151,'[1]Govt Interference Index'!$A$2:$A$153,0),MATCH(B$1,'[1]Govt Interference Index'!$B$1:$O$1,0))+0.1*INDEX('[1]Globalization Index'!$B$2:$Q$217,MATCH($A151,'[1]Globalization Index'!$A$2:$A$217,0),MATCH(B$1,'[1]Globalization Index'!$B$1:$Q$1,0))+0.3*INDEX('[1]Conflict & Unrest Index'!$B$2:$R$161,MATCH($A151,'[1]Conflict & Unrest Index'!$A$2:$A$161,0),MATCH(B$1,'[1]Conflict & Unrest Index'!$B$1:$R$1,0))+0.1*INDEX('[1]Geographical Risk Index'!$B$2:$O$168,MATCH($A151,'[1]Geographical Risk Index'!$A$2:$A$168,0),MATCH(B$1,'[1]Geographical Risk Index'!$B$1:$O$1,0))+0.1*INDEX('[1]Geoeconomic Dependency Index'!$B$2:$S$253,MATCH($A151,'[1]Geoeconomic Dependency Index'!$A$2:$A$253,0),MATCH(B$1,'[1]Geoeconomic Dependency Index'!$B$1:$S$1,0)) -> #N/A | C151: =SUM(C4:C150) -> 0.9847 | D151: =Tabella13[[#This Row],[Percentage of Suppliers - Raw]]/$C$151 -> 1 | E151: =SUM(E4:E150) -> 0.9891 | F151: =SUM(F4:F150) -> 1

Sheet Country of Suppliers - Meta
A1: Meta
A3: Country of Supplier | B3: Country Geopolitical Risk Index | C3: Percentage of Suppliers - Raw | D3: Percentage of Suppliers - Standardized | E3: Percentage of Supplier's Facilities - Raw | F3: Percentage of Supplier's Facilities - Standardize
A4: Albania | B4: 4.3705708 | C4: 0 | D4: =Tabella14[[#This Row],[Percentage of Suppliers - Raw]]/$C$151 -> 0 | E4: 0.0004 | F4: =Tabella14[[#This Row],[Percentage of Supplier''s Facilities - Raw]]/$E$151 -> 0.00040371417
A5: Algeria | B5: 5.2136193 | C5: 0 | D5: =Tabella14[[#This Row],[Percentage of Suppliers - Raw]]/$C$151 -> 0 | E5: 0.0008 | F5: =Tabella14[[#This Row],[Percentage of Supplier''s Facilities - Raw]]/$E$151 -> 0.00080742834 | H5: Main Data | M5: Main Data
A6: Angola | B6: 5.6305966 | C6: 0 | D6: =Tabella14[[#This Row],[Percentage of Suppliers - Raw]]/$C$151 -> 0 | E6: 0.0013 | F6: =Tabella14[[#This Row],[Percentage of Supplier''s Facilities - Raw]]/$E$151 -> 0.0013120711 | I6: Country | J6: Geopolitical Risk Index | K6: Value | N6: Country | O6: Geopolitical Risk Index | P6: Value
A7: Argentina | B7: 4.3620978 | C7: 0 | D7: =Tabella14[[#This Row],[Percentage of Suppliers - Raw]]/$C$151 -> 0 | E7: 0.0025 | F7: =Tabella14[[#This Row],[Percentage of Supplier''s Facilities - Raw]]/$E$151 -> 0.0025232136 | H7: Minimum | I7: =INDEX(A4:A150,MATCH(MIN(D4:D150),D4:D150,0)) -> Albania | J7: =INDEX(B4:B150,MATCH(MIN(D4:D150),D4:D150,0)) -> 4.3705708 | K7: =INDEX(D4:D150,MATCH(MIN(D4:D150),D4:D150,0)) -> 0 | M7: Minimum | N7: =INDEX(A4:A150,MATCH(MIN(F4:F150),F4:F150,0)) -> Azerbaijan | O7: =INDEX(B4:B150,MATCH(MIN(F4:F150),F4:F150,0)) -> 5.2109259 | P7: =INDEX(F4:F150,MATCH(MIN(F4:F150),F4:F150,0)) -> 0
A8: Armenia | B8: 4.7882033 | C8: 0 | D8: =Tabella14[[#This Row],[Percentage of Suppliers - Raw]]/$C$151 -> 0 | E8: 0.0004 | F8: =Tabella14[[#This Row],[Percentage of Supplier''s Facilities - Raw]]/$E$151 -> 0.00040371417 | H8: Maximum | I8: =INDEX(A4:A150,MATCH(MAX(D4:D150),D4:D150,0)) -> United States | J8: =INDEX(B4:B150,MATCH(MAX(D4:D150),D4:D150,0)) -> 4.1903554 | K8: =INDEX(D4:D150,MATCH(MAX(D4:D150),D4:D150,0)) -> 0.37392099 | M8: Maximum | N8: =INDEX(A4:A150,MATCH(MAX(F4:F150),F4:F150,0)) -> United States | O8: =INDEX(B4:B150,MATCH(MAX(F4:F150),F4:F150,0)) -> 4.1903554 | P8: =INDEX(F4:F150,MATCH(MAX(F4:F150),F4:F150,0)) -> 0.233044
A9: Australia | B9: 3.2228923 | C9: 0.0155 | D9: =Tabella14[[#This Row],[Percentage of Suppliers - Raw]]/$C$151 -> 0.015740835 | E9: 0.0183 | F9: =Tabella14[[#This Row],[Percentage of Supplier''s Facilities - Raw]]/$E$151 -> 0.018469923 | H9: Component - Suppliers | K9: =SUMPRODUCT(B4:B150,D4:D150) -> 3.9636017 | M9: Component - Suppliers' Facilities | P9: =SUMPRODUCT(B4:B150,F4:F150) -> 4.0689945
A10: Austria | B10: 3.4101851 | C10: 0 | D10: =Tabella14[[#This Row],[Percentage of Suppliers - Raw]]/$C$151 -> 0 | E10: 0.0058 | F10: =Tabella14[[#This Row],[Percentage of Supplier''s Facilities - Raw]]/$E$151 -> 0.0058538555
A11: Azerbaijan | B11: 5.2109259 | C11: 0 | D11: =Tabella14[[#This Row],[Percentage of Suppliers - Raw]]/$C$151 -> 0 | E11: 0 | F11: =Tabella14[[#This Row],[Percentage of Supplier''s Facilities - Raw]]/$E$151 -> 0
A12: Bahrain | B12: 4.2572307 | C12: 0 | D12: =Tabella14[[#This Row],[Percentage of Suppliers - Raw]]/$C$151 -> 0 | E12: 0 | F12: =Tabella14[[#This Row],[Percentage of Supplier''s Facilities - Raw]]/$E$151 -> 0
A13: Bangladesh | B13: 6.2938646 | C13: 0 | D13: =Tabella14[[#This Row],[Percentage of Suppliers - Raw]]/$C$151 -> 0 | E13: 0.0004 | F13: =Tabella14[[#This Row],[Percentage of Supplier''s Facilities - Raw]]/$E$151 -> 0.00040371417
A14: Belarus | B14: 5.4470392 | C14: 0 | D14: =Tabella14[[#This Row],[Percentage of Suppliers - Raw]]/$C$151 -> 0 | E14: 0 | F14: =Tabella14[[#This Row],[Percentage of Supplier''s Facilities - Raw]]/$E$151 -> 0
A15: Belgium | B15: 3.3272157 | C15: 0.0039 | D15: =Tabella14[[#This Row],[Percentage of Suppliers - Raw]]/$C$151 -> 0.0039605971 | E15: 0.0038 | F15: =Tabella14[[#This Row],[Percentage of Supplier''s Facilities - Raw]]/$E$151 -> 0.0038352846
A16: Benin | B16: 5.9976204 | C16: 0 | D16: =Tabella14[[#This Row],[Percentage of Suppliers - Raw]]/$C$151 -> 0 | E16: 0.0001 | F16: =Tabella14[[#This Row],[Percentage of Supplier''s Facilities - Raw]]/$E$151 -> 0.00010092854
A17: Bhutan | B17: 5.0248646 | C17: 0 | D17: =Tabella14[[#This Row],[Percentage of Suppliers - Raw]]/$C$151 -> 0 | E17: 0 | F17: =Tabella14[[#This Row],[Percentage of Supplier''s Facilities - Raw]]/$E$151 -> 0
A18: Bolivia | B18: 5.4119735 | C18: 0 | D18: =Tabella14[[#This Row],[Percentage of Suppliers - Raw]]/$C$151 -> 0 | E18: 0 | F18: =Tabella14[[#This Row],[Percentage of Supplier''s Facilities - Raw]]/$E$151 -> 0
A19: Bosnia and Herzegovina | B19: 5.3424605 | C19: 0 | D19: =Tabella14[[#This Row],[Percentage of Suppliers - Raw]]/$C$151 -> 0 | E19: 0.0004 | F19: =Tabella14[[#This Row],[Percentage of Supplier''s Facilities - Raw]]/$E$151 -> 0.00040371417
A20: Botswana | B20: 4.3392269 | C20: 0 | D20: =Tabella14[[#This Row],[Percentage of Suppliers - Raw]]/$C$151 -> 0 | E20: 0.0001 | F20: =Tabella14[[#This Row],[Percentage of Supplier''s Facilities - Raw]]/$E$151 -> 0.00010092854
A21: Brazil | B21: 5.352888 | C21: 0.0039 | D21: =Tabella14[[#This Row],[Percentage of Suppliers - Raw]]/$C$151 -> 0.0039605971 | E21: 0.0154 | F21: =Tabella14[[#This Row],[Percentage of Supplier''s Facilities - Raw]]/$E$151 -> 0.015542996
... A30: Chile | B30: 4.3579263 | C30: 0.0039 | D30: =Tabella14[[#This Row],[Percentage of Suppliers - Raw]]/$C$151 -> 0.0039605971 | E30: 0.0025 | F30: =Tabella14[[#This Row],[Percentage of Supplier''s Facilities - Raw]]/$E$151 -> 0.0025232136
A31: China | B31: 4.2558828 | C31: =12.02% + 5.43% -> 0.1745 | D31: =Tabella14[[#This Row],[Percentage of Suppliers - Raw]]/$C$151 -> 0.17721133 | E31: 0.1926 | F31: =Tabella14[[#This Row],[Percentage of Supplier''s Facilities - Raw]]/$E$151 -> 0.19438837 | G31: Includes Taiwan
A32: Colombia | B32: 5.724794 | C32: 0 | D32: =Tabella14[[#This Row],[Percentage of Suppliers - Raw]]/$C$151 -> 0 | E32: 0.0021 | F32: =Tabella14[[#This Row],[Percentage of Supplier''s Facilities - Raw]]/$E$151 -> 0.0021194994
A33: Congo, Rep. | B33: 5.6489161 | C33: 0 | D33: =Tabella14[[#This Row],[Percentage of Suppliers - Raw]]/$C$151 -> 0 | E33: 0.0001 | F33: =Tabella14[[#This Row],[Percentage of Supplier''s Facilities - Raw]]/$E$151 -> 0.00010092854
A34: Costa Rica | B34: 4.2297468 | C34: 0 | D34: =Tabella14[[#This Row],[Percentage of Suppliers - Raw]]/$C$151 -> 0 | E34: 0.0033 | F34: =Tabella14[[#This Row],[Percentage of Supplier''s Facilities - Raw]]/$E$151 -> 0.0033306419
A35: Cote d'Ivoire | B35: 5.5958392 | C35: 0 | D35: =Tabella14[[#This Row],[Percentage of Suppliers - Raw]]/$C$151 -> 0 | E35: 0.0004 | F35: =Tabella14[[#This Row],[Percentage of Supplier''s Facilities - Raw]]/$E$151 -> 0.00040371417
A36: Croatia | B36: 4.2818307 | C36: 0 | D36: =Tabella14[[#This Row],[Percentage of Suppliers - Raw]]/$C$151 -> 0 | E36: 0.0013 | F36: =Tabella14[[#This Row],[Percentage of Supplier''s Facilities - Raw]]/$E$151 -> 0.0013120711
A37: Cyprus | B37: 4.6657023 | C37: 0 | D37: =Tabella14[[#This Row],[Percentage of Suppliers - Raw]]/$C$151 -> 0 | E37: 0 | F37: =Tabella14[[#This Row],[Percentage of Supplier''s Facilities - Raw]]/$E$151 -> 0
A38: Czech Republic | B38: 3.748497 | C38: 0 | D38: =Tabella14[[#This Row],[Percentage of Suppliers - Raw]]/$C$151 -> 0 | E38: 0.0079 | F38: =Tabella14[[#This Row],[Percentage of Supplier''s Facilities - Raw]]/$E$151 -> 0.0079733549
A39: Denmark | B39: 3.1990776 | C39: 0 | D39: =Tabella14[[#This Row],[Percentage of Suppliers - Raw]]/$C$151 -> 0 | E39: 0.0038 | F39: =Tabella14[[#This Row],[Percentage of Supplier''s Facilities - Raw]]/$E$151 -> 0.0038352846
A40: Djibouti | B40: 5.9780559 | C40: 0 | D40: =Tabella14[[#This Row],[Percentage of Suppliers - Raw]]/$C$151 -> 0 | E40: 0 | F40: =Tabella14[[#This Row],[Percentage of Supplier''s Facilities - Raw]]/$E$151 -> 0
A41: Dominican Republic | B41: 4.6951386 | C41: 0 | D41: =Tabella14[[#This Row],[Percentage of Suppliers - Raw]]/$C$151 -> 0 | E41: 0.0025 | F41: =Tabella14[[#This Row],[Percentage of Supplier''s Facilities - Raw]]/$E$151 -> 0.0025232136
A42: Ecuador | B42: 5.7086244 | C42: 0 | D42: =Tabella14[[#This Row],[Percentage of Suppliers - Raw]]/$C$151 -> 0 | E42: 0.0001 | F42: =Tabella14[[#This Row],[Percentage of Supplier''s Facilities - Raw]]/$E$151 -> 0.00010092854
A43: Egypt | B43: 5.6039767 | C43: 0 | D43: =Tabella14[[#This Row],[Percentage of Suppliers - Raw]]/$C$151 -> 0 | E43: 0.0017 | F43: =Tabella14[[#This Row],[Percentage of Supplier''s Facilities - Raw]]/$E$151 -> 0.0017157852
... A150: Zimbabwe | B150: 6.1447845 | C150: 0 | D150: =Tabella14[[#This Row],[Percentage of Suppliers - Raw]]/$C$151 -> 0 | E150: 0 | F150: =Tabella14[[#This Row],[Percentage of Supplier''s Facilities - Raw]]/$E$151 -> 0
A151: TOTAL | B151: =0.25*INDEX('[1]Political Risk Index'!$B$2:$Q$171,MATCH($A151,'[1]Political Risk Index'!$A$2:$A$171,0),MATCH(B$1,'[1]Political Risk Index'!$B$1:$Q$1,0))+0.15*INDEX('[1]Govt Interference Index'!$B$2:$O$153,MATCH($A151,'[1]Govt Interference Index'!$A$2:$A$153,0),MATCH(B$1,'[1]Govt Interference Index'!$B$1:$O$1,0))+0.1*INDEX('[1]Globalization Index'!$B$2:$Q$217,MATCH($A151,'[1]Globalization Index'!$A$2:$A$217,0),MATCH(B$1,'[1]Globalization Index'!$B$1:$Q$1,0))+0.3*INDEX('[1]Conflict & Unrest Index'!$B$2:$R$161,MATCH($A151,'[1]Conflict & Unrest Index'!$A$2:$A$161,0),MATCH(B$1,'[1]Conflict & Unrest Index'!$B$1:$R$1,0))+0.1*INDEX('[1]Geographical Risk Index'!$B$2:$O$168,MATCH($A151,'[1]Geographical Risk Index'!$A$2:$A$168,0),MATCH(B$1,'[1]Geographical Risk Index'!$B$1:$O$1,0))+0.1*INDEX('[1]Geoeconomic Dependency Index'!$B$2:$S$253,MATCH($A151,'[1]Geoeconomic Dependency Index'!$A$2:$A$253,0),MATCH(B$1,'[1]Geoeconomic Dependency Index'!$B$1:$S$1,0)) -> #N/A | C151: =SUM(C4:C150) -> 0.9847 | D151: =SUM(D4:D150) -> 1 | E151: =SUM(E4:E150) -> 0.9908 | F151: =SUM(F4:F150) -> 1

Sheet Country of Suppliers - NVIDIA
A1: NVIDIA
A3: Country of Supplier | B3: Country Geopolitical Risk Index | C3: Percentage of Suppliers - Raw | D3: Percentage of Suppliers - Standardized | E3: Percentage of Supplier's Facilities - Raw | F3: Percentage of Supplier's Facilities - Standardized
A4: Albania | B4: 4.3705708 | C4: 0 | D4: =Tabella15[[#This Row],[Percentage of Suppliers - Raw]]/$C$151 -> 0 | E4: 0.0002 | F4: =Tabella15[[#This Row],[Percentage of Supplier''s Facilities - Raw]]/$E$151 -> 0.00020082338
A5: Algeria | B5: 5.2136193 | C5: 0 | D5: =Tabella15[[#This Row],[Percentage of Suppliers - Raw]]/$C$151 -> 0 | E5: 0.0005 | F5: =Tabella15[[#This Row],[Percentage of Supplier''s Facilities - Raw]]/$E$151 -> 0.00050205844 | H5: Main Data | M5: Main Data
A6: Angola | B6: 5.6305966 | C6: 0 | D6: =Tabella15[[#This Row],[Percentage of Suppliers - Raw]]/$C$151 -> 0 | E6: 0.0004 | F6: =Tabella15[[#This Row],[Percentage of Supplier''s Facilities - Raw]]/$E$151 -> 0.00040164675 | I6: Country | J6: Geopolitical Risk Index | K6: Value | N6: Country | O6: Geopolitical Risk Index | P6: Value
A7: Argentina | B7: 4.3620978 | C7: 0 | D7: =Tabella15[[#This Row],[Percentage of Suppliers - Raw]]/$C$151 -> 0 | E7: 0.0018 | F7: =Tabella15[[#This Row],[Percentage of Supplier''s Facilities - Raw]]/$E$151 -> 0.0018074104 | H7: Minimum | I7: =INDEX(A4:A150,MATCH(MIN(D4:D150),D4:D150,0)) -> Albania | J7: =INDEX(B4:B150,MATCH(MIN(D4:D150),D4:D150,0)) -> 4.3705708 | K7: =INDEX(D4:D150,MATCH(MIN(D4:D150),D4:D150,0)) -> 0 | M7: Minimum | N7: =INDEX(A4:A150,MATCH(MIN(F4:F150),F4:F150,0)) -> Bahrain | O7: =INDEX(B4:B150,MATCH(MIN(F4:F150),F4:F150,0)) -> 4.2572307 | P7: =INDEX(F4:F150,MATCH(MIN(F4:F150),F4:F150,0)) -> 0
A8: Armenia | B8: 4.7882033 | C8: 0 | D8: =Tabella15[[#This Row],[Percentage of Suppliers - Raw]]/$C$151 -> 0 | E8: 0.0002 | F8: =Tabella15[[#This Row],[Percentage of Supplier''s Facilities - Raw]]/$E$151 -> 0.00020082338 | H8: Maximum | I8: =INDEX(A4:A150,MATCH(MAX(D4:D150),D4:D150,0)) -> United States | J8: =INDEX(B4:B150,MATCH(MAX(D4:D150),D4:D150,0)) -> 4.1903554 | K8: =INDEX(D4:D150,MATCH(MAX(D4:D150),D4:D150,0)) -> 0.4189624 | M8: Maximum | N8: =INDEX(A4:A150,MATCH(MAX(F4:F150),F4:F150,0)) -> United States | O8: =INDEX(B4:B150,MATCH(MAX(F4:F150),F4:F150,0)) -> 4.1903554 | P8: =INDEX(F4:F150,MATCH(MAX(F4:F150),F4:F150,0)) -> 0.24861934
A9: Australia | B9: 3.2228923 | C9: 0.0056 | D9: =Tabella15[[#This Row],[Percentage of Suppliers - Raw]]/$C$151 -> 0.0056304042 | E9: 0.0107 | F9: =Tabella15[[#This Row],[Percentage of Supplier''s Facilities - Raw]]/$E$151 -> 0.010744051 | H9: Component - Suppliers | K9: =SUMPRODUCT(B4:B150,D4:D150) -> 4.0426345 | M9: Component - Suppliers' Facilities | P9: =SUMPRODUCT(B4:B150,F4:F150) -> 4.099785
A10: Austria | B10: 3.4101851 | C10: 0.0056 | D10: =Tabella15[[#This Row],[Percentage of Suppliers - Raw]]/$C$151 -> 0.0056304042 | E10: 0.0045 | F10: =Tabella15[[#This Row],[Percentage of Supplier''s Facilities - Raw]]/$E$151 -> 0.004518526
A11: Azerbaijan | B11: 5.2109259 | C11: 0 | D11: =Tabella15[[#This Row],[Percentage of Suppliers - Raw]]/$C$151 -> 0 | E11: 0.0002 | F11: =Tabella15[[#This Row],[Percentage of Supplier''s Facilities - Raw]]/$E$151 -> 0.00020082338
A12: Bahrain | B12: 4.2572307 | C12: 0 | D12: =Tabella15[[#This Row],[Percentage of Suppliers - Raw]]/$C$151 -> 0 | E12: 0 | F12: =Tabella15[[#This Row],[Percentage of Supplier''s Facilities - Raw]]/$E$151 -> 0
A13: Bangladesh | B13: 6.2938646 | C13: 0 | D13: =Tabella15[[#This Row],[Percentage of Suppliers - Raw]]/$C$151 -> 0 | E13: 0.0004 | F13: =Tabella15[[#This Row],[Percentage of Supplier''s Facilities - Raw]]/$E$151 -> 0.00040164675
A14: Belarus | B14: 5.4470392 | C14: 0 | D14: =Tabella15[[#This Row],[Percentage of Suppliers - Raw]]/$C$151 -> 0 | E14: 0 | F14: =Tabella15[[#This Row],[Percentage of Supplier''s Facilities - Raw]]/$E$151 -> 0
A15: Belgium | B15: 3.3272157 | C15: 0 | D15: =Tabella15[[#This Row],[Percentage of Suppliers - Raw]]/$C$151 -> 0 | E15: 0.0027 | F15: =Tabella15[[#This Row],[Percentage of Supplier''s Facilities - Raw]]/$E$151 -> 0.0027111156
A16: Benin | B16: 5.9976204 | C16: 0 | D16: =Tabella15[[#This Row],[Percentage of Suppliers - Raw]]/$C$151 -> 0 | E16: 0 | F16: =Tabella15[[#This Row],[Percentage of Supplier''s Facilities - Raw]]/$E$151 -> 0
A17: Bhutan | B17: 5.0248646 | C17: 0 | D17: =Tabella15[[#This Row],[Percentage of Suppliers - Raw]]/$C$151 -> 0 | E17: 0 | F17: =Tabella15[[#This Row],[Percentage of Supplier''s Facilities - Raw]]/$E$151 -> 0
A18: Bolivia | B18: 5.4119735 | C18: 0 | D18: =Tabella15[[#This Row],[Percentage of Suppliers - Raw]]/$C$151 -> 0 | E18: 0 | F18: =Tabella15[[#This Row],[Percentage of Supplier''s Facilities - Raw]]/$E$151 -> 0
A19: Bosnia and Herzegovina | B19: 5.3424605 | C19: 0 | D19: =Tabella15[[#This Row],[Percentage of Suppliers - Raw]]/$C$151 -> 0 | E19: 0.0002 | F19: =Tabella15[[#This Row],[Percentage of Supplier''s Facilities - Raw]]/$E$151 -> 0.00020082338
A20: Botswana | B20: 4.3392269 | C20: 0 | D20: =Tabella15[[#This Row],[Percentage of Suppliers - Raw]]/$C$151 -> 0 | E20: 0 | F20: =Tabella15[[#This Row],[Percentage of Supplier''s Facilities - Raw]]/$E$151 -> 0
A21: Brazil | B21: 5.352888 | C21: 0 | D21: =Tabella15[[#This Row],[Percentage of Suppliers - Raw]]/$C$151 -> 0 | E21: 0.0131 | F21: =Tabella15[[#This Row],[Percentage of Supplier''s Facilities - Raw]]/$E$151 -> 0.013153931
... A30: Chile | B30: 4.3579263 | C30: 0 | D30: =Tabella15[[#This Row],[Percentage of Suppliers - Raw]]/$C$151 -> 0 | E30: 0.0015 | F30: =Tabella15[[#This Row],[Percentage of Supplier''s Facilities - Raw]]/$E$151 -> 0.0015061753
A31: China | B31: 4.2558828 | C31: =14.44%+ 14.44% -> 0.2888 | D31: =Tabella15[[#This Row],[Percentage of Suppliers - Raw]]/$C$151 -> 0.29036799 | E31: 0.2161 | F31: =Tabella15[[#This Row],[Percentage of Supplier''s Facilities - Raw]]/$E$151 -> 0.21698966 | G31: Includes Taiwan
A32: Colombia | B32: 5.724794 | C32: 0 | D32: =Tabella15[[#This Row],[Percentage of Suppliers - Raw]]/$C$151 -> 0 | E32: 0.0015 | F32: =Tabella15[[#This Row],[Percentage of Supplier''s Facilities - Raw]]/$E$151 -> 0.0015061753
A33: Congo, Rep. | B33: 5.6489161 | C33: 0 | D33: =Tabella15[[#This Row],[Percentage of Suppliers - Raw]]/$C$151 -> 0 | E33: 0 | F33: =Tabella15[[#This Row],[Percentage of Supplier''s Facilities - Raw]]/$E$151 -> 0
A34: Costa Rica | B34: 4.2297468 | C34: 0 | D34: =Tabella15[[#This Row],[Percentage of Suppliers - Raw]]/$C$151 -> 0 | E34: 0.0015 | F34: =Tabella15[[#This Row],[Percentage of Supplier''s Facilities - Raw]]/$E$151 -> 0.0015061753
