Workbook

Sheet Facility Risk - Overall
A1: Company Name | B1: Facility Risk - Component
A2: Apple | B2: ='Facility Risk - Apple'!J9 -> 4.2493629
A3: Meta | B3: ='Facility Risk - Meta'!J9 -> 3.32
A4: Microsoft | B4: ='Facility Risk - Microsoft'!J9 -> 4.05
A5: Ford | B5: ='Facility Risk - Ford'!J9 -> 4.2394477
A6: Procter & Gamble | B6: ='Facility Risk - P&G'!J9 -> 4.3110533
A7: Samsung | B7: ='Facility Risk - Samsung'!J9 -> 4.0176366
A8: Amazon | B8: ='Facility Risk - Amazon'!J9 -> 4.0365251
A9: NVIDIA | B9: ='Facility Risk - NVIDIA'!J9 -> 4.4
A10: Allianz | B10: ='Facility Risk - Allianz'!J9 -> 0
A11: L'Oreal | B11: ='Facility Risk - L''Oreal'!J9 -> 4.1109066
A12: LVMH | B12: ='Facility Risk - LVMH'!J9 -> 3.7645546
A13: Novo Nordisk | B13: ='Facility Risk - Nordisk'!J9 -> 3.8972
A14: Reliance Industries | B14: ='Facility Risk - Reliance'!J9 -> 5.07
A15: SAP | B15: ='Facility Risk - SAP'!J9 -> 0
A16: Sony | B16: ='Facility Risk - Sony'!J9 -> 3.6262216
A17: Tencent | B17: ='Facility Risk - Tencent'!J9 -> 0
A18: TotaleEnergies | B18: ='Facility Risk - Total en'!J9 -> 4.2137973
A19: Toyota | B19: ='Facility Risk - Toyota'!J9 -> 4.0088225
A20: TSMC | B20: ='Facility Risk - ASML'!J9 -> 3.996919
A21: Volkswagen | B21: ='Facility Risk - VW'!J9 -> 4.1877051
A22: JP Morgan | B22: ='Facility Risk - JP Morgan'!J9 -> 0
A23: ASML | B23: ='Facility Risk - ASML'!J9 -> 3.996919
A24: BNP Paribas | B24: ='Facility Risk - BNP'!J9 -> 0
A25: Eli Lilly | B25: ='Facility Risk - Eli Lilly'!J9 -> 3.9675
A26: ENI | B26: ='Facility Risk - Eni'!J9 -> 0

Sheet Facility Risk - Apple
A1: Apple
A3: Country of Revenue | B3: Country Geopolitical Risk Index | C3: Percentage of Facility Sites - Raw | D3: Percentage of Facility Sites - Standardized
A4: Albania | B4: 4.37 | C4: 0 | D4: ='Facility Risk - Apple'!$C4/$C$151 -> 0
A5: Algeria | B5: 5.21 | C5: 0 | D5: ='Facility Risk - Apple'!$C5/$C$151 -> 0 | G5: Main Data
A6: Angola | B6: 5.63 | C6: 0 | D6: ='Facility Risk - Apple'!$C6/$C$151 -> 0 | H6: Country | I6: Geopolitical Risk Index | J6: Value
A7: Argentina | B7: 4.36 | C7: 0 | D7: ='Facility Risk - Apple'!$C7/$C$151 -> 0 | G7: Minimum | H7: =INDEX(A4:A150,MATCH(MIN(D4:D150),D4:D150,0)) -> Albania | I7: =INDEX(B4:B150,MATCH(MIN(D4:D150),D4:D150,0)) -> 4.37 | J7: =INDEX(D4:D150,MATCH(MIN(D4:D150),D4:D150,0)) -> 0
A8: Armenia | B8: 4.79 | C8: 0 | D8: ='Facility Risk - Apple'!$C8/$C$151 -> 0 | G8: Maximum | H8: =INDEX(A4:A150,MATCH(MAX(D4:D150),D4:D150,0)) -> United States | I8: =INDEX(B4:B150,MATCH(MAX(D4:D150),D4:D150,0)) -> 4.19 | J8: =INDEX(D4:D150,MATCH(MAX(D4:D150),D4:D150,0)) -> 0.35713571
A9: Australia | B9: 3.22 | C9: 0 | D9: ='Facility Risk - Apple'!$C9/$C$151 -> 0 | G9: Component - Facility Risk | J9: =SUMPRODUCT(B4:B150,D4:D150) -> 4.2493629
A10: Austria | B10: 3.41 | C10: 0 | D10: ='Facility Risk - Apple'!$C10/$C$151 -> 0
A11: Azerbaijan | B11: 5.21 | C11: 0 | D11: ='Facility Risk - Apple'!$C11/$C$151 -> 0
A12: Bahrain | B12: 4.26 | C12: 0 | D12: ='Facility Risk - Apple'!$C12/$C$151 -> 0
A13: Bangladesh | B13: 6.29 | C13: 0 | D13: ='Facility Risk - Apple'!$C13/$C$151 -> 0
A14: Belarus | B14: 5.45 | C14: 0 | D14: ='Facility Risk - Apple'!$C14/$C$151 -> 0
A15: Belgium | B15: 3.33 | C15: 0 | D15: ='Facility Risk - Apple'!$C15/$C$151 -> 0
A16: Benin | B16: 6 | C16: 0 | D16: ='Facility Risk - Apple'!$C16/$C$151 -> 0
A17: Bhutan | B17: 5.02 | C17: 0 | D17: ='Facility Risk - Apple'!$C17/$C$151 -> 0
A18: Bolivia | B18: 5.41 | C18: 0 | D18: ='Facility Risk - Apple'!$C18/$C$151 -> 0
A19: Bosnia and Herzegovina | B19: 5.34 | C19: 0 | D19: ='Facility Risk - Apple'!$C19/$C$151 -> 0
A20: Botswana | B20: 4.34 | C20: 0 | D20: ='Facility Risk - Apple'!$C20/$C$151 -> 0
A21: Brazil | B21: 5.35 | C21: 0 | D21: ='Facility Risk - Apple'!$C21/$C$151 -> 0
... A30: Chile | B30: 4.36 | C30: 0 | D30: ='Facility Risk - Apple'!$C30/$C$151 -> 0
A31: China | B31: 4.26 | C31: =21.43%+7.14% -> 0.2857 | D31: ='Facility Risk - Apple'!$C31/$C$151 -> 0.28572857 | E31: Includes Taiwan
A32: Colombia | B32: 5.72 | C32: 0 | D32: ='Facility Risk - Apple'!$C32/$C$151 -> 0
A33: Congo, Rep. | B33: 5.65 | C33: 0 | D33: ='Facility Risk - Apple'!$C33/$C$151 -> 0
A34: Costa Rica | B34: 4.23 | C34: 0 | D34: ='Facility Risk - Apple'!$C34/$C$151 -> 0
A35: Cote d'Ivoire | B35: 5.6 | C35: 0 | D35: ='Facility Risk - Apple'!$C35/$C$151 -> 0
A36: Croatia | B36: 4.28 | C36: 0 | D36: ='Facility Risk - Apple'!$C36/$C$151 -> 0
A37: Cyprus | B37: 4.67 | C37: 0 | D37: ='Facility Risk - Apple'!$C37/$C$151 -> 0
A38: Czech Republic | B38: 3.75 | C38: 0 | D38: ='Facility Risk - Apple'!$C38/$C$151 -> 0
A39: Denmark | B39: 3.2 | C39: 0 | D39: ='Facility Risk - Apple'!$C39/$C$151 -> 0
A40: Djibouti | B40: 5.98 | C40: 0 | D40: ='Facility Risk - Apple'!$C40/$C$151 -> 0
A41: Dominican Republic | B41: 4.7 | C41: 0 | D41: ='Facility Risk - Apple'!$C41/$C$151 -> 0
A42: Ecuador | B42: 5.71 | C42: 0 | D42: ='Facility Risk - Apple'!$C42/$C$151 -> 0
A43: Egypt | B43: 5.6 | C43: 0 | D43: ='Facility Risk - Apple'!$C43/$C$151 -> 0
... A150: Zimbabwe | B150: 6.14 | C150: 0 | D150: ='Facility Risk - Apple'!$C150/$C$151 -> 0
A151: TOTAL | C151: =SUM(C4:C150) -> 0.9999 | D151: =SUM(D4:D150) -> 1

Sheet Facility Risk - Meta
A1: Meta
A3: Country of Revenue | B3: Country Geopolitical Risk Index | C3: Percentage of Facility Sites - Raw | D3: Percentage of Facility Sites - Standardized
A4: Albania | B4: 4.37 | C4: 0 | D4: ='Facility Risk - Meta'!$C4/$C$151 -> 0
A5: Algeria | B5: 5.21 | C5: 0 | D5: ='Facility Risk - Meta'!$C5/$C$151 -> 0 | G5: Main Data
A6: Angola | B6: 5.63 | C6: 0 | D6: ='Facility Risk - Meta'!$C6/$C$151 -> 0 | H6: Country | I6: Geopolitical Risk Index | J6: Value
A7: Argentina | B7: 4.36 | C7: 0 | D7: ='Facility Risk - Meta'!$C7/$C$151 -> 0 | G7: Minimum | H7: =INDEX(A4:A150,MATCH(MIN(D4:D150),D4:D150,0)) -> Albania | I7: =INDEX(B4:B150,MATCH(MIN(D4:D150),D4:D150,0)) -> 4.37 | J7: =INDEX(D4:D150,MATCH(MIN(D4:D150),D4:D150,0)) -> 0
A8: Armenia | B8: 4.79 | C8: 0 | D8: ='Facility Risk - Meta'!$C8/$C$151 -> 0 | G8: Maximum | H8: =INDEX(A4:A150,MATCH(MAX(D4:D150),D4:D150,0)) -> United Kingdom | I8: =INDEX(B4:B150,MATCH(MAX(D4:D150),D4:D150,0)) -> 3.32 | J8: =INDEX(D4:D150,MATCH(MAX(D4:D150),D4:D150,0)) -> 1
A9: Australia | B9: 3.22 | C9: 0 | D9: ='Facility Risk - Meta'!$C9/$C$151 -> 0 | G9: Component - Facility Risk | J9: =SUMPRODUCT(B4:B150,D4:D150) -> 3.32
A10: Austria | B10: 3.41 | C10: 0 | D10: ='Facility Risk - Meta'!$C10/$C$151 -> 0
A11: Azerbaijan | B11: 5.21 | C11: 0 | D11: ='Facility Risk - Meta'!$C11/$C$151 -> 0
A12: Bahrain | B12: 4.26 | C12: 0 | D12: ='Facility Risk - Meta'!$C12/$C$151 -> 0
A13: Bangladesh | B13: 6.29 | C13: 0 | D13: ='Facility Risk - Meta'!$C13/$C$151 -> 0
A14: Belarus | B14: 5.45 | C14: 0 | D14: ='Facility Risk - Meta'!$C14/$C$151 -> 0
A15: Belgium | B15: 3.33 | C15: 0 | D15: ='Facility Risk - Meta'!$C15/$C$151 -> 0
A16: Benin | B16: 6 | C16: 0 | D16: ='Facility Risk - Meta'!$C16/$C$151 -> 0
A17: Bhutan | B17: 5.02 | C17: 0 | D17: ='Facility Risk - Meta'!$C17/$C$151 -> 0
A18: Bolivia | B18: 5.41 | C18: 0 | D18: ='Facility Risk - Meta'!$C18/$C$151 -> 0
A19: Bosnia and Herzegovina | B19: 5.34 | C19: 0 | D19: ='Facility Risk - Meta'!$C19/$C$151 -> 0
A20: Botswana | B20: 4.34 | C20: 0 | D20: ='Facility Risk - Meta'!$C20/$C$151 -> 0
A21: Brazil | B21: 5.35 | C21: 0 | D21: ='Facility Risk - Meta'!$C21/$C$151 -> 0
... A30: Chile | B30: 4.36 | C30: 0 | D30: ='Facility Risk - Meta'!$C30/$C$151 -> 0
A31: China | B31: 4.26 | C31: 0 | D31: ='Facility Risk - Meta'!$C31/$C$151 -> 0 | E31: Includes Taiwan
A32: Colombia | B32: 5.72 | C32: 0 | D32: ='Facility Risk - Meta'!$C32/$C$151 -> 0
A33: Congo, Rep. | B33: 5.65 | C33: 0 | D33: ='Facility Risk - Meta'!$C33/$C$151 -> 0
A34: Costa Rica | B34: 4.23 | C34: 0 | D34: ='Facility Risk - Meta'!$C34/$C$151 -> 0
A35: Cote d'Ivoire | B35: 5.6 | C35: 0 | D35: ='Facility Risk - Meta'!$C35/$C$151 -> 0
A36: Croatia | B36: 4.28 | C36: 0 | D36: ='Facility Risk - Meta'!$C36/$C$151 -> 0
A37: Cyprus | B37: 4.67 | C37: 0 | D37: ='Facility Risk - Meta'!$C37/$C$151 -> 0
A38: Czech Republic | B38: 3.75 | C38: 0 | D38: ='Facility Risk - Meta'!$C38/$C$151 -> 0
A39: Denmark | B39: 3.2 | C39: 0 | D39: ='Facility Risk - Meta'!$C39/$C$151 -> 0
A40: Djibouti | B40: 5.98 | C40: 0 | D40: ='Facility Risk - Meta'!$C40/$C$151 -> 0
A41: Dominican Republic | B41: 4.7 | C41: 0 | D41: ='Facility Risk - Meta'!$C41/$C$151 -> 0
A42: Ecuador | B42: 5.71 | C42: 0 | D42: ='Facility Risk - Meta'!$C42/$C$151 -> 0
A43: Egypt | B43: 5.6 | C43: 0 | D43: ='Facility Risk - Meta'!$C43/$C$151 -> 0
... A150: Zimbabwe | B150: 6.14 | C150: 0 | D150: ='Facility Risk - Meta'!$C150/$C$151 -> 0
A151: TOTAL | C151: =SUM(C4:C150) -> 1 | D151: =SUM(D4:D150) -> 1

Sheet Facility Risk - Microsoft
A1: Microsoft
A3: Country of Revenue | B3: Country Geopolitical Risk Index | C3: Percentage of Facility Sites - Raw | D3: Percentage of Facility Sites - Standardized
A4: Albania | B4: 4.37 | C4: 0 | D4: ='Facility Risk - Microsoft'!$C4/$C$151 -> 0
A5: Algeria | B5: 5.21 | C5: 0 | D5: ='Facility Risk - Microsoft'!$C5/$C$151 -> 0 | G5: Main Data
A6: Angola | B6: 5.63 | C6: 0 | D6: ='Facility Risk - Microsoft'!$C6/$C$151 -> 0 | H6: Country | I6: Geopolitical Risk Index | J6: Value
A7: Argentina | B7: 4.36 | C7: 0 | D7: ='Facility Risk - Microsoft'!$C7/$C$151 -> 0 | G7: Minimum | H7: =INDEX(A4:A150,MATCH(MIN(D4:D150),D4:D150,0)) -> Albania | I7: =INDEX(B4:B150,MATCH(MIN(D4:D150),D4:D150,0)) -> 4.37 | J7: =INDEX(D4:D150,MATCH(MIN(D4:D150),D4:D150,0)) -> 0
A8: Armenia | B8: 4.79 | C8: 0 | D8: ='Facility Risk - Microsoft'!$C8/$C$151 -> 0 | G8: Maximum | H8: =INDEX(A4:A150,MATCH(MAX(D4:D150),D4:D150,0)) -> China | I8: =INDEX(B4:B150,MATCH(MAX(D4:D150),D4:D150,0)) -> 4.26 | J8: =INDEX(D4:D150,MATCH(MAX(D4:D150),D4:D150,0)) -> 0.4
A9: Australia | B9: 3.22 | C9: 0 | D9: ='Facility Risk - Microsoft'!$C9/$C$151 -> 0 | G9: Component - Facility Risk | J9: =SUMPRODUCT(B4:B150,D4:D150) -> 4.05
A10: Austria | B10: 3.41 | C10: 0 | D10: ='Facility Risk - Microsoft'!$C10/$C$151 -> 0
A11: Azerbaijan | B11: 5.21 | C11: 0 | D11: ='Facility Risk - Microsoft'!$C11/$C$151 -> 0
A12: Bahrain | B12: 4.26 | C12: 0 | D12: ='Facility Risk - Microsoft'!$C12/$C$151 -> 0
A13: Bangladesh | B13: 6.29 | C13: 0 | D13: ='Facility Risk - Microsoft'!$C13/$C$151 -> 0
A14: Belarus | B14: 5.45 | C14: 0 | D14: ='Facility Risk - Microsoft'!$C14/$C$151 -> 0
A15: Belgium | B15: 3.33 | C15: 0 | D15: ='Facility Risk - Microsoft'!$C15/$C$151 -> 0
A16: Benin | B16: 6 | C16: 0 | D16: ='Facility Risk - Microsoft'!$C16/$C$151 -> 0
A17: Bhutan | B17: 5.02 | C17: 0 | D17: ='Facility Risk - Microsoft'!$C17/$C$151 -> 0
A18: Bolivia | B18: 5.41 | C18: 0 | D18: ='Facility Risk - Microsoft'!$C18/$C$151 -> 0
A19: Bosnia and Herzegovina | B19: 5.34 | C19: 0 | D19: ='Facility Risk - Microsoft'!$C19/$C$151 -> 0
A20: Botswana | B20: 4.34 | C20: 0 | D20: ='Facility Risk - Microsoft'!$C20/$C$151 -> 0
A21: Brazil | B21: 5.35 | C21: 0 | D21: ='Facility Risk - Microsoft'!$C21/$C$151 -> 0
... A30: Chile | B30: 4.36 | C30: 0 | D30: ='Facility Risk - Microsoft'!$C30/$C$151 -> 0
A31: China | B31: 4.26 | C31: =30%+10% -> 0.4 | D31: ='Facility Risk - Microsoft'!$C31/$C$151 -> 0.4 | E31: Includes Taiwan
A32: Colombia | B32: 5.72 | C32: 0 | D32: ='Facility Risk - Microsoft'!$C32/$C$151 -> 0
A33: Congo, Rep. | B33: 5.65 | C33: 0 | D33: ='Facility Risk - Microsoft'!$C33/$C$151 -> 0
A34: Costa Rica | B34: 4.23 | C34: 0 | D34: ='Facility Risk - Microsoft'!$C34/$C$151 -> 0
A35: Cote d'Ivoire | B35: 5.6 | C35: 0 | D35: ='Facility Risk - Microsoft'!$C35/$C$151 -> 0
A36: Croatia | B36: 4.28 | C36: 0 | D36: ='Facility Risk - Microsoft'!$C36/$C$151 -> 0
A37: Cyprus | B37: 4.67 | C37: 0 | D37: ='Facility Risk - Microsoft'!$C37/$C$151 -> 0
A38: Czech Republic | B38: 3.75 | C38: 0 | D38: ='Facility Risk - Microsoft'!$C38/$C$151 -> 0
A39: Denmark | B39: 3.2 | C39: 0 | D39: ='Facility Risk - Microsoft'!$C39/$C$151 -> 0
A40: Djibouti | B40: 5.98 | C40: 0 | D40: ='Facility Risk - Microsoft'!$C40/$C$151 -> 0
A41: Dominican Republic | B41: 4.7 | C41: 0 | D41: ='Facility Risk - Microsoft'!$C41/$C$151 -> 0
A42: Ecuador | B42: 5.71 | C42: 0 | D42: ='Facility Risk - Microsoft'!$C42/$C$151 -> 0
A43: Egypt | B43: 5.6 | C43: 0 | D43: ='Facility Risk - Microsoft'!$C43/$C$151 -> 0
... A150: Zimbabwe | B150: 6.14 | C150: 0 | D150: ='Facility Risk - Microsoft'!$C150/$C$151 -> 0
A151: TOTAL | C151: =SUM(C4:C150) -> 1 | D151: =SUM(D4:D150) -> 1

Sheet Facility Risk - NVIDIA
A1: NVIDIA
A3: Country of Revenue | B3: Country Geopolitical Risk Index | C3: Percentage of Facility Sites - Raw | D3: Percentage of Facility Sites - Standardized
A4: Albania | B4: 4.37 | C4: 0 | D4: ='Facility Risk - NVIDIA'!$C4/$C$151 -> 0
A5: Algeria | B5: 5.21 | C5: 0 | D5: ='Facility Risk - NVIDIA'!$C5/$C$151 -> 0 | G5: Main Data
A6: Angola | B6: 5.63 | C6: 0 | D6: ='Facility Risk - NVIDIA'!$C6/$C$151 -> 0 | H6: Country | I6: Geopolitical Risk Index | J6: Value
A7: Argentina | B7: 4.36 | C7: 0 | D7: ='Facility Risk - NVIDIA'!$C7/$C$151 -> 0 | G7: Minimum | H7: =INDEX(A4:A150,MATCH(MIN(D4:D150),D4:D150,0)) -> Albania | I7: =INDEX(B4:B150,MATCH(MIN(D4:D150),D4:D150,0)) -> 4.37 | J7: =INDEX(D4:D150,MATCH(MIN(D4:D150),D4:D150,0)) -> 0
A8: Armenia | B8: 4.79 | C8: 0 | D8: ='Facility Risk - NVIDIA'!$C8/$C$151 -> 0 | G8: Maximum | H8: =INDEX(A4:A150,MATCH(MAX(D4:D150),D4:D150,0)) -> Israel | I8: =INDEX(B4:B150,MATCH(MAX(D4:D150),D4:D150,0)) -> 4.61 | J8: =INDEX(D4:D150,MATCH(MAX(D4:D150),D4:D150,0)) -> 0.5
A9: Australia | B9: 3.22 | C9: 0 | D9: ='Facility Risk - NVIDIA'!$C9/$C$151 -> 0 | G9: Component - Facility Risk | J9: =SUMPRODUCT(B4:B150,D4:D150) -> 4.4
A10: Austria | B10: 3.41 | C10: 0 | D10: ='Facility Risk - NVIDIA'!$C10/$C$151 -> 0
A11: Azerbaijan | B11: 5.21 | C11: 0 | D11: ='Facility Risk - NVIDIA'!$C11/$C$151 -> 0
A12: Bahrain | B12: 4.26 | C12: 0 | D12: ='Facility Risk - NVIDIA'!$C12/$C$151 -> 0
A13: Bangladesh | B13: 6.29 | C13: 0 | D13: ='Facility Risk - NVIDIA'!$C13/$C$151 -> 0
A14: Belarus | B14: 5.45 | C14: 0 | D14: ='Facility Risk - NVIDIA'!$C14/$C$151 -> 0
A15: Belgium | B15: 3.33 | C15: 0 | D15: ='Facility Risk - NVIDIA'!$C15/$C$151 -> 0
A16: Benin | B16: 6 | C16: 0 | D16: ='Facility Risk - NVIDIA'!$C16/$C$151 -> 0
A17: Bhutan | B17: 5.02 | C17: 0 | D17: ='Facility Risk - NVIDIA'!$C17/$C$151 -> 0
A18: Bolivia | B18: 5.41 | C18: 0 | D18: ='Facility Risk - NVIDIA'!$C18/$C$151 -> 0
A19: Bosnia and Herzegovina | B19: 5.34 | C19: 0 | D19: ='Facility Risk - NVIDIA'!$C19/$C$151 -> 0
A20: Botswana | B20: 4.34 | C20: 0 | D20: ='Facility Risk - NVIDIA'!$C20/$C$151 -> 0
A21: Brazil | B21: 5.35 | C21: 0 | D21: ='Facility Risk - NVIDIA'!$C21/$C$151 -> 0
... A30: Chile | B30: 4.36 | C30: 0 | D30: ='Facility Risk - NVIDIA'!$C30/$C$151 -> 0
A31: China | B31: 4.26 | C31: 0 | D31: ='Facility Risk - NVIDIA'!$C31/$C$151 -> 0 | E31: Includes Taiwan
A32: Colombia | B32: 5.72 | C32: 0 | D32: ='Facility Risk - NVIDIA'!$C32/$C$151 -> 0
A33: Congo, Rep. | B33: 5.65 | C33: 0 | D33: ='Facility Risk - NVIDIA'!$C33/$C$151 -> 0
A34: Costa Rica | B34: 4.23 | C34: 0 | D34: ='Facility Risk - NVIDIA'!$C34/$C$151 -> 0
A35: Cote d'Ivoire | B35: 5.6 | C35: 0 | D35: ='Facility Risk - NVIDIA'!$C35/$C$151 -> 0
A36: Croatia | B36: 4.28 | C36: 0 | D36: ='Facility Risk - NVIDIA'!$C36/$C$151 -> 0
A37: Cyprus | B37: 4.67 | C37: 0 | D37: ='Facility Risk - NVIDIA'!$C37/$C$151 -> 0
A38: Czech Republic | B38: 3.75 | C38: 0 | D38: ='Facility Risk - NVIDIA'!$C38/$C$151 -> 0
A39: Denmark | B39: 3.2 | C39: 0 | D39: ='Facility Risk - NVIDIA'!$C39/$C$151 -> 0
A40: Djibouti | B40: 5.98 | C40: 0 | D40: ='Facility Risk - NVIDIA'!$C40/$C$151 -> 0
A41: Dominican Republic | B41: 4.7 | C41: 0 | D41: ='Facility Risk - NVIDIA'!$C41/$C$151 -> 0
A42: Ecuador | B42: 5.71 | C42: 0 | D42: ='Facility Risk - NVIDIA'!$C42/$C$151 -> 0
A43: Egypt | B43: 5.6 | C43: 0 | D43: ='Facility Risk - NVIDIA'!$C43/$C$151 -> 0
... A150: Zimbabwe | B150: 6.14 | C150: 0 | D150: ='Facility Risk - NVIDIA'!$C150/$C$151 -> 0
A151: TOTAL | C151: =SUM(C4:C150) -> 1 | D151: =SUM(D4:D150) -> 1

Sheet Facility Risk - VW
A1: Volkswagen
A3: Country of Revenue | B3: Country Geopolitical Risk Index | C3: Percentage of Facility Sites - Raw | D3: Percentage of Facility Sites - Standardized
A4: Albania | B4: 4.37 | C4: 0 | D4: ='Facility Risk - VW'!$C4/$C$151 -> 0
A5: Algeria | B5: 5.21 | C5: 0 | D5: ='Facility Risk - VW'!$C5/$C$151 -> 0 | G5: Main Data
A6: Angola | B6: 5.63 | C6: 0 | D6: ='Facility Risk - VW'!$C6/$C$151 -> 0 | H6: Country | I6: Geopolitical Risk Index | J6: Value
A7: Argentina | B7: 4.36 | C7: 0 | D7: ='Facility Risk - VW'!$C7/$C$151 -> 0 | G7: Minimum | H7: =INDEX(A4:A150,MATCH(MIN(D4:D150),D4:D150,0)) -> Albania | I7: =INDEX(B4:B150,MATCH(MIN(D4:D150),D4:D150,0)) -> 4.37 | J7: =INDEX(D4:D150,MATCH(MIN(D4:D150),D4:D150,0)) -> 0
A8: Armenia | B8: 4.79 | C8: 0 | D8: ='Facility Risk - VW'!$C8/$C$151 -> 0 | G8: Maximum | H8: =INDEX(A4:A150,MATCH(MAX(D4:D150),D4:D150,0)) -> China | I8: =INDEX(B4:B150,MATCH(MAX(D4:D150),D4:D150,0)) -> 4.26 | J8: =INDEX(D4:D150,MATCH(MAX(D4:D150),D4:D150,0)) -> 0.18305658
A9: Australia | B9: 3.22 | C9: 0 | D9: ='Facility Risk - VW'!$C9/$C$151 -> 0 | G9: Component - Facility Risk | J9: =SUMPRODUCT(B4:B150,D4:D150) -> 4.1877051
A10: Austria | B10: 3.41 | C10: 0.0149 | D10: ='Facility Risk - VW'!$C10/$C$151 -> 0.014815551
A11: Azerbaijan | B11: 5.21 | C11: 0 | D11: ='Facility Risk - VW'!$C11/$C$151 -> 0
A12: Bahrain | B12: 4.26 | C12: 0 | D12: ='Facility Risk - VW'!$C12/$C$151 -> 0
A13: Bangladesh | B13: 6.29 | C13: 0 | D13: ='Facility Risk - VW'!$C13/$C$151 -> 0
A14: Belarus | B14: 5.45 | C14: 0 | D14: ='Facility Risk - VW'!$C14/$C$151 -> 0
A15: Belgium | B15: 3.33 | C15: 0 | D15: ='Facility Risk - VW'!$C15/$C$151 -> 0
A16: Benin | B16: 6 | C16: 0 | D16: ='Facility Risk - VW'!$C16/$C$151 -> 0
A17: Bhutan | B17: 5.02 | C17: 0 | D17: ='Facility Risk - VW'!$C17/$C$151 -> 0
A18: Bolivia | B18: 5.41 | C18: 0 | D18: ='Facility Risk - VW'!$C18/$C$151 -> 0
A19: Bosnia and Herzegovina | B19: 5.34 | C19: 0.005 | D19: ='Facility Risk - VW'!$C19/$C$151 -> 0.0049716615
A20: Botswana | B20: 4.34 | C20: 0 | D20: ='Facility Risk - VW'!$C20/$C$151 -> 0
A21: Brazil | B21: 5.35 | C21: 0.0498 | D21: ='Facility Risk - VW'!$C21/$C$151 -> 0.049517749
... A30: Chile | B30: 4.36 | C30: 0 | D30: ='Facility Risk - VW'!$C30/$C$151 -> 0
A31: China | B31: 4.26 | C31: =13.93%+4.48% -> 0.1841 | D31: ='Facility Risk - VW'!$C31/$C$151 -> 0.18305658 | E31: Includes Taiwan
A32: Colombia | B32: 5.72 | C32: 0 | D32: ='Facility Risk - VW'!$C32/$C$151 -> 0
A33: Congo, Rep. | B33: 5.65 | C33: 0 | D33: ='Facility Risk - VW'!$C33/$C$151 -> 0
A34: Costa Rica | B34: 4.23 | C34: 0 | D34: ='Facility Risk - VW'!$C34/$C$151 -> 0
A35: Cote d'Ivoire | B35: 5.6 | C35: 0 | D35: ='Facility Risk - VW'!$C35/$C$151 -> 0
A36: Croatia | B36: 4.28 | C36: 0 | D36: ='Facility Risk - VW'!$C36/$C$151 -> 0
A37: Cyprus | B37: 4.67 | C37: 0 | D37: ='Facility Risk - VW'!$C37/$C$151 -> 0
A38: Czech Republic | B38: 3.75 | C38: 0.0299 | D38: ='Facility Risk - VW'!$C38/$C$151 -> 0.029730536
A39: Denmark | B39: 3.2 | C39: 0.0199 | D39: ='Facility Risk - VW'!$C39/$C$151 -> 0.019787213
A40: Djibouti | B40: 5.98 | C40: 0 | D40: ='Facility Risk - VW'!$C40/$C$151 -> 0
A41: Dominican Republic | B41: 4.7 | C41: 0 | D41: ='Facility Risk - VW'!$C41/$C$151 -> 0
A42: Ecuador | B42: 5.71 | C42: 0 | D42: ='Facility Risk - VW'!$C42/$C$151 -> 0
A43: Egypt | B43: 5.6 | C43: 0 | D43: ='Facility Risk - VW'!$C43/$C$151 -> 0
... A150: Zimbabwe | B150: 6.14 | C150: 0 | D150: ='Facility Risk - VW'!$C150/$C$151 -> 0
A151: TOTAL | C151: =SUM(C4:C150) -> 1.0057 | D151: =SUM(D4:D150) -> 1

Sheet Facility Risk - Reliance
A1: Reliance Industries
A3: Country of Revenue | B3: Country Geopolitical Risk Index | C3: Percentage of Facility Sites - Raw | D3: Percentage of Facility Sites - Standardized
A4: Albania | B4: 4.37 | C4: 0 | D4: ='Facility Risk - Reliance'!$C4/$C$151 -> 0
A5: Algeria | B5: 5.21 | C5: 0 | D5: ='Facility Risk - Reliance'!$C5/$C$151 -> 0 | G5: Main Data
A6: Angola | B6: 5.63 | C6: 0 | D6: ='Facility Risk - Reliance'!$C6/$C$151 -> 0 | H6: Country | I6: Geopolitical Risk Index | J6: Value
A7: Argentina | B7: 4.36 | C7: 0 | D7: ='Facility Risk - Reliance'!$C7/$C$151 -> 0 | G7: Minimum | H7: =INDEX(A4:A150,MATCH(MIN(D4:D150),D4:D150,0)) -> Albania | I7: =INDEX(B4:B150,MATCH(MIN(D4:D150),D4:D150,0)) -> 4.37 | J7: =INDEX(D4:D150,MATCH(MIN(D4:D150),D4:D150,0)) -> 0
A8: Armenia | B8: 4.79 | C8: 0 | D8: ='Facility Risk - Reliance'!$C8/$C$151 -> 0 | G8: Maximum | H8: =INDEX(A4:A150,MATCH(MAX(D4:D150),D4:D150,0)) -> India | I8: =INDEX(B4:B150,MATCH(MAX(D4:D150),D4:D150,0)) -> 5.07 | J8: =INDEX(D4:D150,MATCH(MAX(D4:D150),D4:D150,0)) -> 1
A9: Australia | B9: 3.22 | C9: 0 | D9: ='Facility Risk - Reliance'!$C9/$C$151 -> 0 | G9: Component - Facility Risk | J9: =SUMPRODUCT(B4:B150,D4:D150) -> 5.07
A10: Austria | B10: 3.41 | C10: 0 | D10: ='Facility Risk - Reliance'!$C10/$C$151 -> 0
A11: Azerbaijan | B11: 5.21 | C11: 0 | D11: ='Facility Risk - Reliance'!$C11/$C$151 -> 0
A12: Bahrain | B12: 4.26 | C12: 0 | D12: ='Facility Risk - Reliance'!$C12/$C$151 -> 0
A13: Bangladesh | B13: 6.29 | C13: 0 | D13: ='Facility Risk - Reliance'!$C13/$C$151 -> 0
A14: Belarus | B14: 5.45 | C14: 0 | D14: ='Facility Risk - Reliance'!$C14/$C$151 -> 0
A15: Belgium | B15: 3.33 | C15: 0 | D15: ='Facility Risk - Reliance'!$C15/$C$151 -> 0
A16: Benin | B16: 6 | C16: 0 | D16: ='Facility Risk - Reliance'!$C16/$C$151 -> 0
A17: Bhutan | B17: 5.02 | C17: 0 | D17: ='Facility Risk - Reliance'!$C17/$C$151 -> 0
A18: Bolivia | B18: 5.41 | C18: 0 | D18: ='Facility Risk - Reliance'!$C18/$C$151 -> 0
A19: Bosnia and Herzegovina | B19: 5.34 | C19: 0 | D19: ='Facility Risk - Reliance'!$C19/$C$151 -> 0
A20: Botswana | B20: 4.34 | C20: 0 | D20: ='Facility Risk - Reliance'!$C20/$C$151 -> 0
A21: Brazil | B21: 5.35 | C21: 0 | D21: ='Facility Risk - Reliance'!$C21/$C$151 -> 0
... A30: Chile | B30: 4.36 | C30: 0 | D30: ='Facility Risk - Reliance'!$C30/$C$151 -> 0
A31: China | B31: 4.26 | C31: 0 | D31: ='Facility Risk - Reliance'!$C31/$C$151 -> 0 | E31: Includes Taiwan
A32: Colombia | B32: 5.72 | C32: 0 | D32: ='Facility Risk - Reliance'!$C32/$C$151 -> 0
A33: Congo, Rep. | B33: 5.65 | C33: 0 | D33: ='Facility Risk - Reliance'!$C33/$C$151 -> 0
A34: Costa Rica | B34: 4.23 | C34: 0 | D34: ='Facility Risk - Reliance'!$C34/$C$151 -> 0
A35: Cote d'Ivoire | B35: 5.6 | C35: 0 | D35: ='Facility Risk - Reliance'!$C35/$C$151 -> 0
A36: Croatia | B36: 4.28 | C36: 0 | D36: ='Facility Risk - Reliance'!$C36/$C$151 -> 0
A37: Cyprus | B37: 4.67 | C37: 0 | D37: ='Facility Risk - Reliance'!$C37/$C$151 -> 0
A38: Czech Republic | B38: 3.75 | C38: 0 | D38: ='Facility Risk - Reliance'!$C38/$C$151 -> 0
A39: Denmark | B39: 3.2 | C39: 0 | D39: ='Facility Risk - Reliance'!$C39/$C$151 -> 0
A40: Djibouti | B40: 5.98 | C40: 0 | D40: ='Facility Risk - Reliance'!$C40/$C$151 -> 0
A41: Dominican Republic | B41: 4.7 | C41: 0 | D41: ='Facility Risk - Reliance'!$C41/$C$151 -> 0
A42: Ecuador | B42: 5.71 | C42: 0 | D42: ='Facility Risk - Reliance'!$C42/$C$151 -> 0
A43: Egypt | B43: 5.6 | C43: 0 | D43: ='Facility Risk - Reliance'!$C43/$C$151 -> 0
... A150: Zimbabwe | B150: 6.14 | C150: 0 | D150: ='Facility Risk - Reliance'!$C150/$C$151 -> 0
A151: TOTAL | C151: =SUM(C4:C150) -> 1 | D151: =SUM(D4:D150) -> 1

Sheet Facility Risk - Total en
A1: Total Energies
A3: Country of Revenue | B3: Country Geopolitical Risk Index | C3: Percentage of Facility Sites - Raw | D3: Percentage of Facility Sites - Standardized
A4: Albania | B4: 4.37 | C4: 0 | D4: ='Facility Risk - Total en'!$C4/$C$151 -> 0
A5: Algeria | B5: 5.21 | C5: 0.0162 | D5: ='Facility Risk - Total en'!$C5/$C$151 -> 0.016317486 | G5: Main Data
A6: Angola | B6: 5.63 | C6: 0.0043 | D6: ='Facility Risk - Total en'!$C6/$C$151 -> 0.0043311845 | H6: Country | I6: Geopolitical Risk Index | J6: Value
A7: Argentina | B7: 4.36 | C7: 0.0172 | D7: ='Facility Risk - Total en'!$C7/$C$151 -> 0.017324738 | G7: Minimum | H7: =INDEX(A4:A150,MATCH(MIN(D4:D150),D4:D150,0)) -> Albania | I7: =INDEX(B4:B150,MATCH(MIN(D4:D150),D4:D150,0)) -> 4.37 | J7: =INDEX(D4:D150,MATCH(MIN(D4:D150),D4:D150,0)) -> 0
A8: Armenia | B8: 4.79 | C8: 0 | D8: ='Facility Risk - Total en'!$C8/$C$151 -> 0 | G8: Maximum | H8: =INDEX(A4:A150,MATCH(MAX(D4:D150),D4:D150,0)) -> United States | I8: =INDEX(B4:B150,MATCH(MAX(D4:D150),D4:D150,0)) -> 4.19 | J8: =INDEX(D4:D150,MATCH(MAX(D4:D150),D4:D150,0)) -> 0.12157534
A9: Australia | B9: 3.22 | C9: 0.0273 | D9: ='Facility Risk - Total en'!$C9/$C$151 -> 0.027497985 | G9: Component - Facility Risk | J9: =SUMPRODUCT(B4:B150,D4:D150) -> 4.2137973
A10: Austria | B10: 3.41 | C10: 0 | D10: ='Facility Risk - Total en'!$C10/$C$151 -> 0
A11: Azerbaijan | B11: 5.21 | C11: 0 | D11: ='Facility Risk - Total en'!$C11/$C$151 -> 0
A12: Bahrain | B12: 4.26 | C12: 0 | D12: ='Facility Risk - Total en'!$C12/$C$151 -> 0
A13: Bangladesh | B13: 6.29 | C13: 0 | D13: ='Facility Risk - Total en'!$C13/$C$151 -> 0
A14: Belarus | B14: 5.45 | C14: 0 | D14: ='Facility Risk - Total en'!$C14/$C$151 -> 0
A15: Belgium | B15: 3.33 | C15: 0.0086 | D15: ='Facility Risk - Total en'!$C15/$C$151 -> 0.0086623691
A16: Benin | B16: 6 | C16: 0 | D16: ='Facility Risk - Total en'!$C16/$C$151 -> 0
A17: Bhutan | B17: 5.02 | C17: 0 | D17: ='Facility Risk - Total en'!$C17/$C$151 -> 0
A18: Bolivia | B18: 5.41 | C18: 0 | D18: ='Facility Risk - Total en'!$C18/$C$151 -> 0
A19: Bosnia and Herzegovina | B19: 5.34 | C19: 0 | D19: ='Facility Risk - Total en'!$C19/$C$151 -> 0
A20: Botswana | B20: 4.34 | C20: 0.0014 | D20: ='Facility Risk - Total en'!$C20/$C$151 -> 0.0014101531
A21: Brazil | B21: 5.35 | C21: 0.0345 | D21: ='Facility Risk - Total en'!$C21/$C$151 -> 0.034750201
... A30: Chile | B30: 4.36 | C30: 0.0129 | D30: ='Facility Risk - Total en'!$C30/$C$151 -> 0.012993554
A31: China | B31: 4.26 | C31: =1.01%+1.01% -> 0.0202 | D31: ='Facility Risk - Total en'!$C31/$C$151 -> 0.020346495 | E31: Includes Taiwan
A32: Colombia | B32: 5.72 | C32: 0.0057 | D32: ='Facility Risk - Total en'!$C32/$C$151 -> 0.0057413376
A33: Congo, Rep. | B33: 5.65 | C33: 0 | D33: ='Facility Risk - Total en'!$C33/$C$151 -> 0
A34: Costa Rica | B34: 4.23 | C34: 0 | D34: ='Facility Risk - Total en'!$C34/$C$151 -> 0
A35: Cote d'Ivoire | B35: 5.6 | C35: 0 | D35: ='Facility Risk - Total en'!$C35/$C$151 -> 0
A36: Croatia | B36: 4.28 | C36: 0.0043 | D36: ='Facility Risk - Total en'!$C36/$C$151 -> 0.0043311845
A37: Cyprus | B37: 4.67 | C37: 0.0029 | D37: ='Facility Risk - Total en'!$C37/$C$151 -> 0.0029210314
A38: Czech Republic | B38: 3.75 | C38: 0.0043 | D38: ='Facility Risk - Total en'!$C38/$C$151 -> 0.0043311845
A39: Denmark | B39: 3.2 | C39: 0.0172 | D39: ='Facility Risk - Total en'!$C39/$C$151 -> 0.017324738
A40: Djibouti | B40: 5.98 | C40: 0 | D40: ='Facility Risk - Total en'!$C40/$C$151 -> 0
A41: Dominican Republic | B41: 4.7 | C41: 0 | D41: ='Facility Risk - Total en'!$C41/$C$151 -> 0
A42: Ecuador | B42: 5.71 | C42: 0.0072 | D42: ='Facility Risk - Total en'!$C42/$C$151 -> 0.007252216
A43: Egypt | B43: 5.6 | C43: 0.0101 | D43: ='Facility Risk - Total en'!$C43/$C$151 -> 0.010173247
... A150: Zimbabwe | B150: 6.14 | C150: 0.0029 | D150: ='Facility Risk - Total en'!$C150/$C$151 -> 0.0029210314
A151: TOTAL | C151: =SUM(C4:C150) -> 0.9928 | D151: =SUM(D4:D150) -> 1

Sheet Facility Risk - JP Morgan
A1: JP Morgan
A3: Country of Revenue | B3: Country Geopolitical Risk Index | C3: Percentage of Facility Sites - Raw | D3: Percentage of Facility Sites - Standardized
A4: Albania | B4: 4.37 | C4: 0 | D4: 0
A5: Algeria | B5: 5.21 | C5: 0 | D5: 0 | G5: Main Data
A6: Angola | B6: 5.63 | C6: 0 | D6: 0 | H6: Country | I6: Geopolitical Risk Index | J6: Value
A7: Argentina | B7: 4.36 | C7: 0 | D7: 0 | G7: Minimum | H7: =INDEX(A4:A150,MATCH(MIN(D4:D150),D4:D150,0)) -> Albania | I7: =INDEX(B4:B150,MATCH(MIN(D4:D150),D4:D150,0)) -> 4.37 | J7: =INDEX(D4:D150,MATCH(MIN(D4:D150),D4:D150,0)) -> 0
A8: Armenia | B8: 4.79 | C8: 0 | D8: 0 | G8: Maximum | H8: =INDEX(A4:A150,MATCH(MAX(D4:D150),D4:D150,0)) -> Albania | I8: =INDEX(B4:B150,MATCH(MAX(D4:D150),D4:D150,0)) -> 4.37 | J8: =INDEX(D4:D150,MATCH(MAX(D4:D150),D4:D150,0)) -> 0
A9: Australia | B9: 3.22 | C9: 0 | D9: 0 | G9: Component - Facility Risk | J9: =SUMPRODUCT(B4:B150,D4:D150) -> 0
A10: Austria | B10: 3.41 | C10: 0 | D10: 0
A11: Azerbaijan | B11: 5.21 | C11: 0 | D11: 0
A12: Bahrain | B12: 4.26 | C12: 0 | D12: 0
A13: Bangladesh | B13: 6.29 | C13: 0 | D13: 0
A14: Belarus | B14: 5.45 | C14: 0 | D14: 0
A15: Belgium | B15: 3.33 | C15: 0 | D15: 0
A16: Benin | B16: 6 | C16: 0 | D16: 0
A17: Bhutan | B17: 5.02 | C17: 0 | D17: 0
A18: Bolivia | B18: 5.41 | C18: 0 | D18: 0
A19: Bosnia and Herzegovina | B19: 5.34 | C19: 0 | D19: 0
A20: Botswana | B20: 4.34 | C20: 0 | D20: 0
A21: Brazil | B21: 5.35 | C21: 0 | D21: 0
... A30: Chile | B30: 4.36 | C30: 0 | D30: 0
A31: China | B31: 4.26 | C31: 0 | D31: 0 | E31: Includes Taiwan
A32: Colombia | B32: 5.72 | C32: 0 | D32: 0
A33: Congo, Rep. | B33: 5.65 | C33: 0 | D33: 0
A34: Costa Rica | B34: 4.23 | C34: 0 | D34: 0
A35: Cote d'Ivoire | B35: 5.6 | C35: 0 | D35: 0
A36: Croatia | B36: 4.28 | C36: 0 | D36: 0
A37: Cyprus | B37: 4.67 | C37: 0 | D37: 0
A38: Czech Republic | B38: 3.75 | C38: 0 | D38: 0
A39: Denmark | B39: 3.2 | C39: 0 | D39: 0
A40: Djibouti | B40: 5.98 | C40: 0 | D40: 0
A41: Dominican Republic | B41: 4.7 | C41: 0 | D41: 0
A42: Ecuador | B42: 5.71 | C42: 0 | D42: 0
A43: Egypt | B43: 5.6 | C43: 0 | D43: 0
... A150: Zimbabwe | B150: 6.14 | C150: 0 | D150: 0
A151: TOTAL | C151: =SUM(C4:C150) -> 0 | D151: =SUM(D4:D150) -> 0

Sheet Facility Risk - P&G
A1: Procter & Gamble
A3: Country of Revenue | B3: Country Geopolitical Risk Index | C3: Percentage of Facility Sites - Raw | D3: Percentage of Facility Sites - Standardized
A4: Albania | B4: 4.37 | C4: 0 | D4: ='Facility Risk - P&G'!$C4/$C$151 -> 0
A5: Algeria | B5: 5.21 | C5: 0 | D5: ='Facility Risk - P&G'!$C5/$C$151 -> 0 | G5: Main Data
A6: Angola | B6: 5.63 | C6: 0 | D6: ='Facility Risk - P&G'!$C6/$C$151 -> 0 | H6: Country | I6: Geopolitical Risk Index | J6: Value
A7: Argentina | B7: 4.36 | C7: 0 | D7: ='Facility Risk - P&G'!$C7/$C$151 -> 0 | G7: Minimum | H7: =INDEX(A4:A150,MATCH(MIN(D4:D150),D4:D150,0)) -> Albania | I7: =INDEX(B4:B150,MATCH(MIN(D4:D150),D4:D150,0)) -> 4.37 | J7: =INDEX(D4:D150,MATCH(MIN(D4:D150),D4:D150,0)) -> 0
A8: Armenia | B8: 4.79 | C8: 0 | D8: ='Facility Risk - P&G'!$C8/$C$151 -> 0 | G8: Maximum | H8: =INDEX(A4:A150,MATCH(MAX(D4:D150),D4:D150,0)) -> United States | I8: =INDEX(B4:B150,MATCH(MAX(D4:D150),D4:D150,0)) -> 4.19 | J8: =INDEX(D4:D150,MATCH(MAX(D4:D150),D4:D150,0)) -> 0.25914634
A9: Australia | B9: 3.22 | C9: 0.012 | D9: ='Facility Risk - P&G'!$C9/$C$151 -> 0.011801731 | G9: Component - Facility Risk | J9: =SUMPRODUCT(B4:B150,D4:D150) -> 4.3110533
A10: Austria | B10: 3.41 | C10: 0.006 | D10: ='Facility Risk - P&G'!$C10/$C$151 -> 0.0059008655
A11: Azerbaijan | B11: 5.21 | C11: 0 | D11: ='Facility Risk - P&G'!$C11/$C$151 -> 0
A12: Bahrain | B12: 4.26 | C12: 0 | D12: ='Facility Risk - P&G'!$C12/$C$151 -> 0
A13: Bangladesh | B13: 6.29 | C13: 0 | D13: ='Facility Risk - P&G'!$C13/$C$151 -> 0
A14: Belarus | B14: 5.45 | C14: 0 | D14: ='Facility Risk - P&G'!$C14/$C$151 -> 0
A15: Belgium | B15: 3.33 | C15: 0.024 | D15: ='Facility Risk - P&G'!$C15/$C$151 -> 0.023603462
A16: Benin | B16: 6 | C16: 0 | D16: ='Facility Risk - P&G'!$C16/$C$151 -> 0
A17: Bhutan | B17: 5.02 | C17: 0 | D17: ='Facility Risk - P&G'!$C17/$C$151 -> 0
A18: Bolivia | B18: 5.41 | C18: 0 | D18: ='Facility Risk - P&G'!$C18/$C$151 -> 0
A19: Bosnia and Herzegovina | B19: 5.34 | C19: 0 | D19: ='Facility Risk - P&G'!$C19/$C$151 -> 0
A20: Botswana | B20: 4.34 | C20: 0 | D20: ='Facility Risk - P&G'!$C20/$C$151 -> 0
A21: Brazil | B21: 5.35 | C21: 0.0299 | D21: ='Facility Risk - P&G'!$C21/$C$151 -> 0.02940598
... A30: Chile | B30: 4.36 | C30: 0.006 | D30: ='Facility Risk - P&G'!$C30/$C$151 -> 0.0059008655
A31: China | B31: 4.26 | C31: 0.0599 | D31: ='Facility Risk - P&G'!$C31/$C$151 -> 0.058910307 | E31: Includes Taiwan
A32: Colombia | B32: 5.72 | C32: 0.012 | D32: ='Facility Risk - P&G'!$C32/$C$151 -> 0.011801731
A33: Congo, Rep. | B33: 5.65 | C33: 0 | D33: ='Facility Risk - P&G'!$C33/$C$151 -> 0
A34: Costa Rica | B34: 4.23 | C34: 0 | D34: ='Facility Risk - P&G'!$C34/$C$151 -> 0
A35: Cote d'Ivoire | B35: 5.6 | C35: 0 | D35: ='Facility Risk - P&G'!$C35/$C$151 -> 0
A36: Croatia | B36: 4.28 | C36: 0 | D36: ='Facility Risk - P&G'!$C36/$C$151 -> 0
A37: Cyprus | B37: 4.67 | C37: 0 | D37: ='Facility Risk - P&G'!$C37/$C$151 -> 0
A38: Czech Republic | B38: 3.75 | C38: 0.006 | D38: ='Facility Risk - P&G'!$C38/$C$151 -> 0.0059008655
A39: Denmark | B39: 3.2 | C39: 0 | D39: ='Facility Risk - P&G'!$C39/$C$151 -> 0
A40: Djibouti | B40: 5.98 | C40: 0 | D40: ='Facility Risk - P&G'!$C40/$C$151 -> 0
A41: Dominican Republic | B41: 4.7 | C41: 0 | D41: ='Facility Risk - P&G'!$C41/$C$151 -> 0
A42: Ecuador | B42: 5.71 | C42: 0 | D42: ='Facility Risk - P&G'!$C42/$C$151 -> 0
A43: Egypt | B43: 5.6 | C43: 0.012 | D43: ='Facility Risk - P&G'!$C43/$C$151 -> 0.011801731
... A150: Zimbabwe | B150: 6.14 | C150: 0 | D150: ='Facility Risk - P&G'!$C150/$C$151 -> 0
A151: TOTAL | C151: =SUM(C4:C150) -> 1.0168 | D151: =SUM(D4:D150) -> 1

Sheet Facility Risk - Samsung
A1: Samsung
A3: Country of Revenue | B3: Country Geopolitical Risk Index | C3: Percentage of Facility Sites - Raw | D3: Percentage of Facility Sites - Standardized
A4: Albania | B4: 4.37 | C4: 0 | D4: ='Facility Risk - Samsung'!$C4/$C$151 -> 0
A5: Algeria | B5: 5.21 | C5: 0 | D5: ='Facility Risk - Samsung'!$C5/$C$151 -> 0 | G5: Main Data
A6: Angola | B6: 5.63 | C6: 0 | D6: ='Facility Risk - Samsung'!$C6/$C$151 -> 0 | H6: Country | I6: Geopolitical Risk Index | J6: Value
A7: Argentina | B7: 4.36 | C7: 0 | D7: ='Facility Risk - Samsung'!$C7/$C$151 -> 0 | G7: Minimum | H7: =INDEX(A4:A150,MATCH(MIN(D4:D150),D4:D150,0)) -> Albania | I7: =INDEX(B4:B150,MATCH(MIN(D4:D150),D4:D150,0)) -> 4.37 | J7: =INDEX(D4:D150,MATCH(MIN(D4:D150),D4:D150,0)) -> 0
A8: Armenia | B8: 4.79 | C8: 0 | D8: ='Facility Risk - Samsung'!$C8/$C$151 -> 0 | G8: Maximum | H8: =INDEX(A4:A150,MATCH(MAX(D4:D150),D4:D150,0)) -> South Korea | I8: =INDEX(B4:B150,MATCH(MAX(D4:D150),D4:D150,0)) -> 3.57 | J8: =INDEX(D4:D150,MATCH(MAX(D4:D150),D4:D150,0)) -> 0.5160862
A9: Australia | B9: 3.22 | C9: 0 | D9: ='Facility Risk - Samsung'!$C9/$C$151 -> 0 | G9: Component - Facility Risk | J9: =SUMPRODUCT(B4:B150,D4:D150) -> 4.0176366
A10: Austria | B10: 3.41 | C10: 0 | D10: ='Facility Risk - Samsung'!$C10/$C$151 -> 0
A11: Azerbaijan | B11: 5.21 | C11: 0 | D11: ='Facility Risk - Samsung'!$C11/$C$151 -> 0
A12: Bahrain | B12: 4.26 | C12: 0 | D12: ='Facility Risk - Samsung'!$C12/$C$151 -> 0
A13: Bangladesh | B13: 6.29 | C13: 0 | D13: ='Facility Risk - Samsung'!$C13/$C$151 -> 0
A14: Belarus | B14: 5.45 | C14: 0 | D14: ='Facility Risk - Samsung'!$C14/$C$151 -> 0
A15: Belgium | B15: 3.33 | C15: 0 | D15: ='Facility Risk - Samsung'!$C15/$C$151 -> 0
A16: Benin | B16: 6 | C16: 0 | D16: ='Facility Risk - Samsung'!$C16/$C$151 -> 0
A17: Bhutan | B17: 5.02 | C17: 0 | D17: ='Facility Risk - Samsung'!$C17/$C$151 -> 0
A18: Bolivia | B18: 5.41 | C18: 0 | D18: ='Facility Risk - Samsung'!$C18/$C$151 -> 0
A19: Bosnia and Herzegovina | B19: 5.34 | C19: 0 | D19: ='Facility Risk - Samsung'!$C19/$C$151 -> 0
A20: Botswana | B20: 4.34 | C20: 0 | D20: ='Facility Risk - Samsung'!$C20/$C$151 -> 0
A21: Brazil | B21: 5.35 | C21: 0.0211 | D21: ='Facility Risk - Samsung'!$C21/$C$151 -> 0.021550403
... A30: Chile | B30: 4.36 | C30: 0 | D30: ='Facility Risk - Samsung'!$C30/$C$151 -> 0
A31: China | B31: 4.26 | C31: 0.1263 | D31: ='Facility Risk - Samsung'!$C31/$C$151 -> 0.12899602 | E31: Includes Taiwan
A32: Colombia | B32: 5.72 | C32: 0 | D32: ='Facility Risk - Samsung'!$C32/$C$151 -> 0
A33: Congo, Rep. | B33: 5.65 | C33: 0 | D33: ='Facility Risk - Samsung'!$C33/$C$151 -> 0
A34: Costa Rica | B34: 4.23 | C34: 0 | D34: ='Facility Risk - Samsung'!$C34/$C$151 -> 0
A35: Cote d'Ivoire | B35: 5.6 | C35: 0 | D35: ='Facility Risk - Samsung'!$C35/$C$151 -> 0
A36: Croatia | B36: 4.28 | C36: 0 | D36: ='Facility Risk - Samsung'!$C36/$C$151 -> 0
A37: Cyprus | B37: 4.67 | C37: 0 | D37: ='Facility Risk - Samsung'!$C37/$C$151 -> 0
A38: Czech Republic | B38: 3.75 | C38: 0 | D38: ='Facility Risk - Samsung'!$C38/$C$151 -> 0
A39: Denmark | B39: 3.2 | C39: 0 | D39: ='Facility Risk - Samsung'!$C39/$C$151 -> 0
A40: Djibouti | B40: 5.98 | C40: 0 | D40: ='Facility Risk - Samsung'!$C40/$C$151 -> 0
A41: Dominican Republic | B41: 4.7 | C41: 0 | D41: ='Facility Risk - Samsung'!$C41/$C$151 -> 0
A42: Ecuador | B42: 5.71 | C42: 0 | D42: ='Facility Risk - Samsung'!$C42/$C$151 -> 0
A43: Egypt | B43: 5.6 | C43: 0.0105 | D43: ='Facility Risk - Samsung'!$C43/$C$151 -> 0.010724134
... A150: Zimbabwe | B150: 6.14 | C150: 0 | D150: ='Facility Risk - Samsung'!$C150/$C$151 -> 0
A151: TOTAL | C151: =SUM(C4:C150) -> 0.9791 | D151: =SUM(D4:D150) -> 1

Sheet Facility Risk - Tencent
A1: Tencent
A3: Country of Revenue | B3: Country Geopolitical Risk Index | C3: Percentage of Facility Sites - Raw | D3: Percentage of Facility Sites - Standardized
A4: Albania | B4: 4.37 | C4: 0 | D4: 0
A5: Algeria | B5: 5.21 | C5: 0 | D5: 0 | G5: Main Data
A6: Angola | B6: 5.63 | C6: 0 | D6: 0 | H6: Country | I6: Geopolitical Risk Index | J6: Value
A7: Argentina | B7: 4.36 | C7: 0 | D7: 0 | G7: Minimum | H7: =INDEX(A4:A150,MATCH(MIN(D4:D150),D4:D150,0)) -> Albania | I7: =INDEX(B4:B150,MATCH(MIN(D4:D150),D4:D150,0)) -> 4.37 | J7: =INDEX(D4:D150,MATCH(MIN(D4:D150),D4:D150,0)) -> 0
A8: Armenia | B8: 4.79 | C8: 0 | D8: 0 | G8: Maximum | H8: =INDEX(A4:A150,MATCH(MAX(D4:D150),D4:D150,0)) -> Albania | I8: =INDEX(B4:B150,MATCH(MAX(D4:D150),D4:D150,0)) -> 4.37 | J8: =INDEX(D4:D150,MATCH(MAX(D4:D150),D4:D150,0)) -> 0
A9: Australia | B9: 3.22 | C9: 0 | D9: 0 | G9: Component - Facility Risk | J9: =SUMPRODUCT(B4:B150,D4:D150) -> 0
A10: Austria | B10: 3.41 | C10: 0 | D10: 0
A11: Azerbaijan | B11: 5.21 | C11: 0 | D11: 0
A12: Bahrain | B12: 4.26 | C12: 0 | D12: 0
A13: Bangladesh | B13: 6.29 | C13: 0 | D13: 0
A14: Belarus | B14: 5.45 | C14: 0 | D14: 0
A15: Belgium | B15: 3.33 | C15: 0 | D15: 0
A16: Benin | B16: 6 | C16: 0 | D16: 0
A17: Bhutan | B17: 5.02 | C17: 0 | D17: 0
A18: Bolivia | B18: 5.41 | C18: 0 | D18: 0
A19: Bosnia and Herzegovina | B19: 5.34 | C19: 0 | D19: 0
A20: Botswana | B20: 4.34 | C20: 0 | D20: 0
A21: Brazil | B21: 5.35 | C21: 0 | D21: 0
... A30: Chile | B30: 4.36 | C30: 0 | D30: 0
A31: China | B31: 4.26 | C31: 0 | D31: 0 | E31: Includes Taiwan
A32: Colombia | B32: 5.72 | C32: 0 | D32: 0
A33: Congo, Rep. | B33: 5.65 | C33: 0 | D33: 0
A34: Costa Rica | B34: 4.23 | C34: 0 | D34: 0
A35: Cote d'Ivoire | B35: 5.6 | C35: 0 | D35: 0
A36: Croatia | B36: 4.28 | C36: 0 | D36: 0
A37: Cyprus | B37: 4.67 | C37: 0 | D37: 0
A38: Czech Republic | B38: 3.75 | C38: 0 | D38: 0
A39: Denmark | B39: 3.2 | C39: 0 | D39: 0
A40: Djibouti | B40: 5.98 | C40: 0 | D40: 0
A41: Dominican Republic | B41: 4.7 | C41: 0 | D41: 0
A42: Ecuador | B42: 5.71 | C42: 0 | D42: 0
A43: Egypt | B43: 5.6 | C43: 0 | D43: 0
... A150: Zimbabwe | B150: 6.14 | C150: 0 | D150: 0
A151: TOTAL | C151: =SUM(C4:C150) -> 0 | D151: =SUM(D4:D150) -> 0

Sheet Facility Risk - ASML
A1: ASML
A3: Country of Revenue | B3: Country Geopolitical Risk Index | C3: Percentage of Facility Sites - Raw | D3: Percentage of Facility Sites - Standardized
A4: Albania | B4: 4.37 | C4: 0 | D4: ='Facility Risk - ASML'!$C4/$C$151 -> 0
A5: Algeria | B5: 5.21 | C5: 0 | D5: ='Facility Risk - ASML'!$C5/$C$151 -> 0 | G5: Main Data
A6: Angola | B6: 5.63 | C6: 0 | D6: ='Facility Risk - ASML'!$C6/$C$151 -> 0 | H6: Country | I6: Geopolitical Risk Index | J6: Value
A7: Argentina | B7: 4.36 | C7: 0 | D7: ='Facility Risk - ASML'!$C7/$C$151 -> 0 | G7: Minimum | H7: =INDEX(A4:A150,MATCH(MIN(D4:D150),D4:D150,0)) -> Albania | I7: =INDEX(B4:B150,MATCH(MIN(D4:D150),D4:D150,0)) -> 4.37 | J7: =INDEX(D4:D150,MATCH(MIN(D4:D150),D4:D150,0)) -> 0
A8: Armenia | B8: 4.79 | C8: 0 | D8: ='Facility Risk - ASML'!$C8/$C$151 -> 0 | G8: Maximum | H8: =INDEX(A4:A150,MATCH(MAX(D4:D150),D4:D150,0)) -> China | I8: =INDEX(B4:B150,MATCH(MAX(D4:D150),D4:D150,0)) -> 4.26 | J8: =INDEX(D4:D150,MATCH(MAX(D4:D150),D4:D150,0)) -> 0.3685
A9: Australia | B9: 3.22 | C9: 0 | D9: ='Facility Risk - ASML'!$C9/$C$151 -> 0 | G9: Component - Facility Risk | J9: =SUMPRODUCT(B4:B150,D4:D150) -> 3.996919
A10: Austria | B10: 3.41 | C10: 0 | D10: ='Facility Risk - ASML'!$C10/$C$151 -> 0
A11: Azerbaijan | B11: 5.21 | C11: 0 | D11: ='Facility Risk - ASML'!$C11/$C$151 -> 0
A12: Bahrain | B12: 4.26 | C12: 0 | D12: ='Facility Risk - ASML'!$C12/$C$151 -> 0
A13: Bangladesh | B13: 6.29 | C13: 0 | D13: ='Facility Risk - ASML'!$C13/$C$151 -> 0
A14: Belarus | B14: 5.45 | C14: 0 | D14: ='Facility Risk - ASML'!$C14/$C$151 -> 0
A15: Belgium | B15: 3.33 | C15: 0 | D15: ='Facility Risk - ASML'!$C15/$C$151 -> 0
A16: Benin | B16: 6 | C16: 0 | D16: ='Facility Risk - ASML'!$C16/$C$151 -> 0
A17: Bhutan | B17: 5.02 | C17: 0 | D17: ='Facility Risk - ASML'!$C17/$C$151 -> 0
A18: Bolivia | B18: 5.41 | C18: 0 | D18: ='Facility Risk - ASML'!$C18/$C$151 -> 0
A19: Bosnia and Herzegovina | B19: 5.34 | C19: 0 | D19: ='Facility Risk - ASML'!$C19/$C$151 -> 0
A20: Botswana | B20: 4.34 | C20: 0 | D20: ='Facility Risk - ASML'!$C20/$C$151 -> 0
A21: Brazil | B21: 5.35 | C21: 0 | D21: ='Facility Risk - ASML'!$C21/$C$151 -> 0
... A30: Chile | B30: 4.36 | C30: 0 | D30: ='Facility Risk - ASML'!$C30/$C$151 -> 0
A31: China | B31: 4.26 | C31: =10.53%+26.32% -> 0.3685 | D31: ='Facility Risk - ASML'!$C31/$C$151 -> 0.3685 | E31: Includes Taiwan
A32: Colombia | B32: 5.72 | C32: 0 | D32: ='Facility Risk - ASML'!$C32/$C$151 -> 0
A33: Congo, Rep. | B33: 5.65 | C33: 0 | D33: ='Facility Risk - ASML'!$C33/$C$151 -> 0
A34: Costa Rica | B34: 4.23 | C34: 0 | D34: ='Facility Risk - ASML'!$C34/$C$151 -> 0
A35: Cote d'Ivoire | B35: 5.6 | C35: 0 | D35: ='Facility Risk - ASML'!$C35/$C$151 -> 0
A36: Croatia | B36: 4.28 | C36: 0 | D36: ='Facility Risk - ASML'!$C36/$C$151 -> 0
A37: Cyprus | B37: 4.67 | C37: 0 | D37: ='Facility Risk - ASML'!$C37/$C$151 -> 0
A38: Czech Republic | B38: 3.75 | C38: 0 | D38: ='Facility Risk - ASML'!$C38/$C$151 -> 0
A39: Denmark | B39: 3.2 | C39: 0 | D39: ='Facility Risk - ASML'!$C39/$C$151 -> 0
A40: Djibouti | B40: 5.98 | C40: 0 | D40: ='Facility Risk - ASML'!$C40/$C$151 -> 0
A41: Dominican Republic | B41: 4.7 | C41: 0 | D41: ='Facility Risk - ASML'!$C41/$C$151 -> 0
A42: Ecuador | B42: 5.71 | C42: 0 | D42: ='Facility Risk - ASML'!$C42/$C$151 -> 0
A43: Egypt | B43: 5.6 | C43: 0 | D43: ='Facility Risk - ASML'!$C43/$C$151 -> 0
... A150: Zimbabwe | B150: 6.14 | C150: 0 | D150: ='Facility Risk - ASML'!$C150/$C$151 -> 0
A151: TOTAL | C151: =SUM(C4:C150) -> 1 | D151: =SUM(D4:D150) -> 1

Sheet Facility Risk - TSMC
A1: TSMC
A3: Country of Revenue | B3: Country Geopolitical Risk Index | C3: Percentage of Facility Sites - Raw | D3: Percentage of Facility Sites - Standardized
A4: Albania | B4: 4.37 | C4: 0 | D4: ='Facility Risk - TSMC'!$C4/$C$151 -> 0
A5: Algeria | B5: 5.21 | C5: 0 | D5: ='Facility Risk - TSMC'!$C5/$C$151 -> 0 | G5: Main Data
A6: Angola | B6: 5.63 | C6: 0 | D6: ='Facility Risk - TSMC'!$C6/$C$151 -> 0 | H6: Country | I6: Geopolitical Risk Index | J6: Value
A7: Argentina | B7: 4.36 | C7: 0 | D7: ='Facility Risk - TSMC'!$C7/$C$151 -> 0 | G7: Minimum | H7: =INDEX(A4:A150,MATCH(MIN(D4:D150),D4:D150,0)) -> Albania | I7: =INDEX(B4:B150,MATCH(MIN(D4:D150),D4:D150,0)) -> 4.37 | J7: =INDEX(D4:D150,MATCH(MIN(D4:D150),D4:D150,0)) -> 0
A8: Armenia | B8: 4.79 | C8: 0 | D8: ='Facility Risk - TSMC'!$C8/$C$151 -> 0 | G8: Maximum | H8: =INDEX(A4:A150,MATCH(MAX(D4:D150),D4:D150,0)) -> China | I8: =INDEX(B4:B150,MATCH(MAX(D4:D150),D4:D150,0)) -> 4.26 | J8: =INDEX(D4:D150,MATCH(MAX(D4:D150),D4:D150,0)) -> 0.75672433
A9: Australia | B9: 3.22 | C9: 0 | D9: ='Facility Risk - TSMC'!$C9/$C$151 -> 0 | G9: Component - Facility Risk | J9: =SUMPRODUCT(B4:B150,D4:D150) -> 4.1356334
A10: Austria | B10: 3.41 | C10: 0 | D10: ='Facility Risk - TSMC'!$C10/$C$151 -> 0
A11: Azerbaijan | B11: 5.21 | C11: 0 | D11: ='Facility Risk - TSMC'!$C11/$C$151 -> 0
A12: Bahrain | B12: 4.26 | C12: 0 | D12: ='Facility Risk - TSMC'!$C12/$C$151 -> 0
A13: Bangladesh | B13: 6.29 | C13: 0 | D13: ='Facility Risk - TSMC'!$C13/$C$151 -> 0
A14: Belarus | B14: 5.45 | C14: 0 | D14: ='Facility Risk - TSMC'!$C14/$C$151 -> 0
A15: Belgium | B15: 3.33 | C15: 0 | D15: ='Facility Risk - TSMC'!$C15/$C$151 -> 0
A16: Benin | B16: 6 | C16: 0 | D16: ='Facility Risk - TSMC'!$C16/$C$151 -> 0
A17: Bhutan | B17: 5.02 | C17: 0 | D17: ='Facility Risk - TSMC'!$C17/$C$151 -> 0
A18: Bolivia | B18: 5.41 | C18: 0 | D18: ='Facility Risk - TSMC'!$C18/$C$151 -> 0
A19: Bosnia and Herzegovina | B19: 5.34 | C19: 0 | D19: ='Facility Risk - TSMC'!$C19/$C$151 -> 0
A20: Botswana | B20: 4.34 | C20: 0 | D20: ='Facility Risk - TSMC'!$C20/$C$151 -> 0
A21: Brazil | B21: 5.35 | C21: 0 | D21: ='Facility Risk - TSMC'!$C21/$C$151 -> 0
... A30: Chile | B30: 4.36 | C30: 0 | D30: ='Facility Risk - TSMC'!$C30/$C$151 -> 0
A31: China | B31: 4.26 | C31: =5.41%+70.27% -> 0.7568 | D31: ='Facility Risk - TSMC'!$C31/$C$151 -> 0.75672433 | E31: Includes Taiwan
A32: Colombia | B32: 5.72 | C32: 0 | D32: ='Facility Risk - TSMC'!$C32/$C$151 -> 0
A33: Congo, Rep. | B33: 5.65 | C33: 0 | D33: ='Facility Risk - TSMC'!$C33/$C$151 -> 0
A34: Costa Rica | B34: 4.23 | C34: 0 | D34: ='Facility Risk - TSMC'!$C34/$C$151 -> 0
A35: Cote d'Ivoire | B35: 5.6 | C35: 0 | D35: ='Facility Risk - TSMC'!$C35/$C$151 -> 0
A36: Croatia | B36: 4.28 | C36: 0 | D36: ='Facility Risk - TSMC'!$C36/$C$151 -> 0
A37: Cyprus | B37: 4.67 | C37: 0 | D37: ='Facility Risk - TSMC'!$C37/$C$151 -> 0
A38: Czech Republic | B38: 3.75 | C38: 0 | D38: ='Facility Risk - TSMC'!$C38/$C$151 -> 0
A39: Denmark | B39: 3.2 | C39: 0 | D39: ='Facility Risk - TSMC'!$C39/$C$151 -> 0
A40: Djibouti | B40: 5.98 | C40: 0 | D40: ='Facility Risk - TSMC'!$C40/$C$151 -> 0
A41: Dominican Republic | B41: 4.7 | C41: 0 | D41: ='Facility Risk - TSMC'!$C41/$C$151 -> 0
A42: Ecuador | B42: 5.71 | C42: 0 | D42: ='Facility Risk - TSMC'!$C42/$C$151 -> 0
A43: Egypt | B43: 5.6 | C43: 0 | D43: ='Facility Risk - TSMC'!$C43/$C$151 -> 0
... A150: Zimbabwe | B150: 6.14 | C150: 0 | D150: ='Facility Risk - TSMC'!$C150/$C$151 -> 0
A151: TOTAL | C151: =SUM(C4:C150) -> 1.0001 | D151: =SUM(D4:D150) -> 1

Sheet Facility Risk - Sony
A1: Sony
A3: Country of Revenue | B3: Country Geopolitical Risk Index | C3: Percentage of Facility Sites - Raw | D3: Percentage of Facility Sites - Standardized
A4: Albania | B4: 4.37 | C4: 0 | D4: ='Facility Risk - Sony'!$C4/$C$151 -> 0
A5: Algeria | B5: 5.21 | C5: 0 | D5: ='Facility Risk - Sony'!$C5/$C$151 -> 0 | G5: Main Data
A6: Angola | B6: 5.63 | C6: 0 | D6: ='Facility Risk - Sony'!$C6/$C$151 -> 0 | H6: Country | I6: Geopolitical Risk Index | J6: Value
A7: Argentina | B7: 4.36 | C7: 0 | D7: ='Facility Risk - Sony'!$C7/$C$151 -> 0 | G7: Minimum | H7: =INDEX(A4:A150,MATCH(MIN(D4:D150),D4:D150,0)) -> Albania | I7: =INDEX(B4:B150,MATCH(MIN(D4:D150),D4:D150,0)) -> 4.37 | J7: =INDEX(D4:D150,MATCH(MIN(D4:D150),D4:D150,0)) -> 0
A8: Armenia | B8: 4.79 | C8: 0 | D8: ='Facility Risk - Sony'!$C8/$C$151 -> 0 | G8: Maximum | H8: =INDEX(A4:A150,MATCH(MAX(D4:D150),D4:D150,0)) -> Japan | I8: =INDEX(B4:B150,MATCH(MAX(D4:D150),D4:D150,0)) -> 3.38 | J8: =INDEX(D4:D150,MATCH(MAX(D4:D150),D4:D150,0)) -> 0.62966297
A9: Australia | B9: 3.22 | C9: 0 | D9: ='Facility Risk - Sony'!$C9/$C$151 -> 0 | G9: Component - Facility Risk | J9: =SUMPRODUCT(B4:B150,D4:D150) -> 3.6262216
A10: Austria | B10: 3.41 | C10: 0 | D10: ='Facility Risk - Sony'!$C10/$C$151 -> 0
A11: Azerbaijan | B11: 5.21 | C11: 0 | D11: ='Facility Risk - Sony'!$C11/$C$151 -> 0
A12: Bahrain | B12: 4.26 | C12: 0 | D12: ='Facility Risk - Sony'!$C12/$C$151 -> 0
A13: Bangladesh | B13: 6.29 | C13: 0 | D13: ='Facility Risk - Sony'!$C13/$C$151 -> 0
A14: Belarus | B14: 5.45 | C14: 0 | D14: ='Facility Risk - Sony'!$C14/$C$151 -> 0
A15: Belgium | B15: 3.33 | C15: 0 | D15: ='Facility Risk - Sony'!$C15/$C$151 -> 0
A16: Benin | B16: 6 | C16: 0 | D16: ='Facility Risk - Sony'!$C16/$C$151 -> 0
A17: Bhutan | B17: 5.02 | C17: 0 | D17: ='Facility Risk - Sony'!$C17/$C$151 -> 0
A18: Bolivia | B18: 5.41 | C18: 0 | D18: ='Facility Risk - Sony'!$C18/$C$151 -> 0
A19: Bosnia and Herzegovina | B19: 5.34 | C19: 0 | D19: ='Facility Risk - Sony'!$C19/$C$151 -> 0
A20: Botswana | B20: 4.34 | C20: 0 | D20: ='Facility Risk - Sony'!$C20/$C$151 -> 0
A21: Brazil | B21: 5.35 | C21: 0 | D21: ='Facility Risk - Sony'!$C21/$C$151 -> 0
... A30: Chile | B30: 4.36 | C30: 0 | D30: ='Facility Risk - Sony'!$C30/$C$151 -> 0
A31: China | B31: 4.26 | C31: 0.1111 | D31: ='Facility Risk - Sony'!$C31/$C$151 -> 0.11111111 | E31: Includes Taiwan
A32: Colombia | B32: 5.72 | C32: 0 | D32: ='Facility Risk - Sony'!$C32/$C$151 -> 0
A33: Congo, Rep. | B33: 5.65 | C33: 0 | D33: ='Facility Risk - Sony'!$C33/$C$151 -> 0
A34: Costa Rica | B34: 4.23 | C34: 0 | D34: ='Facility Risk - Sony'!$C34/$C$151 -> 0
A35: Cote d'Ivoire | B35: 5.6 | C35: 0 | D35: ='Facility Risk - Sony'!$C35/$C$151 -> 0
A36: Croatia | B36: 4.28 | C36: 0 | D36: ='Facility Risk - Sony'!$C36/$C$151 -> 0
A37: Cyprus | B37: 4.67 | C37: 0 | D37: ='Facility Risk - Sony'!$C37/$C$151 -> 0
A38: Czech Republic | B38: 3.75 | C38: 0 | D38: ='Facility Risk - Sony'!$C38/$C$151 -> 0
A39: Denmark | B39: 3.2 | C39: 0 | D39: ='Facility Risk - Sony'!$C39/$C$151 -> 0
A40: Djibouti | B40: 5.98 | C40: 0 | D40: ='Facility Risk - Sony'!$C40/$C$151 -> 0
A41: Dominican Republic | B41: 4.7 | C41: 0 | D41: ='Facility Risk - Sony'!$C41/$C$151 -> 0
A42: Ecuador | B42: 5.71 | C42: 0 | D42: ='Facility Risk - Sony'!$C42/$C$151 -> 0
A43: Egypt | B43: 5.6 | C43: 0 | D43: ='Facility Risk - Sony'!$C43/$C$151 -> 0
... A150: Zimbabwe | B150: 6.14 | C150: 0 | D150: ='Facility Risk - Sony'!$C150/$C$151 -> 0
A151: TOTAL | C151: =SUM(C4:C150) -> 0.9999 | D151: =SUM(D4:D150) -> 1

Sheet Facility Risk - Eli Lilly
A1: Eli Lilly
A3: Country of Revenue | B3: Country Geopolitical Risk Index | C3: Percentage of Facility Sites - Raw | D3: Percentage of Facility Sites - Standardized
A4: Albania | B4: 4.37 | C4: 0 | D4: ='Facility Risk - Eli Lilly'!$C4/$C$151 -> 0
A5: Algeria | B5: 5.21 | C5: 0 | D5: ='Facility Risk - Eli Lilly'!$C5/$C$151 -> 0 | G5: Main Data
A6: Angola | B6: 5.63 | C6: 0 | D6: ='Facility Risk - Eli Lilly'!$C6/$C$151 -> 0 | H6: Country | I6: Geopolitical Risk Index | J6: Value
A7: Argentina | B7: 4.36 | C7: 0 | D7: ='Facility Risk - Eli Lilly'!$C7/$C$151 -> 0 | G7: Minimum | H7: =INDEX(A4:A150,MATCH(MIN(D4:D150),D4:D150,0)) -> Albania | I7: =INDEX(B4:B150,MATCH(MIN(D4:D150),D4:D150,0)) -> 4.37 | J7: =INDEX(D4:D150,MATCH(MIN(D4:D150),D4:D150,0)) -> 0
A8: Armenia | B8: 4.79 | C8: 0 | D8: ='Facility Risk - Eli Lilly'!$C8/$C$151 -> 0 | G8: Maximum | H8: =INDEX(A4:A150,MATCH(MAX(D4:D150),D4:D150,0)) -> United States | I8: =INDEX(B4:B150,MATCH(MAX(D4:D150),D4:D150,0)) -> 4.19 | J8: =INDEX(D4:D150,MATCH(MAX(D4:D150),D4:D150,0)) -> 0.41666667
A9: Australia | B9: 3.22 | C9: 0.04 | D9: ='Facility Risk - Eli Lilly'!$C9/$C$151 -> 0.041666667 | G9: Component - Facility Risk | J9: =SUMPRODUCT(B4:B150,D4:D150) -> 3.9675
A10: Austria | B10: 3.41 | C10: 0 | D10: ='Facility Risk - Eli Lilly'!$C10/$C$151 -> 0
A11: Azerbaijan | B11: 5.21 | C11: 0 | D11: ='Facility Risk - Eli Lilly'!$C11/$C$151 -> 0
A12: Bahrain | B12: 4.26 | C12: 0 | D12: ='Facility Risk - Eli Lilly'!$C12/$C$151 -> 0
A13: Bangladesh | B13: 6.29 | C13: 0 | D13: ='Facility Risk - Eli Lilly'!$C13/$C$151 -> 0
A14: Belarus | B14: 5.45 | C14: 0 | D14: ='Facility Risk - Eli Lilly'!$C14/$C$151 -> 0
A15: Belgium | B15: 3.33 | C15: 0 | D15: ='Facility Risk - Eli Lilly'!$C15/$C$151 -> 0
A16: Benin | B16: 6 | C16: 0 | D16: ='Facility Risk - Eli Lilly'!$C16/$C$151 -> 0
A17: Bhutan | B17: 5.02 | C17: 0 | D17: ='Facility Risk - Eli Lilly'!$C17/$C$151 -> 0
A18: Bolivia | B18: 5.41 | C18: 0 | D18: ='Facility Risk - Eli Lilly'!$C18/$C$151 -> 0
A19: Bosnia and Herzegovina | B19: 5.34 | C19: 0 | D19: ='Facility Risk - Eli Lilly'!$C19/$C$151 -> 0
A20: Botswana | B20: 4.34 | C20: 0 | D20: ='Facility Risk - Eli Lilly'!$C20/$C$151 -> 0
A21: Brazil | B21: 5.35 | C21: 0 | D21: ='Facility Risk - Eli Lilly'!$C21/$C$151 -> 0
... A30: Chile | B30: 4.36 | C30: 0 | D30: ='Facility Risk - Eli Lilly'!$C30/$C$151 -> 0
A31: China | B31: 4.26 | C31: 0.04 | D31: ='Facility Risk - Eli Lilly'!$C31/$C$151 -> 0.041666667 | E31: Includes Taiwan
A32: Colombia | B32: 5.72 | C32: 0 | D32: ='Facility Risk - Eli Lilly'!$C32/$C$151 -> 0
A33: Congo, Rep. | B33: 5.65 | C33: 0 | D33: ='Facility Risk - Eli Lilly'!$C33/$C$151 -> 0
A34: Costa Rica | B34: 4.23 | C34: 0 | D34: ='Facility Risk - Eli Lilly'!$C34/$C$151 -> 0
A35: Cote d'Ivoire | B35: 5.6 | C35: 0 | D35: ='Facility Risk - Eli Lilly'!$C35/$C$151 -> 0
A36: Croatia | B36: 4.28 | C36: 0 | D36: ='Facility Risk - Eli Lilly'!$C36/$C$151 -> 0
A37: Cyprus | B37: 4.67 | C37: 0 | D37: ='Facility Risk - Eli Lilly'!$C37/$C$151 -> 0
A38: Czech Republic | B38: 3.75 | C38: 0 | D38: ='Facility Risk - Eli Lilly'!$C38/$C$151 -> 0
A39: Denmark | B39: 3.2 | C39: 0 | D39: ='Facility Risk - Eli Lilly'!$C39/$C$151 -> 0
A40: Djibouti | B40: 5.98 | C40: 0 | D40: ='Facility Risk - Eli Lilly'!$C40/$C$151 -> 0
A41: Dominican Republic | B41: 4.7 | C41: 0 | D41: ='Facility Risk - Eli Lilly'!$C41/$C$151 -> 0
A42: Ecuador | B42: 5.71 | C42: 0 | D42: ='Facility Risk - Eli Lilly'!$C42/$C$151 -> 0
A43: Egypt | B43: 5.6 | C43: 0.04 | D43: ='Facility Risk - Eli Lilly'!$C43/$C$151 -> 0.041666667
... A150: Zimbabwe | B150: 6.14 | C150: 0 | D150: ='Facility Risk - Eli Lilly'!$C150/$C$151 -> 0
A151: TOTAL | C151: =SUM(C4:C150) -> 0.96 | D151: =SUM(D4:D150) -> 1

Sheet Facility Risk - L'Oreal
A1: L'Oreal
A3: Country of Revenue | B3: Country Geopolitical Risk Index | C3: Percentage of Facility Sites - Raw | D3: Percentage of Facility Sites - Standardized
A4: Albania | B4: 4.37 | C4: 0 | D4: ='Facility Risk - L''Oreal'!$C4/$C$151 -> 0
A5: Algeria | B5: 5.21 | C5: 0 | D5: ='Facility Risk - L''Oreal'!$C5/$C$151 -> 0 | G5: Main Data
A6: Angola | B6: 5.63 | C6: 0 | D6: ='Facility Risk - L''Oreal'!$C6/$C$151 -> 0 | H6: Country | I6: Geopolitical Risk Index | J6: Value
A7: Argentina | B7: 4.36 | C7: 0 | D7: ='Facility Risk - L''Oreal'!$C7/$C$151 -> 0 | G7: Minimum | H7: =INDEX(A4:A150,MATCH(MIN(D4:D150),D4:D150,0)) -> Albania | I7: =INDEX(B4:B150,MATCH(MIN(D4:D150),D4:D150,0)) -> 4.37 | J7: =INDEX(D4:D150,MATCH(MIN(D4:D150),D4:D150,0)) -> 0
A8: Armenia | B8: 4.79 | C8: 0 | D8: ='Facility Risk - L''Oreal'!$C8/$C$151 -> 0 | G8: Maximum | H8: =INDEX(A4:A150,MATCH(MAX(D4:D150),D4:D150,0)) -> United States | I8: =INDEX(B4:B150,MATCH(MAX(D4:D150),D4:D150,0)) -> 4.19 | J8: =INDEX(D4:D150,MATCH(MAX(D4:D150),D4:D150,0)) -> 0.25259896
A9: Australia | B9: 3.22 | C9: 0.011 | D9: ='Facility Risk - L''Oreal'!$C9/$C$151 -> 0.010995602 | G9: Component - Facility Risk | J9: =SUMPRODUCT(B4:B150,D4:D150) -> 4.1109066
A10: Austria | B10: 3.41 | C10: 0 | D10: ='Facility Risk - L''Oreal'!$C10/$C$151 -> 0
A11: Azerbaijan | B11: 5.21 | C11: 0 | D11: ='Facility Risk - L''Oreal'!$C11/$C$151 -> 0
A12: Bahrain | B12: 4.26 | C12: 0 | D12: ='Facility Risk - L''Oreal'!$C12/$C$151 -> 0
A13: Bangladesh | B13: 6.29 | C13: 0 | D13: ='Facility Risk - L''Oreal'!$C13/$C$151 -> 0
A14: Belarus | B14: 5.45 | C14: 0 | D14: ='Facility Risk - L''Oreal'!$C14/$C$151 -> 0
A15: Belgium | B15: 3.33 | C15: 0.011 | D15: ='Facility Risk - L''Oreal'!$C15/$C$151 -> 0.010995602
A16: Benin | B16: 6 | C16: 0 | D16: ='Facility Risk - L''Oreal'!$C16/$C$151 -> 0
A17: Bhutan | B17: 5.02 | C17: 0 | D17: ='Facility Risk - L''Oreal'!$C17/$C$151 -> 0
A18: Bolivia | B18: 5.41 | C18: 0 | D18: ='Facility Risk - L''Oreal'!$C18/$C$151 -> 0
A19: Bosnia and Herzegovina | B19: 5.34 | C19: 0 | D19: ='Facility Risk - L''Oreal'!$C19/$C$151 -> 0
A20: Botswana | B20: 4.34 | C20: 0 | D20: ='Facility Risk - L''Oreal'!$C20/$C$151 -> 0
A21: Brazil | B21: 5.35 | C21: 0.033 | D21: ='Facility Risk - L''Oreal'!$C21/$C$151 -> 0.032986805
... A30: Chile | B30: 4.36 | C30: 0 | D30: ='Facility Risk - L''Oreal'!$C30/$C$151 -> 0
A31: China | B31: 4.26 | C31: 0.044 | D31: ='Facility Risk - L''Oreal'!$C31/$C$151 -> 0.043982407 | E31: Includes Taiwan
A32: Colombia | B32: 5.72 | C32: 0.011 | D32: ='Facility Risk - L''Oreal'!$C32/$C$151 -> 0.010995602
A33: Congo, Rep. | B33: 5.65 | C33: 0 | D33: ='Facility Risk - L''Oreal'!$C33/$C$151 -> 0
A34: Costa Rica | B34: 4.23 | C34: 0 | D34: ='Facility Risk - L''Oreal'!$C34/$C$151 -> 0
A35: Cote d'Ivoire | B35: 5.6 | C35: 0 | D35: ='Facility Risk - L''Oreal'!$C35/$C$151 -> 0
A36: Croatia | B36: 4.28 | C36: 0 | D36: ='Facility Risk - L''Oreal'!$C36/$C$151 -> 0
A37: Cyprus | B37: 4.67 | C37: 0 | D37: ='Facility Risk - L''Oreal'!$C37/$C$151 -> 0
A38: Czech Republic | B38: 3.75 | C38: 0 | D38: ='Facility Risk - L''Oreal'!$C38/$C$151 -> 0
A39: Denmark | B39: 3.2 | C39: 0.011 | D39: ='Facility Risk - L''Oreal'!$C39/$C$151 -> 0.010995602
A40: Djibouti | B40: 5.98 | C40: 0 | D40: ='Facility Risk - L''Oreal'!$C40/$C$151 -> 0
A41: Dominican Republic | B41: 4.7 | C41: 0 | D41: ='Facility Risk - L''Oreal'!$C41/$C$151 -> 0
A42: Ecuador | B42: 5.71 | C42: 0 | D42: ='Facility Risk - L''Oreal'!$C42/$C$151 -> 0
A43: Egypt | B43: 5.6 | C43: 0.011 | D43: ='Facility Risk - L''Oreal'!$C43/$C$151 -> 0.010995602
... A150: Zimbabwe | B150: 6.14 | C150: 0 | D150: ='Facility Risk - L''Oreal'!$C150/$C$151 -> 0
A151: TOTAL | C151: =SUM(C4:C150) -> 1.0004 | D151: =SUM(D4:D150) -> 1

Sheet Facility Risk - Eni
A1: ENI
A3: Country of Revenue | B3: Country Geopolitical Risk Index | C3: Percentage of Facility Sites - Raw | D3: Percentage of Facility Sites - Standardized
A4: Albania | B4: 4.37 | C4: 0 | D4: 0
A5: Algeria | B5: 5.21 | C5: 0 | D5: 0 | G5: Main Data
A6: Angola | B6: 5.63 | C6: 0 | D6: 0 | H6: Country | I6: Geopolitical Risk Index | J6: Value
A7: Argentina | B7: 4.36 | C7: 0 | D7: 0 | G7: Minimum | H7: =INDEX(A4:A150,MATCH(MIN(D4:D150),D4:D150,0)) -> Albania | I7: =INDEX(B4:B150,MATCH(MIN(D4:D150),D4:D150,0)) -> 4.37 | J7: =INDEX(D4:D150,MATCH(MIN(D4:D150),D4:D150,0)) -> 0
A8: Armenia | B8: 4.79 | C8: 0 | D8: 0 | G8: Maximum | H8: =INDEX(A4:A150,MATCH(MAX(D4:D150),D4:D150,0)) -> Albania | I8: =INDEX(B4:B150,MATCH(MAX(D4:D150),D4:D150,0)) -> 4.37 | J8: =INDEX(D4:D150,MATCH(MAX(D4:D150),D4:D150,0)) -> 0
A9: Australia | B9: 3.22 | C9: 0 | D9: 0 | G9: Component - Facility Risk | J9: =SUMPRODUCT(B4:B150,D4:D150) -> 0
A10: Austria | B10: 3.41 | C10: 0 | D10: 0
A11: Azerbaijan | B11: 5.21 | C11: 0 | D11: 0
A12: Bahrain | B12: 4.26 | C12: 0 | D12: 0
A13: Bangladesh | B13: 6.29 | C13: 0 | D13: 0
A14: Belarus | B14: 5.45 | C14: 0 | D14: 0
A15: Belgium | B15: 3.33 | C15: 0 | D15: 0
A16: Benin | B16: 6 | C16: 0 | D16: 0
A17: Bhutan | B17: 5.02 | C17: 0 | D17: 0
A18: Bolivia | B18: 5.41 | C18: 0 | D18: 0
A19: Bosnia and Herzegovina | B19: 5.34 | C19: 0 | D19: 0
A20: Botswana | B20: 4.34 | C20: 0 | D20: 0
A21: Brazil | B21: 5.35 | C21: 0 | D21: 0
... A30: Chile | B30: 4.36 | C30: 0 | D30: 0
A31: China | B31: 4.26 | C31: 0 | D31: 0 | E31: Includes Taiwan
A32: Colombia | B32: 5.72 | C32: 0 | D32: 0
A33: Congo, Rep. | B33: 5.65 | C33: 0 | D33: 0
A34: Costa Rica | B34: 4.23 | C34: 0 | D34: 0
A35: Cote d'Ivoire | B35: 5.6 | C35: 0 | D35: 0
A36: Croatia | B36: 4.28 | C36: 0 | D36: 0
A37: Cyprus | B37: 4.67 | C37: 0 | D37: 0
A38: Czech Republic | B38: 3.75 | C38: 0 | D38: 0
A39: Denmark | B39: 3.2 | C39: 0 | D39: 0
A40: Djibouti | B40: 5.98 | C40: 0 | D40: 0
A41: Dominican Republic | B41: 4.7 | C41: 0 | D41: 0
A42: Ecuador | B42: 5.71 | C42: 0 | D42: 0
A43: Egypt | B43: 5.6 | C43: 0 | D43: 0
... A150: Zimbabwe | B150: 6.14 | C150: 0 | D150: 0
A151: TOTAL | C151: =SUM(C4:C150) -> 0 | D151: =SUM(D4:D150) -> 0

Sheet Facility Risk - Amazon
A1: Amazon
