Workbook

Sheet Introduction
A1: Corporate Geopolitical Risk Index - INTRODUCTION
A3: This Excel file contains the empirical measurement of the Corporate Geopolitical Risk Index (CGRI), starting from the previously developed Geopolitical Risk Index (GPR), defined at the country level.
A5: Specifically, the file is unpacked into 8 different sheets (excluding this "Introduction" section), where a final template of the index is represented, as well as all its 7 single company-level measures
A7: [Below you find the explanation and measurement process for each element of the CGRI]
A9: Final Template - It aggregates the results of the single measures into a score from 1 to 10
A10: 1) Main Components
A13: 1 - HQ Country Risk - GPR of the company's HQ country - Weight assigned: 15%
A16: 2 - Revenue Exposure - GPR of each country of revenue, weighted by the associated percentage of company's revenue in the country - Weight assigned: 25%
A19: 3 - Supply Chain Exposure - GPR of each country of the company's supply chain, weighted by the associated percentage of company's supply intensity in the country - Weight assigned: 25%
A22: 4 - Facility Sites Location Risk - GPR of each country where at least a facility is located, weighted by the associated percentage of company's facility sites in the country - Weight assigned: 15%
A24: 5 - Financial Exposure - Net Debt / EBITDA, which defines the credit vulnerability of the company - Weight Assigned: 20%
A27: 2) Multipliers
... A32: 2 - Volatility Index Multiplier - Volatility index for the S&P 500 companies, averaged over the year. The measure is one plus the percentage difference between the current VIX average year index and the historical average of the last 25 years.

Sheet Final Template - 2024
B1: Main Components | G1: Multipliers
A2: Company Name | B2: HQ Country Risk | C2: Revenue Exposure | D2: Supply Chain Exposure | E2: Facility Sites Location Risk | F2: Financial Exposure | G2: Sector Risk | H2: Volatility Risk | I2: Final Risk Index
A3: Allianz | B3: ='HQ Country Risk'!D2 -> 3.42 | C3: ='Revenue Exposure'!B2 -> 3.3948195 | D3: ='Supply Chain Exposure'!B2 -> 3.6559789 | E3: ='Facility Sites Location Risk'!B2 -> 0 | F3: ='Financial Exposure'!C2 -> 5 | G3: ='Sector Risk Multiplier'!H5 -> 1.1 | H3: ='Volatility Risk Multiplier'!$H$29 -> 0.93482826 | I3: =(0.15*Tabella6[[#This Row],[HQ Country Risk]]+0.25*Tabella6[[#This Row],[Revenue Exposure]]+0.25*Tabella6[[#This Row],[Supply Chain Exposure]]+0.15*Tabella6[[#This Row],[Facility Sites Location Risk]]+0.2*Tabella6[[#This Row],[Financial Exposure]]) *Tabella6[[#This Row],[Sector Risk]]*Tabella6[[#This Row],[Volatility Risk]] -> 3.3684382
A4: Amazon | B4: ='HQ Country Risk'!D3 -> 4.19 | C4: ='Revenue Exposure'!B3 -> 6.0438158 | D4: ='Supply Chain Exposure'!B3 -> 4.2231945 | E4: ='Facility Sites Location Risk'!B3 -> 4.0365251 | F4: ='Financial Exposure'!C3 -> 4 | G4: ='Sector Risk Multiplier'!H6 -> 1 | H4: ='Volatility Risk Multiplier'!$H$29 -> 0.93482826 | I4: =(0.15*Tabella6[[#This Row],[HQ Country Risk]]+0.25*Tabella6[[#This Row],[Revenue Exposure]]+0.25*Tabella6[[#This Row],[Supply Chain Exposure]]+0.15*Tabella6[[#This Row],[Facility Sites Location Risk]]+0.2*Tabella6[[#This Row],[Financial Exposure]]) *Tabella6[[#This Row],[Sector Risk]]*Tabella6[[#This Row],[Volatility Risk]] -> 4.3008937
A5: Apple | B5: ='HQ Country Risk'!D4 -> 4.19 | C5: ='Revenue Exposure'!B4 -> 4.1049432 | D5: ='Supply Chain Exposure'!B4 -> 3.9761125 | E5: ='Facility Sites Location Risk'!B4 -> 4.2493629 | F5: ='Financial Exposure'!C4 -> 3 | G5: ='Sector Risk Multiplier'!H7 -> 1.1 | H5: ='Volatility Risk Multiplier'!$H$29 -> 0.93482826 | I5: =(0.15*Tabella6[[#This Row],[HQ Country Risk]]+0.25*Tabella6[[#This Row],[Revenue Exposure]]+0.25*Tabella6[[#This Row],[Supply Chain Exposure]]+0.15*Tabella6[[#This Row],[Facility Sites Location Risk]]+0.2*Tabella6[[#This Row],[Financial Exposure]]) *Tabella6[[#This Row],[Sector Risk]]*Tabella6[[#This Row],[Volatility Risk]] -> 3.99619
A6: ASML | B6: ='HQ Country Risk'!D5 -> 3.59 | C6: ='Revenue Exposure'!B5 -> 4.4116251 | D6: ='Supply Chain Exposure'!B5 -> 3.8700067 | E6: ='Facility Sites Location Risk'!B5 -> 3.996919 | F6: ='Financial Exposure'!C5 -> 3 | G6: ='Sector Risk Multiplier'!H8 -> 1.1 | H6: ='Volatility Risk Multiplier'!$H$29 -> 0.93482826 | I6: =(0.15*Tabella6[[#This Row],[HQ Country Risk]]+0.25*Tabella6[[#This Row],[Revenue Exposure]]+0.25*Tabella6[[#This Row],[Supply Chain Exposure]]+0.15*Tabella6[[#This Row],[Facility Sites Location Risk]]+0.2*Tabella6[[#This Row],[Financial Exposure]]) *Tabella6[[#This Row],[Sector Risk]]*Tabella6[[#This Row],[Volatility Risk]] -> 3.9162671
A7: BNP Paribas | B7: ='HQ Country Risk'!D6 -> 3.65 | C7: ='Revenue Exposure'!B6 -> 3.3561259 | D7: ='Supply Chain Exposure'!B6 -> 3.5278254 | E7: ='Facility Sites Location Risk'!B6 -> 0 | F7: ='Financial Exposure'!C6 -> 9 | G7: ='Sector Risk Multiplier'!H9 -> 1.1 | H7: ='Volatility Risk Multiplier'!$H$29 -> 0.93482826 | I7: =(0.15*Tabella6[[#This Row],[HQ Country Risk]]+0.25*Tabella6[[#This Row],[Revenue Exposure]]+0.25*Tabella6[[#This Row],[Supply Chain Exposure]]+0.15*Tabella6[[#This Row],[Facility Sites Location Risk]]+0.2*Tabella6[[#This Row],[Financial Exposure]]) *Tabella6[[#This Row],[Sector Risk]]*Tabella6[[#This Row],[Volatility Risk]] -> 4.1836712
A8: Eli Lilly | B8: ='HQ Country Risk'!D7 -> 4.19 | C8: ='Revenue Exposure'!B7 -> 4.1002007 | D8: ='Supply Chain Exposure'!B7 -> 4.3884561 | E8: ='Facility Sites Location Risk'!B7 -> 3.9675 | F8: ='Financial Exposure'!C7 -> 6 | G8: ='Sector Risk Multiplier'!H10 -> 0.85 | H8: ='Volatility Risk Multiplier'!$H$29 -> 0.93482826 | I8: =(0.15*Tabella6[[#This Row],[HQ Country Risk]]+0.25*Tabella6[[#This Row],[Revenue Exposure]]+0.25*Tabella6[[#This Row],[Supply Chain Exposure]]+0.15*Tabella6[[#This Row],[Facility Sites Location Risk]]+0.2*Tabella6[[#This Row],[Financial Exposure]]) *Tabella6[[#This Row],[Sector Risk]]*Tabella6[[#This Row],[Volatility Risk]] -> 3.6121024
A9: ENI | B9: ='HQ Country Risk'!D8 -> 3.84 | C9: ='Revenue Exposure'!B8 -> 3.9368104 | D9: ='Supply Chain Exposure'!B8 -> 3.6504162 | E9: ='Facility Sites Location Risk'!B8 -> 0 | F9: ='Financial Exposure'!C8 -> 5 | G9: ='Sector Risk Multiplier'!H11 -> 1.1 | H9: ='Volatility Risk Multiplier'!$H$29 -> 0.93482826 | I9: =(0.15*Tabella6[[#This Row],[HQ Country Risk]]+0.25*Tabella6[[#This Row],[Revenue Exposure]]+0.25*Tabella6[[#This Row],[Supply Chain Exposure]]+0.15*Tabella6[[#This Row],[Facility Sites Location Risk]]+0.2*Tabella6[[#This Row],[Financial Exposure]]) *Tabella6[[#This Row],[Sector Risk]]*Tabella6[[#This Row],[Volatility Risk]] -> 3.5711256
A10: Ford | B10: ='HQ Country Risk'!D9 -> 4.19 | C10: ='Revenue Exposure'!B9 -> 5.0981045 | D10: ='Supply Chain Exposure'!B9 -> 3.7340614 | E10: ='Facility Sites Location Risk'!B9 -> 4.2394477 | F10: ='Financial Exposure'!C9 -> 3 | G10: ='Sector Risk Multiplier'!H12 -> 1.1 | H10: ='Volatility Risk Multiplier'!$H$29 -> 0.93482826 | I10: =(0.15*Tabella6[[#This Row],[HQ Country Risk]]+0.25*Tabella6[[#This Row],[Revenue Exposure]]+0.25*Tabella6[[#This Row],[Supply Chain Exposure]]+0.15*Tabella6[[#This Row],[Facility Sites Location Risk]]+0.2*Tabella6[[#This Row],[Financial Exposure]]) *Tabella6[[#This Row],[Sector Risk]]*Tabella6[[#This Row],[Volatility Risk]] -> 4.1877544
A11: JP Morgan | B11: ='HQ Country Risk'!D10 -> 4.19 | C11: ='Revenue Exposure'!B10 -> 5.0411231 | D11: ='Supply Chain Exposure'!B10 -> 4.2350891 | E11: ='Facility Sites Location Risk'!B10 -> 0 | F11: ='Financial Exposure'!C10 -> 3 | G11: ='Sector Risk Multiplier'!H13 -> 1.1 | H11: ='Volatility Risk Multiplier'!$H$29 -> 0.93482826 | I11: =(0.15*Tabella6[[#This Row],[HQ Country Risk]]+0.25*Tabella6[[#This Row],[Revenue Exposure]]+0.25*Tabella6[[#This Row],[Supply Chain Exposure]]+0.15*Tabella6[[#This Row],[Facility Sites Location Risk]]+0.2*Tabella6[[#This Row],[Financial Exposure]]) *Tabella6[[#This Row],[Sector Risk]]*Tabella6[[#This Row],[Volatility Risk]] -> 3.6479881
A12: L'Oreal | B12: ='HQ Country Risk'!D11 -> 3.65 | C12: ='Revenue Exposure'!B11 -> 4.0242964 | D12: ='Supply Chain Exposure'!B11 -> 3.5876772 | E12: ='Facility Sites Location Risk'!B11 -> 4.1109066 | F12: ='Financial Exposure'!C11 -> 4 | G12: ='Sector Risk Multiplier'!H14 -> 0.85 | H12: ='Volatility Risk Multiplier'!$H$29 -> 0.93482826 | I12: =(0.15*Tabella6[[#This Row],[HQ Country Risk]]+0.25*Tabella6[[#This Row],[Revenue Exposure]]+0.25*Tabella6[[#This Row],[Supply Chain Exposure]]+0.15*Tabella6[[#This Row],[Facility Sites Location Risk]]+0.2*Tabella6[[#This Row],[Financial Exposure]]) *Tabella6[[#This Row],[Sector Risk]]*Tabella6[[#This Row],[Volatility Risk]] -> 3.0728366
A13: LVMH | B13: ='HQ Country Risk'!D12 -> 3.65 | C13: ='Revenue Exposure'!B12 -> 4.0610137 | D13: ='Supply Chain Exposure'!B12 -> 3.458849 | E13: ='Facility Sites Location Risk'!B12 -> 3.7645546 | F13: ='Financial Exposure'!C12 -> 5 | G13: ='Sector Risk Multiplier'!H15 -> 1 | H13: ='Volatility Risk Multiplier'!$H$29 -> 0.93482826 | I13: =(0.15*Tabella6[[#This Row],[HQ Country Risk]]+0.25*Tabella6[[#This Row],[Revenue Exposure]]+0.25*Tabella6[[#This Row],[Supply Chain Exposure]]+0.15*Tabella6[[#This Row],[Facility Sites Location Risk]]+0.2*Tabella6[[#This Row],[Financial Exposure]]) *Tabella6[[#This Row],[Sector Risk]]*Tabella6[[#This Row],[Volatility Risk]] -> 3.7319736
A14: Meta | B14: ='HQ Country Risk'!D13 -> 4.19 | C14: ='Revenue Exposure'!B13 -> 4.0756275 | D14: ='Supply Chain Exposure'!B13 -> 3.6287716 | E14: ='Facility Sites Location Risk'!B13 -> 3.32 | F14: ='Financial Exposure'!C13 -> 3 | G14: ='Sector Risk Multiplier'!H16 -> 1 | H14: ='Volatility Risk Multiplier'!$H$29 -> 0.93482826 | I14: =(0.15*Tabella6[[#This Row],[HQ Country Risk]]+0.25*Tabella6[[#This Row],[Revenue Exposure]]+0.25*Tabella6[[#This Row],[Supply Chain Exposure]]+0.15*Tabella6[[#This Row],[Facility Sites Location Risk]]+0.2*Tabella6[[#This Row],[Financial Exposure]]) *Tabella6[[#This Row],[Sector Risk]]*Tabella6[[#This Row],[Volatility Risk]] -> 3.4145535
... A27: Volkswagen | B27: ='HQ Country Risk'!D26 -> 3.42 | C27: ='Revenue Exposure'!B26 -> 3.4274333 | D27: ='Supply Chain Exposure'!B26 -> 3.7787245 | E27: ='Facility Sites Location Risk'!B26 -> 4.1877051 | F27: ='Financial Exposure'!C26 -> 3 | G27: ='Sector Risk Multiplier'!H29 -> 1.1 | H27: ='Volatility Risk Multiplier'!$H$29 -> 0.93482826 | I27: =(0.15*Tabella6[[#This Row],[HQ Country Risk]]+0.25*Tabella6[[#This Row],[Revenue Exposure]]+0.25*Tabella6[[#This Row],[Supply Chain Exposure]]+0.15*Tabella6[[#This Row],[Facility Sites Location Risk]]+0.2*Tabella6[[#This Row],[Financial Exposure]]) *Tabella6[[#This Row],[Sector Risk]]*Tabella6[[#This Row],[Volatility Risk]] -> 3.6429928

Sheet Correlation Matrix - 2024
A1: Company Name | B1: HQ Country Risk | C1: Revenue Exposure | D1: Supply Chain Exposure | E1: Facility Sites Location Risk | F1: Financial Exposure | G1: Final Index - Reweighted | I1: Correlation coefficients for 2023
A2: Allianz | B2: 3.42 | C2: 3.3948195 | D2: 3.6559789 | E2: 0 | F2: 5 | G2: =L$12*B2+L$13*C2+L$14*D2+L$15*E2+L$16*F2 -> 2.8396872 | J2: HQ Country Risk | K2: Revenue Exposure | L2: Supply Chain Exposure | M2: Facility Sites Location Risk | N2: Financial Exposure
A3: Amazon | B3: 4.19 | C3: 6.0438158 | D3: 4.2231945 | E3: 4.0365251 | F3: 4 | G3: =L$12*B3+L$13*C3+L$14*D3+L$15*E3+L$16*F3 -> 4.2921327 | I3: HQ Country Risk | J3: {=CORREL(_xlfn._xlws.FILTER($B2:$B26,ISNUMBER($B2:$B26)*ISNUMBER(B2:B26)),_xlfn._xlws.FILTER(B2:B26,ISNUMBER($B2:$B26)*ISNUMBER(B2:B26)))} -> 1 | K3: {=CORREL(_xlfn._xlws.FILTER($B2:$B26,ISNUMBER($B2:$B26)*ISNUMBER(C2:C26)),_xlfn._xlws.FILTER(C2:C26,ISNUMBER($B2:$B26)*ISNUMBER(C2:C26)))} -> 0.7078222 | L3: {=CORREL(_xlfn._xlws.FILTER($B2:$B26,ISNUMBER($B2:$B26)*ISNUMBER(D2:D26)),_xlfn._xlws.FILTER(D2:D26,ISNUMBER($B2:$B26)*ISNUMBER(D2:D26)))} -> 0.73728629 | M3: {=CORREL(_xlfn._xlws.FILTER($B2:$B26,ISNUMBER($B2:$B26)*ISNUMBER(E2:E26)),_xlfn._xlws.FILTER(E2:E26,ISNUMBER($B2:$B26)*ISNUMBER(E2:E26)))} -> 0.070792687 | N3: {=CORREL(_xlfn._xlws.FILTER($B2:$B26,ISNUMBER($B2:$B26)*ISNUMBER(F2:F26)),_xlfn._xlws.FILTER(F2:F26,ISNUMBER($B2:$B26)*ISNUMBER(F2:F26)))} -> -0.050489286
A4: Apple | B4: 4.19 | C4: 4.1049432 | D4: 3.9761125 | E4: 4.2493629 | F4: 3 | G4: =L$12*B4+L$13*C4+L$14*D4+L$15*E4+L$16*F4 -> 3.8060786 | I4: Revenue Exposure | J4: {=CORREL(_xlfn._xlws.FILTER($C2:$C26,ISNUMBER($C2:$C26)*ISNUMBER(B2:B26)),_xlfn._xlws.FILTER(B2:B26,ISNUMBER($C2:$C26)*ISNUMBER(B2:B26)))} -> 0.7078222 | K4: {=CORREL(_xlfn._xlws.FILTER($C2:$C26,ISNUMBER($C2:$C26)*ISNUMBER(C2:C26)),_xlfn._xlws.FILTER(C2:C26,ISNUMBER($C2:$C26)*ISNUMBER(C2:C26)))} -> 1 | L4: {=CORREL(_xlfn._xlws.FILTER($C2:$C26,ISNUMBER($C2:$C26)*ISNUMBER(D2:D26)),_xlfn._xlws.FILTER(D2:D26,ISNUMBER($C2:$C26)*ISNUMBER(D2:D26)))} -> 0.73888107 | M4: {=CORREL(_xlfn._xlws.FILTER($C2:$C26,ISNUMBER($C2:$C26)*ISNUMBER(E2:E26)),_xlfn._xlws.FILTER(E2:E26,ISNUMBER($C2:$C26)*ISNUMBER(E2:E26)))} -> 0.17875779 | N4: {=CORREL(_xlfn._xlws.FILTER($C2:$C26,ISNUMBER($C2:$C26)*ISNUMBER(F2:F26)),_xlfn._xlws.FILTER(F2:F26,ISNUMBER($C2:$C26)*ISNUMBER(F2:F26)))} -> -0.22157866
A5: ASML | B5: 3.59 | C5: 4.4116251 | D5: 3.8700067 | E5: 3.996919 | F5: 3 | G5: =L$12*B5+L$13*C5+L$14*D5+L$15*E5+L$16*F5 -> 3.6669752 | I5: Supply Chain Exposure | J5: {=CORREL(_xlfn._xlws.FILTER($D2:$D26,ISNUMBER($D2:$D26)*ISNUMBER(B2:B26)),_xlfn._xlws.FILTER(B2:B26,ISNUMBER($D2:$D26)*ISNUMBER(B2:B26)))} -> 0.73728629 | K5: {=CORREL(_xlfn._xlws.FILTER($D2:$D26,ISNUMBER($D2:$D26)*ISNUMBER(C2:C26)),_xlfn._xlws.FILTER(C2:C26,ISNUMBER($D2:$D26)*ISNUMBER(C2:C26)))} -> 0.73888107 | L5: {=CORREL(_xlfn._xlws.FILTER($D2:$D26,ISNUMBER($D2:$D26)*ISNUMBER(D2:D26)),_xlfn._xlws.FILTER(D2:D26,ISNUMBER($D2:$D26)*ISNUMBER(D2:D26)))} -> 1 | M5: {=CORREL(_xlfn._xlws.FILTER($D2:$D26,ISNUMBER($D2:$D26)*ISNUMBER(E2:E26)),_xlfn._xlws.FILTER(E2:E26,ISNUMBER($D2:$D26)*ISNUMBER(E2:E26)))} -> 0.032918525 | N5: {=CORREL(_xlfn._xlws.FILTER($D2:$D26,ISNUMBER($D2:$D26)*ISNUMBER(F2:F26)),_xlfn._xlws.FILTER(F2:F26,ISNUMBER($D2:$D26)*ISNUMBER(F2:F26)))} -> -0.037198038
A6: BNP Paribas | B6: 3.65 | C6: 3.3561259 | D6: 3.5278254 | E6: 0 | F6: 9 | G6: =L$12*B6+L$13*C6+L$14*D6+L$15*E6+L$16*F6 -> 4.0761106 | I6: Facility Sites Location Risk | J6: {=CORREL(_xlfn._xlws.FILTER($E2:$E26,ISNUMBER($E2:$E26)*ISNUMBER(B2:B26)),_xlfn._xlws.FILTER(B2:B26,ISNUMBER($E2:$E26)*ISNUMBER(B2:B26)))} -> 0.070792687 | K6: {=CORREL(_xlfn._xlws.FILTER($E2:$E26,ISNUMBER($E2:$E26)*ISNUMBER(C2:C26)),_xlfn._xlws.FILTER(C2:C26,ISNUMBER($E2:$E26)*ISNUMBER(C2:C26)))} -> 0.17875779 | L6: {=CORREL(_xlfn._xlws.FILTER($E2:$E26,ISNUMBER($E2:$E26)*ISNUMBER(D2:D26)),_xlfn._xlws.FILTER(D2:D26,ISNUMBER($E2:$E26)*ISNUMBER(D2:D26)))} -> 0.032918525 | M6: {=CORREL(_xlfn._xlws.FILTER($E2:$E26,ISNUMBER($E2:$E26)*ISNUMBER(E2:E26)),_xlfn._xlws.FILTER(E2:E26,ISNUMBER($E2:$E26)*ISNUMBER(E2:E26)))} -> 1 | N6: {=CORREL(_xlfn._xlws.FILTER($E2:$E26,ISNUMBER($E2:$E26)*ISNUMBER(F2:F26)),_xlfn._xlws.FILTER(F2:F26,ISNUMBER($E2:$E26)*ISNUMBER(F2:F26)))} -> -0.35668343
A7: Eli Lilly | B7: 4.19 | C7: 4.1002007 | D7: 4.3884561 | E7: 3.9675 | F7: 6 | G7: =L$12*B7+L$13*C7+L$14*D7+L$15*E7+L$16*F7 -> 4.6906488 | I7: Financial Exposure | J7: {=CORREL(_xlfn._xlws.FILTER($F2:$F26,ISNUMBER($F2:$F26)*ISNUMBER(B2:B26)),_xlfn._xlws.FILTER(B2:B26,ISNUMBER($F2:$F26)*ISNUMBER(B2:B26)))} -> -0.050489286 | K7: {=CORREL(_xlfn._xlws.FILTER($F2:$F26,ISNUMBER($F2:$F26)*ISNUMBER(C2:C26)),_xlfn._xlws.FILTER(C2:C26,ISNUMBER($F2:$F26)*ISNUMBER(C2:C26)))} -> -0.22157866 | L7: {=CORREL(_xlfn._xlws.FILTER($F2:$F26,ISNUMBER($F2:$F26)*ISNUMBER(D2:D26)),_xlfn._xlws.FILTER(D2:D26,ISNUMBER($F2:$F26)*ISNUMBER(D2:D26)))} -> -0.037198038 | M7: {=CORREL(_xlfn._xlws.FILTER($F2:$F26,ISNUMBER($F2:$F26)*ISNUMBER(E2:E26)),_xlfn._xlws.FILTER(E2:E26,ISNUMBER($F2:$F26)*ISNUMBER(E2:E26)))} -> -0.35668343 | N7: {=CORREL(_xlfn._xlws.FILTER($F2:$F26,ISNUMBER($F2:$F26)*ISNUMBER(F2:F26)),_xlfn._xlws.FILTER(F2:F26,ISNUMBER($F2:$F26)*ISNUMBER(F2:F26)))} -> 1
A8: ENI | B8: 3.84 | C8: 3.9368104 | D8: 3.6504162 | E8: 0 | F8: 5 | G8: =L$12*B8+L$13*C8+L$14*D8+L$15*E8+L$16*F8 -> 2.9537286
A9: Ford | B9: 4.19 | C9: 5.0981045 | D9: 3.7340614 | E9: 4.2394477 | F9: 3 | G9: =L$12*B9+L$13*C9+L$14*D9+L$15*E9+L$16*F9 -> 3.8808129
A10: JP Morgan | B10: 4.19 | C10: 5.0411231 | D10: 4.2350891 | E10: 0 | F10: 3 | G10: =L$12*B10+L$13*C10+L$14*D10+L$15*E10+L$16*F10 -> 2.5850602 | J10: Re-weighting of sub-sub-indices:
A11: L'Oreal | B11: 3.65 | C11: 4.0242964 | D11: 3.5876772 | E11: 4.1109066 | F11: 4 | G11: =L$12*B11+L$13*C11+L$14*D11+L$15*E11+L$16*F11 -> 3.937985 | J11: Sum abs. Corr. | K11: Inversion | L11: Weights
A12: LVMH | B12: 3.65 | C12: 4.0610137 | D12: 3.458849 | E12: 3.7645546 | F12: 5 | G12: =L$12*B12+L$13*C12+L$14*D12+L$15*E12+L$16*F12 -> 4.121173 | I12: HQ Country Risk | J12: {=+SUM(ABS(J3:N3))-1} -> 1.5663905 | K12: =1/J12 -> 0.63841042 | L12: =K12/SUM(K$12:K$16) -> 0.13048179
A13: Meta | B13: 4.19 | C13: 4.0756275 | D13: 3.6287716 | E13: 3.32 | F13: 3 | G13: =L$12*B13+L$13*C13+L$14*D13+L$15*E13+L$16*F13 -> 3.4597359 | I13: Revenue Exposure | J13: {=+SUM(ABS(J4:N4))-1} -> 1.8470397 | K13: =1/J13 -> 0.54140687 | L13: =K13/SUM(K$12:K$16) -> 0.11065568
A14: Microsoft | B14: 4.19 | C14: 5.2124623 | D14: 4.1209866 | E14: 4.05 | F14: 4 | G14: =L$12*B14+L$13*C14+L$14*D14+L$15*E14+L$16*F14 -> 4.190938 | I14: Supply Chain Exposure | J14: {=+SUM(ABS(J5:N5))-1} -> 1.5462839 | K14: =1/J14 -> 0.64671176 | L14: =K14/SUM(K$12:K$16) -> 0.13217846
A15: Novo Nordisk | B15: 3.2 | C15: 5.1711361 | D15: 3.4176086 | E15: 3.8972 | F15: 4 | G15: =L$12*B15+L$13*C15+L$14*D15+L$15*E15+L$16*F15 -> 3.9153549 | I15: Facility Sites Location Risk | J15: {=+SUM(ABS(J6:N6))-1} -> 0.63915244 | K15: =1/J15 -> 1.564572 | L15: =K15/SUM(K$12:K$16) -> 0.31977572
A16: NVIDIA | B16: 4.19 | C16: 5.2612345 | D16: 4.1434831 | E16: 4.4 | F16: 3 | G16: =L$12*B16+L$13*C16+L$14*D16+L$15*E16+L$16*F16 -> 4.0043216 | I16: Financial Exposure | J16: {=+SUM(ABS(J7:N7))-1} -> 0.66594942 | K16: =1/J16 -> 1.5016156 | L16: =K16/SUM(K$12:K$16) -> 0.30690834
A17: Procter & Gamble | B17: 4.19 | C17: 4.5829008 | D17: 4.2609774 | E17: 4.3110533 | F17: 5 | G17: =L$12*B17+L$13*C17+L$14*D17+L$15*E17+L$16*F17 -> 4.5301641
A18: Reliance Industries | B18: 5.07 | C18: 7.3623067 | D18: 5.834516 | E18: 5.07 | F18: 4 | G18: =L$12*B18+L$13*C18+L$14*D18+L$15*E18+L$16*F18 -> 5.0963174
A19: Samsung | B19: 3.57 | C19: 4.0305108 | D19: 3.904929 | E19: 4.0176366 | F19: 2 | G19: =L$12*B19+L$13*C19+L$14*D19+L$15*E19+L$16*F19 -> 3.3265258
A20: SAP | B20: 4.19 | C20: 4.3659773 | D20: 3.8569461 | E20: 0 | F20: 3 | G20: =L$12*B20+L$13*C20+L$14*D20+L$15*E20+L$16*F20 -> 2.4603691
A21: Sony | B21: 3.38 | C21: 3.931858 | D21: 3.8860856 | E21: 3.6262216 | F21: 4 | G21: =L$12*B21+L$13*C21+L$14*D21+L$15*E21+L$16*F21 -> 3.7769787
A22: Tencent | B22: 4.26 | C22: 6.3838242 | D22: 5.3896557 | E22: 0 | F22: 4 | G22: =L$12*B22+L$13*C22+L$14*D22+L$15*E22+L$16*F22 -> 3.2022886
A23: Total Energies | B23: 3.65 | C23: 3.4740649 | D23: 3.6571923 | E23: 4.2137973 | F23: 4 | G23: =L$12*B23+L$13*C23+L$14*D23+L$15*E23+L$16*F23 -> 3.9191891
A24: Toyota | B24: 3.38 | C24: 4.0129565 | D24: 3.6129972 | E24: 4.0088225 | F24: 2 | G24: =L$12*B24+L$13*C24+L$14*D24+L$15*E24+L$16*F24 -> 3.2583861
A25: TSMC | B25: 4.26 | C25: 6.2516869 | D25: 3.8774537 | E25: 3.996919 | F25: 3 | G25: =L$12*B25+L$13*C25+L$14*D25+L$15*E25+L$16*F25 -> 3.9589957
A26: Volkswagen | B26: 3.42 | C26: 3.4274333 | D26: 3.7787245 | E26: 4.1877051 | F26: 3 | G26: =L$12*B26+L$13*C26+L$14*D26+L$15*E26+L$16*F26 -> 3.5848301

Sheet HQ Country Risk
A1: Company Name | B1: HQ Country | C1: Country Geopolitical Risk Index | D1: HQ Country Risk - Component
A2: Allianz | B2: Germany | C2: =VLOOKUP(Tabella112[[#This Row],[HQ Country]],'[1]Geopolitical Risk Index'!A10:B156,2,FALSE) -> 3.42 | D2: =Tabella112[[#This Row],[Country Geopolitical Risk Index]] -> 3.42
A3: Amazon | B3: United States | C3: =VLOOKUP(Tabella112[[#This Row],[HQ Country]],'[1]Geopolitical Risk Index'!A8:B154,2,FALSE) -> 4.19 | D3: =Tabella112[[#This Row],[Country Geopolitical Risk Index]] -> 4.19
A4: Apple | B4: United States | C4: =VLOOKUP(Tabella112[[#This Row],[HQ Country]],'[1]Geopolitical Risk Index'!A2:B148,2,FALSE) -> 4.19 | D4: =Tabella112[[#This Row],[Country Geopolitical Risk Index]] -> 4.19
A5: ASML | B5: Netherlands | C5: =VLOOKUP(Tabella112[[#This Row],[HQ Country]],'[1]Geopolitical Risk Index'!A23:B169,2,FALSE) -> 3.59 | D5: =Tabella112[[#This Row],[Country Geopolitical Risk Index]] -> 3.59
A6: BNP Paribas | B6: France | C6: =VLOOKUP(Tabella112[[#This Row],[HQ Country]],'[1]Geopolitical Risk Index'!A24:B170,2,FALSE) -> 3.65 | D6: =Tabella112[[#This Row],[Country Geopolitical Risk Index]] -> 3.65
A7: Eli Lilly | B7: United States | C7: =VLOOKUP(Tabella112[[#This Row],[HQ Country]],'[1]Geopolitical Risk Index'!A25:B171,2,FALSE) -> 4.19 | D7: =Tabella112[[#This Row],[Country Geopolitical Risk Index]] -> 4.19
A8: ENI | B8: Italy | C8: =VLOOKUP(Tabella112[[#This Row],[HQ Country]],'[1]Geopolitical Risk Index'!A26:B172,2,FALSE) -> 3.84 | D8: =Tabella112[[#This Row],[Country Geopolitical Risk Index]] -> 3.84
A9: Ford | B9: United States | C9: =VLOOKUP(Tabella112[[#This Row],[HQ Country]],'[1]Geopolitical Risk Index'!A5:B151,2,FALSE) -> 4.19 | D9: =Tabella112[[#This Row],[Country Geopolitical Risk Index]] -> 4.19
A10: JP Morgan | B10: United States | C10: =VLOOKUP(Tabella112[[#This Row],[HQ Country]],'[1]Geopolitical Risk Index'!A22:B168,2,FALSE) -> 4.19 | D10: =Tabella112[[#This Row],[Country Geopolitical Risk Index]] -> 4.19
A11: L'Oreal | B11: France | C11: =VLOOKUP(Tabella112[[#This Row],[HQ Country]],'[1]Geopolitical Risk Index'!A11:B157,2,FALSE) -> 3.65 | D11: =Tabella112[[#This Row],[Country Geopolitical Risk Index]] -> 3.65
A12: LVMH | B12: France | C12: =VLOOKUP(Tabella112[[#This Row],[HQ Country]],'[1]Geopolitical Risk Index'!A12:B158,2,FALSE) -> 3.65 | D12: =Tabella112[[#This Row],[Country Geopolitical Risk Index]] -> 3.65
A13: Meta | B13: United States | C13: =VLOOKUP(Tabella112[[#This Row],[HQ Country]],'[1]Geopolitical Risk Index'!A3:B149,2,FALSE) -> 4.19 | D13: =Tabella112[[#This Row],[Country Geopolitical Risk Index]] -> 4.19
A14: Microsoft | B14: United States | C14: =VLOOKUP(Tabella112[[#This Row],[HQ Country]],'[1]Geopolitical Risk Index'!A4:B150,2,FALSE) -> 4.19 | D14: =Tabella112[[#This Row],[Country Geopolitical Risk Index]] -> 4.19
A15: Novo Nordisk | B15: Denmark | C15: =VLOOKUP(Tabella112[[#This Row],[HQ Country]],'[1]Geopolitical Risk Index'!A13:B159,2,FALSE) -> 3.2 | D15: =Tabella112[[#This Row],[Country Geopolitical Risk Index]] -> 3.2
A16: NVIDIA | B16: United States | C16: =VLOOKUP(Tabella112[[#This Row],[HQ Country]],'[1]Geopolitical Risk Index'!A9:B155,2,FALSE) -> 4.19 | D16: =Tabella112[[#This Row],[Country Geopolitical Risk Index]] -> 4.19
A17: Procter & Gamble | B17: United States | C17: =VLOOKUP(Tabella112[[#This Row],[HQ Country]],'[1]Geopolitical Risk Index'!A6:B152,2,FALSE) -> 4.19 | D17: =Tabella112[[#This Row],[Country Geopolitical Risk Index]] -> 4.19
A18: Reliance Industries | B18: India | C18: =VLOOKUP(Tabella112[[#This Row],[HQ Country]],'[1]Geopolitical Risk Index'!A14:B160,2,FALSE) -> 5.07 | D18: =Tabella112[[#This Row],[Country Geopolitical Risk Index]] -> 5.07
A19: Samsung | B19: South Korea | C19: =VLOOKUP(Tabella112[[#This Row],[HQ Country]],'[1]Geopolitical Risk Index'!A7:B153,2,FALSE) -> 3.57 | D19: =Tabella112[[#This Row],[Country Geopolitical Risk Index]] -> 3.57
A20: SAP | B20: United States | C20: =VLOOKUP(Tabella112[[#This Row],[HQ Country]],'[1]Geopolitical Risk Index'!A15:B161,2,FALSE) -> 4.19 | D20: =Tabella112[[#This Row],[Country Geopolitical Risk Index]] -> 4.19
A21: Sony | B21: Japan | C21: =VLOOKUP(Tabella112[[#This Row],[HQ Country]],'[1]Geopolitical Risk Index'!A16:B162,2,FALSE) -> 3.38 | D21: =Tabella112[[#This Row],[Country Geopolitical Risk Index]] -> 3.38
A22: Tencent | B22: China | C22: =VLOOKUP(Tabella112[[#This Row],[HQ Country]],'[1]Geopolitical Risk Index'!A17:B163,2,FALSE) -> 4.26 | D22: =Tabella112[[#This Row],[Country Geopolitical Risk Index]] -> 4.26
A23: Total Energies | B23: France | C23: =VLOOKUP(Tabella112[[#This Row],[HQ Country]],'[1]Geopolitical Risk Index'!A18:B164,2,FALSE) -> 3.65 | D23: =Tabella112[[#This Row],[Country Geopolitical Risk Index]] -> 3.65
A24: Toyota | B24: Japan | C24: =VLOOKUP(Tabella112[[#This Row],[HQ Country]],'[1]Geopolitical Risk Index'!A19:B165,2,FALSE) -> 3.38 | D24: =Tabella112[[#This Row],[Country Geopolitical Risk Index]] -> 3.38
A25: TSMC | B25: Taiwan | C25: 4.26 | D25: =Tabella112[[#This Row],[Country Geopolitical Risk Index]] -> 4.26
A26: Volkswagen | B26: Germany | C26: =VLOOKUP(Tabella112[[#This Row],[HQ Country]],'[1]Geopolitical Risk Index'!A21:B167,2,FALSE) -> 3.42 | D26: =Tabella112[[#This Row],[Country Geopolitical Risk Index]] -> 3.42

Sheet Revenue Exposure
A1: Company Name | B1: Revenue Exposure - Component
A2: Allianz | B2: =[5]!Tabella2[[#This Row],[Revenue Exposure - Intermediate Component]]*[5]!Tabella2[[#This Row],[HHI Index - Submultiplier]] -> 3.3948195
A3: Amazon | B3: =[5]!Tabella2[[#This Row],[Revenue Exposure - Intermediate Component]]*[5]!Tabella2[[#This Row],[HHI Index - Submultiplier]] -> 6.0438158
A4: Apple | B4: =[5]!Tabella2[[#This Row],[Revenue Exposure - Intermediate Component]]*[5]!Tabella2[[#This Row],[HHI Index - Submultiplier]] -> 4.1049432
A5: ASML | B5: =[5]!Tabella2[[#This Row],[Revenue Exposure - Intermediate Component]]*[5]!Tabella2[[#This Row],[HHI Index - Submultiplier]] -> 4.4116251
A6: BNP Paribas | B6: =[5]!Tabella2[[#This Row],[Revenue Exposure - Intermediate Component]]*[5]!Tabella2[[#This Row],[HHI Index - Submultiplier]] -> 3.3561259
A7: Eli Lilly | B7: =[5]!Tabella2[[#This Row],[Revenue Exposure - Intermediate Component]]*[5]!Tabella2[[#This Row],[HHI Index - Submultiplier]] -> 4.1002007
A8: ENI | B8: =[5]!Tabella2[[#This Row],[Revenue Exposure - Intermediate Component]]*[5]!Tabella2[[#This Row],[HHI Index - Submultiplier]] -> 3.9368104
A9: Ford | B9: =[5]!Tabella2[[#This Row],[Revenue Exposure - Intermediate Component]]*[5]!Tabella2[[#This Row],[HHI Index - Submultiplier]] -> 5.0981045
A10: JP Morgan | B10: =[5]!Tabella2[[#This Row],[Revenue Exposure - Intermediate Component]]*[5]!Tabella2[[#This Row],[HHI Index - Submultiplier]] -> 5.0411231
A11: L'Oreal | B11: =[5]!Tabella2[[#This Row],[Revenue Exposure - Intermediate Component]]*[5]!Tabella2[[#This Row],[HHI Index - Submultiplier]] -> 4.0242964
A12: LVMH | B12: =[5]!Tabella2[[#This Row],[Revenue Exposure - Intermediate Component]]*[5]!Tabella2[[#This Row],[HHI Index - Submultiplier]] -> 4.0610137
A13: Meta | B13: =[5]!Tabella2[[#This Row],[Revenue Exposure - Intermediate Component]]*[5]!Tabella2[[#This Row],[HHI Index - Submultiplier]] -> 4.0756275
... A26: Volkswagen | B26: =[5]!Tabella2[[#This Row],[Revenue Exposure - Intermediate Component]]*[5]!Tabella2[[#This Row],[HHI Index - Submultiplier]] -> 3.4274333

Sheet Supply Chain Exposure
A1: Company Name | B1: Supply Chain Risk - Component
A2: Allianz | B2: =[2]!Tabella26[[#This Row],[Supply Chain Exposure - Final Component]] -> 3.6559789
A3: Amazon | B3: =[2]!Tabella26[[#This Row],[Supply Chain Exposure - Final Component]] -> 4.2231945
A4: Apple | B4: =[2]!Tabella26[[#This Row],[Supply Chain Exposure - Final Component]] -> 3.9761125
A5: ASML | B5: =[2]!Tabella26[[#This Row],[Supply Chain Exposure - Final Component]] -> 3.8700067
A6: BNP Paribas | B6: =[2]!Tabella26[[#This Row],[Supply Chain Exposure - Final Component]] -> 3.5278254
A7: Eli Lilly | B7: =[2]!Tabella26[[#This Row],[Supply Chain Exposure - Final Component]] -> 4.3884561
A8: ENI | B8: =[2]!Tabella26[[#This Row],[Supply Chain Exposure - Final Component]] -> 3.6504162
A9: Ford | B9: =[2]!Tabella26[[#This Row],[Supply Chain Exposure - Final Component]] -> 3.7340614
A10: JP Morgan | B10: =[2]!Tabella26[[#This Row],[Supply Chain Exposure - Final Component]] -> 4.2350891
A11: L'Oreal | B11: =[2]!Tabella26[[#This Row],[Supply Chain Exposure - Final Component]] -> 3.5876772
A12: LVMH | B12: =[2]!Tabella26[[#This Row],[Supply Chain Exposure - Final Component]] -> 3.458849
A13: Meta | B13: =[2]!Tabella26[[#This Row],[Supply Chain Exposure - Final Component]] -> 3.6287716
... A26: Volkswagen | B26: =[2]!Tabella26[[#This Row],[Supply Chain Exposure - Final Component]] -> 3.7787245

Sheet Facility Sites Location Risk
A1: Company Name | B1: Facility Risk - Component
A2: Allianz | B2: ='[3]Facility Risk - Allianz'!J9 -> 0
A3: Amazon | B3: ='[3]Facility Risk - Amazon'!J9 -> 4.0365251
A4: Apple | B4: ='[3]Facility Risk - Apple'!J9 -> 4.2493629
A5: ASML | B5: ='[3]Facility Risk - ASML'!J9 -> 3.996919
A6: BNP Paribas | B6: ='[3]Facility Risk - BNP'!J9 -> 0
A7: Eli Lilly | B7: ='[3]Facility Risk - Eli Lilly'!J9 -> 3.9675
A8: ENI | B8: ='[3]Facility Risk - Eni'!J9 -> 0
A9: Ford | B9: ='[3]Facility Risk - Ford'!J9 -> 4.2394477
A10: JP Morgan | B10: ='[3]Facility Risk - JP Morgan'!J9 -> 0
A11: L'Oreal | B11: ='[3]Facility Risk - L''Oreal'!J9 -> 4.1109066
A12: LVMH | B12: ='[3]Facility Risk - LVMH'!J9 -> 3.7645546
A13: Meta | B13: ='[3]Facility Risk - Meta'!J9 -> 3.32
A14: Microsoft | B14: ='[3]Facility Risk - Microsoft'!J9 -> 4.05
A15: Novo Nordisk | B15: ='[3]Facility Risk - Nordisk'!J9 -> 3.8972
A16: NVIDIA | B16: ='[3]Facility Risk - NVIDIA'!J9 -> 4.4
A17: Procter & Gamble | B17: ='[3]Facility Risk - P&G'!J9 -> 4.3110533
A18: Reliance Industries | B18: ='[3]Facility Risk - Reliance'!J9 -> 5.07
A19: Samsung | B19: ='[3]Facility Risk - Samsung'!J9 -> 4.0176366
A20: SAP | B20: ='[3]Facility Risk - SAP'!J9 -> 0
A21: Sony | B21: ='[3]Facility Risk - Sony'!J9 -> 3.6262216
A22: Tencent | B22: ='[3]Facility Risk - Tencent'!J9 -> 0
A23: Total Energies | B23: ='[3]Facility Risk - Total en'!J9 -> 4.2137973
A24: Toyota | B24: ='[3]Facility Risk - Toyota'!J9 -> 4.0088225
A25: TSMC | B25: ='[3]Facility Risk - ASML'!J9 -> 3.996919
A26: Volkswagen | B26: ='[3]Facility Risk - VW'!J9 -> 4.1877051

Sheet Financial Exposure
A1: Company | B1: Net Debt/EBITDA 2024 | C1: Financial Exposure
A2: Allianz | B2: 1.45 | C2: =IF(B2<-1,2, IF(B2<0,3, IF(B2<1,4, IF(B2<2,5, IF(B2<3,6, IF(B2<4,7, IF(B2<5,8, IF(B2<6,9, 10)))))))) -> 5
A3: Amazon | B3: 0.35 | C3: =IF(B3<-1,2, IF(B3<0,3, IF(B3<1,4, IF(B3<2,5, IF(B3<3,6, IF(B3<4,7, IF(B3<5,8, IF(B3<6,9, 10)))))))) -> 4
A4: Apple | B4: -0.35 | C4: =IF(B4<-1,2, IF(B4<0,3, IF(B4<1,4, IF(B4<2,5, IF(B4<3,6, IF(B4<4,7, IF(B4<5,8, IF(B4<6,9, 10)))))))) -> 3
A5: ASML | B5: -0.72 | C5: =IF(B5<-1,2, IF(B5<0,3, IF(B5<1,4, IF(B5<2,5, IF(B5<3,6, IF(B5<4,7, IF(B5<5,8, IF(B5<6,9, 10)))))))) -> 3
A6: BNP Paribas | B6: 5.1 | C6: =IF(B6<-1,2, IF(B6<0,3, IF(B6<1,4, IF(B6<2,5, IF(B6<3,6, IF(B6<4,7, IF(B6<5,8, IF(B6<6,9, 10)))))))) -> 9
A7: Eli Lilly | B7: 2.15 | C7: =IF(B7<-1,2, IF(B7<0,3, IF(B7<1,4, IF(B7<2,5, IF(B7<3,6, IF(B7<4,7, IF(B7<5,8, IF(B7<6,9, 10)))))))) -> 6
A8: ENI | B8: 1.69 | C8: =IF(B8<-1,2, IF(B8<0,3, IF(B8<1,4, IF(B8<2,5, IF(B8<3,6, IF(B8<4,7, IF(B8<5,8, IF(B8<6,9, 10)))))))) -> 5
A9: Ford | B9: -0.58 | C9: =IF(B9<-1,2, IF(B9<0,3, IF(B9<1,4, IF(B9<2,5, IF(B9<3,6, IF(B9<4,7, IF(B9<5,8, IF(B9<6,9, 10)))))))) -> 3
A10: JP Morgan | B10: -0.57 | C10: =IF(B10<-1,2, IF(B10<0,3, IF(B10<1,4, IF(B10<2,5, IF(B10<3,6, IF(B10<4,7, IF(B10<5,8, IF(B10<6,9, 10)))))))) -> 3
A11: L'Oreal | B11: 0.44 | C11: =IF(B11<-1,2, IF(B11<0,3, IF(B11<1,4, IF(B11<2,5, IF(B11<3,6, IF(B11<4,7, IF(B11<5,8, IF(B11<6,9, 10)))))))) -> 4
A12: LVMH | B12: 1.02 | C12: =IF(B12<-1,2, IF(B12<0,3, IF(B12<1,4, IF(B12<2,5, IF(B12<3,6, IF(B12<4,7, IF(B12<5,8, IF(B12<6,9, 10)))))))) -> 5
A13: META | B13: -0.32 | C13: =IF(B13<-1,2, IF(B13<0,3, IF(B13<1,4, IF(B13<2,5, IF(B13<3,6, IF(B13<4,7, IF(B13<5,8, IF(B13<6,9, 10)))))))) -> 3
... A26: Volkswagen | B26: -1 | C26: =IF(B26<-1,2, IF(B26<0,3, IF(B26<1,4, IF(B26<2,5, IF(B26<3,6, IF(B26<4,7, IF(B26<5,8, IF(B26<6,9, 10)))))))) -> 3

Sheet Sector Risk Multiplier
A1: Source - S&P Global Ratings (Industry Risk Assessment): https://spratings.spglobal.com/ratings/en/regulatory/article/-/view/sourceId/8304862
A4: Sector - List | B4: S&P Global Industry Risk Assessment Index | D4: Company Name | E4: Sector | F4: S&P Global Industry Risk Assessment | G4: S&P Global Industry Risk Assessment - Value | H4: Sector Risk - Multiplier
A5: Aerospace and defense | B5: Intermediate risk | D5: Allianz | E5: Insurance (Financial services) | F5: =VLOOKUP(Tabella211[[#This Row],[Sector]],[4]!Tabella1[#Data],2) -> Moderately high risk | G5: =IF(F5="Very low risk",1,IF(F5="Low risk",2,IF(F5="Intermediate risk",3,IF(F5="Moderately high risk",4,IF(F5="High risk",5,IF(F5="Very high risk",6, "")))))) -> 4 | H5: =IF(F5="Very low risk",0.75,IF(F5="Low risk",0.85,IF(F5="Intermediate risk",1,IF(F5="Moderately high risk",1.1,IF(F5="High risk",1.15,IF(F5="Very high risk",1.25, "")))))) -> 1.1
A6: Agribusiness, commodity foods, and agricultural cooperatives | B6: Intermediate risk | D6: Amazon | E6: Retail and restaurants | F6: =VLOOKUP(Tabella211[[#This Row],[Sector]],[4]!Tabella1[#Data],2) -> Intermediate risk | G6: =IF(F6="Very low risk",1,IF(F6="Low risk",2,IF(F6="Intermediate risk",3,IF(F6="Moderately high risk",4,IF(F6="High risk",5,IF(F6="Very high risk",6, "")))))) -> 3 | H6: =IF(F6="Very low risk",0.75,IF(F6="Low risk",0.85,IF(F6="Intermediate risk",1,IF(F6="Moderately high risk",1.1,IF(F6="High risk",1.15,IF(F6="Very high risk",1.25, "")))))) -> 1
A7: Asset managers | B7: Intermediate risk | D7: Apple | E7: Technology hardware and semiconductors | F7: =VLOOKUP(Tabella211[[#This Row],[Sector]],[4]!Tabella1[#Data],2) -> Moderately high risk | G7: =IF(F7="Very low risk",1,IF(F7="Low risk",2,IF(F7="Intermediate risk",3,IF(F7="Moderately high risk",4,IF(F7="High risk",5,IF(F7="Very high risk",6, "")))))) -> 4 | H7: =IF(F7="Very low risk",0.75,IF(F7="Low risk",0.85,IF(F7="Intermediate risk",1,IF(F7="Moderately high risk",1.1,IF(F7="High risk",1.15,IF(F7="Very high risk",1.25, "")))))) -> 1.1
A8: Auto and commercial vehicle manufacturing | B8: Moderately high risk | D8: ASML | E8: Technology hardware and semiconductors | F8: =VLOOKUP(Tabella211[[#This Row],[Sector]],[4]!Tabella1[#Data],2) -> Moderately high risk | G8: =IF(F8="Very low risk",1,IF(F8="Low risk",2,IF(F8="Intermediate risk",3,IF(F8="Moderately high risk",4,IF(F8="High risk",5,IF(F8="Very high risk",6, "")))))) -> 4 | H8: =IF(F8="Very low risk",0.75,IF(F8="Low risk",0.85,IF(F8="Intermediate risk",1,IF(F8="Moderately high risk",1.1,IF(F8="High risk",1.15,IF(F8="Very high risk",1.25, "")))))) -> 1.1
A9: Auto suppliers | B9: Moderately high risk | D9: BNP Paribas | E9: Financial services finance companies | F9: =VLOOKUP(Tabella211[[#This Row],[Sector]],[4]!Tabella1[#Data],2) -> Moderately high risk | G9: =IF(F9="Very low risk",1,IF(F9="Low risk",2,IF(F9="Intermediate risk",3,IF(F9="Moderately high risk",4,IF(F9="High risk",5,IF(F9="Very high risk",6, "")))))) -> 4 | H9: =IF(F9="Very low risk",0.75,IF(F9="Low risk",0.85,IF(F9="Intermediate risk",1,IF(F9="Moderately high risk",1.1,IF(F9="High risk",1.15,IF(F9="Very high risk",1.25, "")))))) -> 1.1
A10: Building materials | B10: Intermediate risk | D10: Eli Lilly | E10: Pharmaceuticals | F10: =VLOOKUP(Tabella211[[#This Row],[Sector]],[4]!Tabella1[#Data],2) -> Low risk | G10: =IF(F10="Very low risk",1,IF(F10="Low risk",2,IF(F10="Intermediate risk",3,IF(F10="Moderately high risk",4,IF(F10="High risk",5,IF(F10="Very high risk",6, "")))))) -> 2 | H10: =IF(F10="Very low risk",0.75,IF(F10="Low risk",0.85,IF(F10="Intermediate risk",1,IF(F10="Moderately high risk",1.1,IF(F10="High risk",1.15,IF(F10="Very high risk",1.25, "")))))) -> 0.85
A11: Business and consumer services | B11: Intermediate risk | D11: ENI | E11: Oil and gas exploration and production | F11: =VLOOKUP(Tabella211[[#This Row],[Sector]],[4]!Tabella1[#Data],2) -> Moderately high risk | G11: =IF(F11="Very low risk",1,IF(F11="Low risk",2,IF(F11="Intermediate risk",3,IF(F11="Moderately high risk",4,IF(F11="High risk",5,IF(F11="Very high risk",6, "")))))) -> 4 | H11: =IF(F11="Very low risk",0.75,IF(F11="Low risk",0.85,IF(F11="Intermediate risk",1,IF(F11="Moderately high risk",1.1,IF(F11="High risk",1.15,IF(F11="Very high risk",1.25, "")))))) -> 1.1
A12: Capital goods | B12: Intermediate risk | D12: Ford | E12: Auto and commercial vehicle manufacturing | F12: =VLOOKUP(Tabella211[[#This Row],[Sector]],[4]!Tabella1[#Data],2) -> Moderately high risk | G12: =IF(F12="Very low risk",1,IF(F12="Low risk",2,IF(F12="Intermediate risk",3,IF(F12="Moderately high risk",4,IF(F12="High risk",5,IF(F12="Very high risk",6, "")))))) -> 4 | H12: =IF(F12="Very low risk",0.75,IF(F12="Low risk",0.85,IF(F12="Intermediate risk",1,IF(F12="Moderately high risk",1.1,IF(F12="High risk",1.15,IF(F12="Very high risk",1.25, "")))))) -> 1.1
A13: Charter schools | B13: Moderately high risk | D13: JP Morgan | E13: Financial services finance companies | F13: =VLOOKUP(Tabella211[[#This Row],[Sector]],[4]!Tabella1[#Data],2) -> Moderately high risk | G13: =IF(F13="Very low risk",1,IF(F13="Low risk",2,IF(F13="Intermediate risk",3,IF(F13="Moderately high risk",4,IF(F13="High risk",5,IF(F13="Very high risk",6, "")))))) -> 4 | H13: =IF(F13="Very low risk",0.75,IF(F13="Low risk",0.85,IF(F13="Intermediate risk",1,IF(F13="Moderately high risk",1.1,IF(F13="High risk",1.15,IF(F13="Very high risk",1.25, "")))))) -> 1.1
A14: Commodity chemicals | B14: Moderately high risk | D14: L'Oreal | E14: Consumer staples and branded nondurables | F14: =VLOOKUP(Tabella211[[#This Row],[Sector]],[4]!Tabella1[#Data],2) -> Low risk | G14: =IF(F14="Very low risk",1,IF(F14="Low risk",2,IF(F14="Intermediate risk",3,IF(F14="Moderately high risk",4,IF(F14="High risk",5,IF(F14="Very high risk",6, "")))))) -> 2 | H14: =IF(F14="Very low risk",0.75,IF(F14="Low risk",0.85,IF(F14="Intermediate risk",1,IF(F14="Moderately high risk",1.1,IF(F14="High risk",1.15,IF(F14="Very high risk",1.25, "")))))) -> 0.85
A15: Consumer durables | B15: Intermediate risk | D15: LVMH | E15: Consumer durables | F15: =VLOOKUP(Tabella211[[#This Row],[Sector]],[4]!Tabella1[#Data],2) -> Intermediate risk | G15: =IF(F15="Very low risk",1,IF(F15="Low risk",2,IF(F15="Intermediate risk",3,IF(F15="Moderately high risk",4,IF(F15="High risk",5,IF(F15="Very high risk",6, "")))))) -> 3 | H15: =IF(F15="Very low risk",0.75,IF(F15="Low risk",0.85,IF(F15="Intermediate risk",1,IF(F15="Moderately high risk",1.1,IF(F15="High risk",1.15,IF(F15="Very high risk",1.25, "")))))) -> 1
A16: Consumer staples and branded nondurables | B16: Low risk | D16: Meta | E16: Technology software and services | F16: =VLOOKUP(Tabella211[[#This Row],[Sector]],[4]!Tabella1[#Data],2) -> Intermediate risk | G16: =IF(F16="Very low risk",1,IF(F16="Low risk",2,IF(F16="Intermediate risk",3,IF(F16="Moderately high risk",4,IF(F16="High risk",5,IF(F16="Very high risk",6, "")))))) -> 3 | H16: =IF(F16="Very low risk",0.75,IF(F16="Low risk",0.85,IF(F16="Intermediate risk",1,IF(F16="Moderately high risk",1.1,IF(F16="High risk",1.15,IF(F16="Very high risk",1.25, "")))))) -> 1
... A29: Media and entertainment | B29: Intermediate risk | D29: Volkswagen | E29: Auto and commercial vehicle manufacturing | F29: =VLOOKUP(Tabella211[[#This Row],[Sector]],[4]!Tabella1[#Data],2) -> Moderately high risk | G29: =IF(F29="Very low risk",1,IF(F29="Low risk",2,IF(F29="Intermediate risk",3,IF(F29="Moderately high risk",4,IF(F29="High risk",5,IF(F29="Very high risk",6, "")))))) -> 4 | H29: =IF(F29="Very low risk",0.75,IF(F29="Low risk",0.85,IF(F29="Intermediate risk",1,IF(F29="Moderately high risk",1.1,IF(F29="High risk",1.15,IF(F29="Very high risk",1.25, "")))))) -> 1.1
A30: Metals production and processing | B30: Moderately high risk
A31: Midstream energy | B31: Intermediate risk
A32: Mining | B32: Moderately high risk
A33: Municipal retail electric and gas utilities | B33: Very low risk
A34: Municipal water and waste - Irrigation | B34: Very low risk
A35: Municipal water and waste - Solid waste | B35: Low risk
A36: Municipal water and waste - Water, sewer, and combined | B36: Very low risk
A37: Not-for-profit acute care health care organizations | B37: Intermediate risk
A38: Not-for-profit education providers | B38: Low risk
A39: Not-for-profit transportation infrastructure enterprises - Airports and ports | B39: Low risk
A40: Not-for-profit transportation infrastructure enterprises - Toll roads, parking systems, and mass transit | B40: Low risk
A41: Oil and gas exploration and production | B41: Moderately high risk
... A57: Unregulated power and gas | B57: Moderately high risk

Sheet Volatility Risk Multiplier
A1: Source - CBOE Volatility Index (VIXCLS) : https://fred.stlouisfed.org/series/VIXCLS
A4: Observation Date | B4: VIX | D4: Year | E4: VIX | F4: VIX Average | G4: Delta % | H4: Volatility Risk - Multiplier ( 1 + Delta %)
A5: 36528 | B5: 24.21 | D5: 2000 | E5: =AVERAGEIFS($B$5:$B$6526,$A$5:$A$6526,">="&DATE(D5,1,1),$A$5:$A$6526,"<="&DATE(D5,12,31)) -> 23.315 | F5: =AVERAGE(Tabella3[VIX]) -> 19.86642 | G5: =(Tabella3[[#This Row],[VIX]]-Tabella3[[#This Row],[VIX Average]])/Tabella3[[#This Row],[VIX Average]] -> 0.1735884 | H5: =1 +0.3*Tabella3[[#This Row],[Delta %]] -> 1.0520765
A6: 36529 | B6: 27.01 | D6: 2001 | E6: =AVERAGEIFS($B$5:$B$6526,$A$5:$A$6526,">="&DATE(D6,1,1),$A$5:$A$6526,"<="&DATE(D6,12,31)) -> 25.749677 | F6: =AVERAGE(Tabella3[VIX]) -> 19.86642 | G6: =(Tabella3[[#This Row],[VIX]]-Tabella3[[#This Row],[VIX Average]])/Tabella3[[#This Row],[VIX Average]] -> 0.2961408 | H6: =1 +0.3*Tabella3[[#This Row],[Delta %]] -> 1.0888422
A7: 36530 | B7: 26.41 | D7: 2002 | E7: =AVERAGEIFS($B$5:$B$6526,$A$5:$A$6526,">="&DATE(D7,1,1),$A$5:$A$6526,"<="&DATE(D7,12,31)) -> 27.29246 | F7: =AVERAGE(Tabella3[VIX]) -> 19.86642 | G7: =(Tabella3[[#This Row],[VIX]]-Tabella3[[#This Row],[VIX Average]])/Tabella3[[#This Row],[VIX Average]] -> 0.37379862 | H7: =1 +0.3*Tabella3[[#This Row],[Delta %]] -> 1.1121396
A8: 36531 | B8: 25.73 | D8: 2003 | E8: =AVERAGEIFS($B$5:$B$6526,$A$5:$A$6526,">="&DATE(D8,1,1),$A$5:$A$6526,"<="&DATE(D8,12,31)) -> 21.982857 | F8: =AVERAGE(Tabella3[VIX]) -> 19.86642 | G8: =(Tabella3[[#This Row],[VIX]]-Tabella3[[#This Row],[VIX Average]])/Tabella3[[#This Row],[VIX Average]] -> 0.10653339 | H8: =1 +0.3*Tabella3[[#This Row],[Delta %]] -> 1.03196
A9: 36532 | B9: 21.72 | D9: 2004 | E9: =AVERAGEIFS($B$5:$B$6526,$A$5:$A$6526,">="&DATE(D9,1,1),$A$5:$A$6526,"<="&DATE(D9,12,31)) -> 15.478656 | F9: =AVERAGE(Tabella3[VIX]) -> 19.86642 | G9: =(Tabella3[[#This Row],[VIX]]-Tabella3[[#This Row],[VIX Average]])/Tabella3[[#This Row],[VIX Average]] -> -0.22086334 | H9: =1 +0.3*Tabella3[[#This Row],[Delta %]] -> 0.933741
A10: 36535 | B10: 21.71 | D10: 2005 | E10: =AVERAGEIFS($B$5:$B$6526,$A$5:$A$6526,">="&DATE(D10,1,1),$A$5:$A$6526,"<="&DATE(D10,12,31)) -> 12.807063 | F10: =AVERAGE(Tabella3[VIX]) -> 19.86642 | G10: =(Tabella3[[#This Row],[VIX]]-Tabella3[[#This Row],[VIX Average]])/Tabella3[[#This Row],[VIX Average]] -> -0.35534115 | H10: =1 +0.3*Tabella3[[#This Row],[Delta %]] -> 0.89339766
A11: 36536 | B11: 22.5 | D11: 2006 | E11: =AVERAGEIFS($B$5:$B$6526,$A$5:$A$6526,">="&DATE(D11,1,1),$A$5:$A$6526,"<="&DATE(D11,12,31)) -> 12.806534 | F11: =AVERAGE(Tabella3[VIX]) -> 19.86642 | G11: =(Tabella3[[#This Row],[VIX]]-Tabella3[[#This Row],[VIX Average]])/Tabella3[[#This Row],[VIX Average]] -> -0.35536781 | H11: =1 +0.3*Tabella3[[#This Row],[Delta %]] -> 0.89338966
A12: 36537 | B12: 22.84 | D12: 2007 | E12: =AVERAGEIFS($B$5:$B$6526,$A$5:$A$6526,">="&DATE(D12,1,1),$A$5:$A$6526,"<="&DATE(D12,12,31)) -> 17.535936 | F12: =AVERAGE(Tabella3[VIX]) -> 19.86642 | G12: =(Tabella3[[#This Row],[VIX]]-Tabella3[[#This Row],[VIX Average]])/Tabella3[[#This Row],[VIX Average]] -> -0.11730768 | H12: =1 +0.3*Tabella3[[#This Row],[Delta %]] -> 0.96480769
A13: 36538 | B13: 21.71 | D13: 2008 | E13: =AVERAGEIFS($B$5:$B$6526,$A$5:$A$6526,">="&DATE(D13,1,1),$A$5:$A$6526,"<="&DATE(D13,12,31)) -> 32.694862 | F13: =AVERAGE(Tabella3[VIX]) -> 19.86642 | G13: =(Tabella3[[#This Row],[VIX]]-Tabella3[[#This Row],[VIX Average]])/Tabella3[[#This Row],[VIX Average]] -> 0.64573495 | H13: =1 +0.3*Tabella3[[#This Row],[Delta %]] -> 1.1937205
A14: 36539 | B14: 19.66 | D14: 2009 | E14: =AVERAGEIFS($B$5:$B$6526,$A$5:$A$6526,">="&DATE(D14,1,1),$A$5:$A$6526,"<="&DATE(D14,12,31)) -> 31.479008 | F14: =AVERAGE(Tabella3[VIX]) -> 19.86642 | G14: =(Tabella3[[#This Row],[VIX]]-Tabella3[[#This Row],[VIX Average]])/Tabella3[[#This Row],[VIX Average]] -> 0.5845335 | H14: =1 +0.3*Tabella3[[#This Row],[Delta %]] -> 1.17536
A15: 36542 | D15: 2010 | E15: =AVERAGEIFS($B$5:$B$6526,$A$5:$A$6526,">="&DATE(D15,1,1),$A$5:$A$6526,"<="&DATE(D15,12,31)) -> 22.548889 | F15: =AVERAGE(Tabella3[VIX]) -> 19.86642 | G15: =(Tabella3[[#This Row],[VIX]]-Tabella3[[#This Row],[VIX Average]])/Tabella3[[#This Row],[VIX Average]] -> 0.13502528 | H15: =1 +0.3*Tabella3[[#This Row],[Delta %]] -> 1.0405076
A16: 36543 | B16: 21.5 | D16: 2011 | E16: =AVERAGEIFS($B$5:$B$6526,$A$5:$A$6526,">="&DATE(D16,1,1),$A$5:$A$6526,"<="&DATE(D16,12,31)) -> 24.202579 | F16: =AVERAGE(Tabella3[VIX]) -> 19.86642 | G16: =(Tabella3[[#This Row],[VIX]]-Tabella3[[#This Row],[VIX Average]])/Tabella3[[#This Row],[VIX Average]] -> 0.21826577 | H16: =1 +0.3*Tabella3[[#This Row],[Delta %]] -> 1.0654797
A17: 36544 | B17: 21.72 | D17: 2012 | E17: =AVERAGEIFS($B$5:$B$6526,$A$5:$A$6526,">="&DATE(D17,1,1),$A$5:$A$6526,"<="&DATE(D17,12,31)) -> 17.79888 | F17: =AVERAGE(Tabella3[VIX]) -> 19.86642 | G17: =(Tabella3[[#This Row],[VIX]]-Tabella3[[#This Row],[VIX Average]])/Tabella3[[#This Row],[VIX Average]] -> -0.1040721 | H17: =1 +0.3*Tabella3[[#This Row],[Delta %]] -> 0.96877837
A18: 36545 | B18: 21.75 | D18: 2013 | E18: =AVERAGEIFS($B$5:$B$6526,$A$5:$A$6526,">="&DATE(D18,1,1),$A$5:$A$6526,"<="&DATE(D18,12,31)) -> 14.230119 | F18: =AVERAGE(Tabella3[VIX]) -> 19.86642 | G18: =(Tabella3[[#This Row],[VIX]]-Tabella3[[#This Row],[VIX Average]])/Tabella3[[#This Row],[VIX Average]] -> -0.28370995 | H18: =1 +0.3*Tabella3[[#This Row],[Delta %]] -> 0.91488702
A19: 36546 | B19: 20.82 | D19: 2014 | E19: =AVERAGEIFS($B$5:$B$6526,$A$5:$A$6526,">="&DATE(D19,1,1),$A$5:$A$6526,"<="&DATE(D19,12,31)) -> 14.175992 | F19: =AVERAGE(Tabella3[VIX]) -> 19.86642 | G19: =(Tabella3[[#This Row],[VIX]]-Tabella3[[#This Row],[VIX Average]])/Tabella3[[#This Row],[VIX Average]] -> -0.28643449 | H19: =1 +0.3*Tabella3[[#This Row],[Delta %]] -> 0.91406965
A20: 36549 | B20: 24.07 | D20: 2015 | E20: =AVERAGEIFS($B$5:$B$6526,$A$5:$A$6526,">="&DATE(D20,1,1),$A$5:$A$6526,"<="&DATE(D20,12,31)) -> 16.674127 | F20: =AVERAGE(Tabella3[VIX]) -> 19.86642 | G20: =(Tabella3[[#This Row],[VIX]]-Tabella3[[#This Row],[VIX Average]])/Tabella3[[#This Row],[VIX Average]] -> -0.16068788 | H20: =1 +0.3*Tabella3[[#This Row],[Delta %]] -> 0.95179363
A21: 36550 | B21: 23.02 | D21: 2016 | E21: =AVERAGEIFS($B$5:$B$6526,$A$5:$A$6526,">="&DATE(D21,1,1),$A$5:$A$6526,"<="&DATE(D21,12,31)) -> 15.825635 | F21: =AVERAGE(Tabella3[VIX]) -> 19.86642 | G21: =(Tabella3[[#This Row],[VIX]]-Tabella3[[#This Row],[VIX Average]])/Tabella3[[#This Row],[VIX Average]] -> -0.20339775 | H21: =1 +0.3*Tabella3[[#This Row],[Delta %]] -> 0.93898068
A22: 36551 | B22: 23.03 | D22: 2017 | E22: =AVERAGEIFS($B$5:$B$6526,$A$5:$A$6526,">="&DATE(D22,1,1),$A$5:$A$6526,"<="&DATE(D22,12,31)) -> 11.090239 | F22: =AVERAGE(Tabella3[VIX]) -> 19.86642 | G22: =(Tabella3[[#This Row],[VIX]]-Tabella3[[#This Row],[VIX Average]])/Tabella3[[#This Row],[VIX Average]] -> -0.44175956 | H22: =1 +0.3*Tabella3[[#This Row],[Delta %]] -> 0.86747213
A23: 36552 | B23: 23.54 | D23: 2018 | E23: =AVERAGEIFS($B$5:$B$6526,$A$5:$A$6526,">="&DATE(D23,1,1),$A$5:$A$6526,"<="&DATE(D23,12,31)) -> 16.639841 | F23: =AVERAGE(Tabella3[VIX]) -> 19.86642 | G23: =(Tabella3[[#This Row],[VIX]]-Tabella3[[#This Row],[VIX Average]])/Tabella3[[#This Row],[VIX Average]] -> -0.16241373 | H23: =1 +0.3*Tabella3[[#This Row],[Delta %]] -> 0.95127588
A24: 36553 | B24: 26.14 | D24: 2019 | E24: =AVERAGEIFS($B$5:$B$6526,$A$5:$A$6526,">="&DATE(D24,1,1),$A$5:$A$6526,"<="&DATE(D24,12,31)) -> 15.387857 | F24: =AVERAGE(Tabella3[VIX]) -> 19.86642 | G24: =(Tabella3[[#This Row],[VIX]]-Tabella3[[#This Row],[VIX Average]])/Tabella3[[#This Row],[VIX Average]] -> -0.22543381 | H24: =1 +0.3*Tabella3[[#This Row],[Delta %]] -> 0.93236986
A25: 36556 | B25: 24.95 | D25: 2020 | E25: =AVERAGEIFS($B$5:$B$6526,$A$5:$A$6526,">="&DATE(D25,1,1),$A$5:$A$6526,"<="&DATE(D25,12,31)) -> 29.251304 | F25: =AVERAGE(Tabella3[VIX]) -> 19.86642 | G25: =(Tabella3[[#This Row],[VIX]]-Tabella3[[#This Row],[VIX Average]])/Tabella3[[#This Row],[VIX Average]] -> 0.47239937 | H25: =1 +0.3*Tabella3[[#This Row],[Delta %]] -> 1.1417198
A26: 36557 | B26: 23.45 | D26: 2021 | E26: =AVERAGEIFS($B$5:$B$6526,$A$5:$A$6526,">="&DATE(D26,1,1),$A$5:$A$6526,"<="&DATE(D26,12,31)) -> 19.656151 | F26: =AVERAGE(Tabella3[VIX]) -> 19.86642 | G26: =(Tabella3[[#This Row],[VIX]]-Tabella3[[#This Row],[VIX Average]])/Tabella3[[#This Row],[VIX Average]] -> -0.010584151 | H26: =1 +0.3*Tabella3[[#This Row],[Delta %]] -> 0.99682475
A27: 36558 | B27: 23.12 | D27: 2022 | E27: =AVERAGEIFS($B$5:$B$6526,$A$5:$A$6526,">="&DATE(D27,1,1),$A$5:$A$6526,"<="&DATE(D27,12,31)) -> 25.637148 | F27: =AVERAGE(Tabella3[VIX]) -> 19.86642 | G27: =(Tabella3[[#This Row],[VIX]]-Tabella3[[#This Row],[VIX Average]])/Tabella3[[#This Row],[VIX Average]] -> 0.29047652 | H27: =1 +0.3*Tabella3[[#This Row],[Delta %]] -> 1.087143
... A29: 36560 | B29: 21.54 | D29: 2024 | E29: =AVERAGEIFS($B$5:$B$6526,$A$5:$A$6526,">="&DATE(D29,1,1),$A$5:$A$6526,"<="&DATE(D29,12,31)) -> 15.550656 | F29: =AVERAGE(Tabella3[VIX]) -> 19.86642 | G29: =(Tabella3[[#This Row],[VIX]]-Tabella3[[#This Row],[VIX Average]])/Tabella3[[#This Row],[VIX Average]] -> -0.21723912 | H29: =1 +0.3*Tabella3[[#This Row],[Delta %]] -> 0.93482826
A30: 36563 | B30: 22.79
A31: 36564 | B31: 21.25
A32: 36565 | B32: 22.9
A33: 36566 | B33: 23.07
A34: 36567 | B34: 24.42
A35: 36570 | B35: 24.38
A36: 36571 | B36: 22.92
A37: 36572 | B37: 23.51
A38: 36573 | B38: 23.17
A39: 36574 | B39: 26
A40: 36577
A41: 36578 | B41: 25.86
A42: 36579 | B42: 23.89
A43: 36580 | B43: 24.38
...
